Workbook

Sheet Instruções
A1: LEVANTAMENTO DA MALHA VIÁRIA DE GURIRI — PROTOCOLO DE 17 MEDIÇÕES
A2: Objetivo: medir a malha inteira do balneário (comprimento de cada rua e avenida, m² e o que falta pavimentar) SEM medir rua por rua. Como Guriri é uma grade regular numa ilha alongada, 17 medições no Google Maps determinam a malha toda; a planilha calcula o resto e confere os totais contra três âncoras independentes (contrato da Bacia 1, contagem oficial de logradouros e a estimativa atual do Estudo).
A4: PASSO 1 — Extensão norte–sul (1 medição).
A5: No Google Maps, clique com o botão direito no cruzamento mais ao NORTE da malha urbanizada (onde as ruas acabam) e escolha 'Medir distância'; estenda a linha pelo eixo da avenida principal até o cruzamento mais ao SUL. Anote em km na célula B5 da aba Entradas.
A7: PASSO 2 — Largura leste–oeste em 5 estações (5 medições).
A8: Divida mentalmente a ilha em 5 pontos: extremo norte, um quarto, centro (na altura da ponte/eixo comercial), três quartos e extremo sul. Em cada ponto, meça a rua transversal mais próxima, da beira-mar até onde a malha urbanizada termina (mangue/rio). Anote em METROS em B8:B12.
A10: PASSO 3 — Quantas avenidas existem em cada estação (5 contagens).
A11: Nas mesmas 5 alturas, conte no satélite quantas vias LONGITUDINAIS (paralelas à praia) existem — inclua a beira-mar. A ilha afina: no centro haverá mais avenidas que nas pontas. Anote em C8:C12.
A13: PASSO 4 — Última rua numerada de cada lado (2 leituras).
A14: As ruas transversais são numeradas a partir do centro. Navegue até o fim da malha ao NORTE e anote o número da última rua (ex.: Rua 31); repita ao SUL. Células B15 e B16.
A16: PASSO 5 — Largura de caixa típica (4 medições).
A17: Com a régua do Maps no satélite, meça a largura da via (meio-fio a meio-fio) de DUAS avenidas e DUAS ruas representativas. Anote em metros em B19:B22.
... A23: Faça tudo no modo satélite com o zoom em ~200 m. Se uma estação cair num trecho sem malha (dunas/mangue), use a rua urbanizada mais próxima. Os nomes oficiais têm duas numerações — bairros Guriri Norte e Guriri Sul — por isso o Passo 4 pede um número por lado.

Sheet Entradas
A1: ENTRADAS — preencha SOMENTE as células azuis (17 medições + grade de status)
A3: PASSO 1 · EXTENSÃO DA MALHA
A5: Extensão norte–sul da malha urbanizada (km)
A7: Estação | B7: Largura E–O (m) | C7: Nº de avenidas | D7: % avenidas pavimentadas | E7: % ruas pavimentadas
A8: Extremo norte
A9: Um quarto
A10: Centro
A11: Três quartos
A12: Extremo sul
A14: PASSO 4 · RUAS NUMERADAS
A15: Número da última rua — lado NORTE (bairro Guriri Norte)
A16: Número da última rua — lado SUL (bairro Guriri Sul)
A18: PASSO 5 · CAIXA DAS VIAS
A19: Largura da avenida A (m)
A20: Largura da avenida B (m)
A21: Largura da rua A (m)
... A25: Data do levantamento / observações

Sheet Malha
A1: MALHA RUA A RUA — gerada pelas 17 medições (nada a preencher aqui)
A2: Modelo declarado: as ruas transversais de cada lado espalham-se uniformemente entre o extremo e o centro; o comprimento de cada uma é a largura da ilha interpolada linearmente entre as 5 estações; cada avenida j existe nas zonas em que a contagem de avenidas é ≥ j, com comprimento = nº dessas zonas × (extensão ÷ 5).
A4: Rua | B4: Posição (0=extremo N, 1=extremo S) | C4: Zona (1–5) | D4: Comprimento (m) | E4: Caixa (m) | F4: Área (m²)
A5: =IF(1<=Entradas!$B$15,"Rua 1 (N)","") | B5: =IF(1<=Entradas!$B$15,0.5-0.5*((1-0.5)/Entradas!$B$15),"") | C5: =IF($B5="",0,MIN(5,INT($B5*5)+1)) | D5: =IF($B5="","",IF($B5<=0.25,Entradas!$B$8+(Entradas!$B$9-Entradas!$B$8)*($B5/0.25),IF($B5<=0.5,Entradas!$B$9+(Entradas!$B$10-Entradas!$B$9)*(($B5-0.25)/0.25),IF($B5<=0.75,Entradas!$B$10+(Entradas!$B$11-Entradas!$B$10)*(($B5-0.5)/0.25),Entradas!$B$11+(Entradas!$B$12-Entradas!$B$11)*(($B5-0.75)/0.25))))) | E5: =IF($B5="","",AVERAGE(Entradas!$B$21:$B$22)) | F5: =IF($B5="",0,$D5*$E5)
A6: =IF(2<=Entradas!$B$15,"Rua 2 (N)","") | B6: =IF(2<=Entradas!$B$15,0.5-0.5*((2-0.5)/Entradas!$B$15),"") | C6: =IF($B6="",0,MIN(5,INT($B6*5)+1)) | D6: =IF($B6="","",IF($B6<=0.25,Entradas!$B$8+(Entradas!$B$9-Entradas!$B$8)*($B6/0.25),IF($B6<=0.5,Entradas!$B$9+(Entradas!$B$10-Entradas!$B$9)*(($B6-0.25)/0.25),IF($B6<=0.75,Entradas!$B$10+(Entradas!$B$11-Entradas!$B$10)*(($B6-0.5)/0.25),Entradas!$B$11+(Entradas!$B$12-Entradas!$B$11)*(($B6-0.75)/0.25))))) | E6: =IF($B6="","",AVERAGE(Entradas!$B$21:$B$22)) | F6: =IF($B6="",0,$D6*$E6)
A7: =IF(3<=Entradas!$B$15,"Rua 3 (N)","") | B7: =IF(3<=Entradas!$B$15,0.5-0.5*((3-0.5)/Entradas!$B$15),"") | C7: =IF($B7="",0,MIN(5,INT($B7*5)+1)) | D7: =IF($B7="","",IF($B7<=0.25,Entradas!$B$8+(Entradas!$B$9-Entradas!$B$8)*($B7/0.25),IF($B7<=0.5,Entradas!$B$9+(Entradas!$B$10-Entradas!$B$9)*(($B7-0.25)/0.25),IF($B7<=0.75,Entradas!$B$10+(Entradas!$B$11-Entradas!$B$10)*(($B7-0.5)/0.25),Entradas!$B$11+(Entradas!$B$12-Entradas!$B$11)*(($B7-0.75)/0.25))))) | E7: =IF($B7="","",AVERAGE(Entradas!$B$21:$B$22)) | F7: =IF($B7="",0,$D7*$E7)
A8: =IF(4<=Entradas!$B$15,"Rua 4 (N)","") | B8: =IF(4<=Entradas!$B$15,0.5-0.5*((4-0.5)/Entradas!$B$15),"") | C8: =IF($B8="",0,MIN(5,INT($B8*5)+1)) | D8: =IF($B8="","",IF($B8<=0.25,Entradas!$B$8+(Entradas!$B$9-Entradas!$B$8)*($B8/0.25),IF($B8<=0.5,Entradas!$B$9+(Entradas!$B$10-Entradas!$B$9)*(($B8-0.25)/0.25),IF($B8<=0.75,Entradas!$B$10+(Entradas!$B$11-Entradas!$B$10)*(($B8-0.5)/0.25),Entradas!$B$11+(Entradas!$B$12-Entradas!$B$11)*(($B8-0.75)/0.25))))) | E8: =IF($B8="","",AVERAGE(Entradas!$B$21:$B$22)) | F8: =IF($B8="",0,$D8*$E8)
A9: =IF(5<=Entradas!$B$15,"Rua 5 (N)","") | B9: =IF(5<=Entradas!$B$15,0.5-0.5*((5-0.5)/Entradas!$B$15),"") | C9: =IF($B9="",0,MIN(5,INT($B9*5)+1)) | D9: =IF($B9="","",IF($B9<=0.25,Entradas!$B$8+(Entradas!$B$9-Entradas!$B$8)*($B9/0.25),IF($B9<=0.5,Entradas!$B$9+(Entradas!$B$10-Entradas!$B$9)*(($B9-0.25)/0.25),IF($B9<=0.75,Entradas!$B$10+(Entradas!$B$11-Entradas!$B$10)*(($B9-0.5)/0.25),Entradas!$B$11+(Entradas!$B$12-Entradas!$B$11)*(($B9-0.75)/0.25))))) | E9: =IF($B9="","",AVERAGE(Entradas!$B$21:$B$22)) | F9: =IF($B9="",0,$D9*$E9)
A10: =IF(6<=Entradas!$B$15,"Rua 6 (N)","") | B10: =IF(6<=Entradas!$B$15,0.5-0.5*((6-0.5)/Entradas!$B$15),"") | C10: =IF($B10="",0,MIN(5,INT($B10*5)+1)) | D10: =IF($B10="","",IF($B10<=0.25,Entradas!$B$8+(Entradas!$B$9-Entradas!$B$8)*($B10/0.25),IF($B10<=0.5,Entradas!$B$9+(Entradas!$B$10-Entradas!$B$9)*(($B10-0.25)/0.25),IF($B10<=0.75,Entradas!$B$10+(Entradas!$B$11-Entradas!$B$10)*(($B10-0.5)/0.25),Entradas!$B$11+(Entradas!$B$12-Entradas!$B$11)*(($B10-0.75)/0.25))))) | E10: =IF($B10="","",AVERAGE(Entradas!$B$21:$B$22)) | F10: =IF($B10="",0,$D10*$E10)
A11: =IF(7<=Entradas!$B$15,"Rua 7 (N)","") | B11: =IF(7<=Entradas!$B$15,0.5-0.5*((7-0.5)/Entradas!$B$15),"") | C11: =IF($B11="",0,MIN(5,INT($B11*5)+1)) | D11: =IF($B11="","",IF($B11<=0.25,Entradas!$B$8+(Entradas!$B$9-Entradas!$B$8)*($B11/0.25),IF($B11<=0.5,Entradas!$B$9+(Entradas!$B$10-Entradas!$B$9)*(($B11-0.25)/0.25),IF($B11<=0.75,Entradas!$B$10+(Entradas!$B$11-Entradas!$B$10)*(($B11-0.5)/0.25),Entradas!$B$11+(Entradas!$B$12-Entradas!$B$11)*(($B11-0.75)/0.25))))) | E11: =IF($B11="","",AVERAGE(Entradas!$B$21:$B$22)) | F11: =IF($B11="",0,$D11*$E11)
A12: =IF(8<=Entradas!$B$15,"Rua 8 (N)","") | B12: =IF(8<=Entradas!$B$15,0.5-0.5*((8-0.5)/Entradas!$B$15),"") | C12: =IF($B12="",0,MIN(5,INT($B12*5)+1)) | D12: =IF($B12="","",IF($B12<=0.25,Entradas!$B$8+(Entradas!$B$9-Entradas!$B$8)*($B12/0.25),IF($B12<=0.5,Entradas!$B$9+(Entradas!$B$10-Entradas!$B$9)*(($B12-0.25)/0.25),IF($B12<=0.75,Entradas!$B$10+(Entradas!$B$11-Entradas!$B$10)*(($B12-0.5)/0.25),Entradas!$B$11+(Entradas!$B$12-Entradas!$B$11)*(($B12-0.75)/0.25))))) | E12: =IF($B12="","",AVERAGE(Entradas!$B$21:$B$22)) | F12: =IF($B12="",0,$D12*$E12)
A13: =IF(9<=Entradas!$B$15,"Rua 9 (N)","") | B13: =IF(9<=Entradas!$B$15,0.5-0.5*((9-0.5)/Entradas!$B$15),"") | C13: =IF($B13="",0,MIN(5,INT($B13*5)+1)) | D13: =IF($B13="","",IF($B13<=0.25,Entradas!$B$8+(Entradas!$B$9-Entradas!$B$8)*($B13/0.25),IF($B13<=0.5,Entradas!$B$9+(Entradas!$B$10-Entradas!$B$9)*(($B13-0.25)/0.25),IF($B13<=0.75,Entradas!$B$10+(Entradas!$B$11-Entradas!$B$10)*(($B13-0.5)/0.25),Entradas!$B$11+(Entradas!$B$12-Entradas!$B$11)*(($B13-0.75)/0.25))))) | E13: =IF($B13="","",AVERAGE(Entradas!$B$21:$B$22)) | F13: =IF($B13="",0,$D13*$E13)
A14: =IF(10<=Entradas!$B$15,"Rua 10 (N)","") | B14: =IF(10<=Entradas!$B$15,0.5-0.5*((10-0.5)/Entradas!$B$15),"") | C14: =IF($B14="",0,MIN(5,INT($B14*5)+1)) | D14: =IF($B14="","",IF($B14<=0.25,Entradas!$B$8+(Entradas!$B$9-Entradas!$B$8)*($B14/0.25),IF($B14<=0.5,Entradas!$B$9+(Entradas!$B$10-Entradas!$B$9)*(($B14-0.25)/0.25),IF($B14<=0.75,Entradas!$B$10+(Entradas!$B$11-Entradas!$B$10)*(($B14-0.5)/0.25),Entradas!$B$11+(Entradas!$B$12-Entradas!$B$11)*(($B14-0.75)/0.25))))) | E14: =IF($B14="","",AVERAGE(Entradas!$B$21:$B$22)) | F14: =IF($B14="",0,$D14*$E14)
A15: =IF(11<=Entradas!$B$15,"Rua 11 (N)","") | B15: =IF(11<=Entradas!$B$15,0.5-0.5*((11-0.5)/Entradas!$B$15),"") | C15: =IF($B15="",0,MIN(5,INT($B15*5)+1)) | D15: =IF($B15="","",IF($B15<=0.25,Entradas!$B$8+(Entradas!$B$9-Entradas!$B$8)*($B15/0.25),IF($B15<=0.5,Entradas!$B$9+(Entradas!$B$10-Entradas!$B$9)*(($B15-0.25)/0.25),IF($B15<=0.75,Entradas!$B$10+(Entradas!$B$11-Entradas!$B$10)*(($B15-0.5)/0.25),Entradas!$B$11+(Entradas!$B$12-Entradas!$B$11)*(($B15-0.75)/0.25))))) | E15: =IF($B15="","",AVERAGE(Entradas!$B$21:$B$22)) | F15: =IF($B15="",0,$D15*$E15)
A16: =IF(12<=Entradas!$B$15,"Rua 12 (N)","") | B16: =IF(12<=Entradas!$B$15,0.5-0.5*((12-0.5)/Entradas!$B$15),"") | C16: =IF($B16="",0,MIN(5,INT($B16*5)+1)) | D16: =IF($B16="","",IF($B16<=0.25,Entradas!$B$8+(Entradas!$B$9-Entradas!$B$8)*($B16/0.25),IF($B16<=0.5,Entradas!$B$9+(Entradas!$B$10-Entradas!$B$9)*(($B16-0.25)/0.25),IF($B16<=0.75,Entradas!$B$10+(Entradas!$B$11-Entradas!$B$10)*(($B16-0.5)/0.25),Entradas!$B$11+(Entradas!$B$12-Entradas!$B$11)*(($B16-0.75)/0.25))))) | E16: =IF($B16="","",AVERAGE(Entradas!$B$21:$B$22)) | F16: =IF($B16="",0,$D16*$E16)
A17: =IF(13<=Entradas!$B$15,"Rua 13 (N)","") | B17: =IF(13<=Entradas!$B$15,0.5-0.5*((13-0.5)/Entradas!$B$15),"") | C17: =IF($B17="",0,MIN(5,INT($B17*5)+1)) | D17: =IF($B17="","",IF($B17<=0.25,Entradas!$B$8+(Entradas!$B$9-Entradas!$B$8)*($B17/0.25),IF($B17<=0.5,Entradas!$B$9+(Entradas!$B$10-Entradas!$B$9)*(($B17-0.25)/0.25),IF($B17<=0.75,Entradas!$B$10+(Entradas!$B$11-Entradas!$B$10)*(($B17-0.5)/0.25),Entradas!$B$11+(Entradas!$B$12-Entradas!$B$11)*(($B17-0.75)/0.25))))) | E17: =IF($B17="","",AVERAGE(Entradas!$B$21:$B$22)) | F17: =IF($B17="",0,$D17*$E17)
A18: =IF(14<=Entradas!$B$15,"Rua 14 (N)","") | B18: =IF(14<=Entradas!$B$15,0.5-0.5*((14-0.5)/Entradas!$B$15),"") | C18: =IF($B18="",0,MIN(5,INT($B18*5)+1)) | D18: =IF($B18="","",IF($B18<=0.25,Entradas!$B$8+(Entradas!$B$9-Entradas!$B$8)*($B18/0.25),IF($B18<=0.5,Entradas!$B$9+(Entradas!$B$10-Entradas!$B$9)*(($B18-0.25)/0.25),IF($B18<=0.75,Entradas!$B$10+(Entradas!$B$11-Entradas!$B$10)*(($B18-0.5)/0.25),Entradas!$B$11+(Entradas!$B$12-Entradas!$B$11)*(($B18-0.75)/0.25))))) | E18: =IF($B18="","",AVERAGE(Entradas!$B$21:$B$22)) | F18: =IF($B18="",0,$D18*$E18)
A19: =IF(15<=Entradas!$B$15,"Rua 15 (N)","") | B19: =IF(15<=Entradas!$B$15,0.5-0.5*((15-0.5)/Entradas!$B$15),"") | C19: =IF($B19="",0,MIN(5,INT($B19*5)+1)) | D19: =IF($B19="","",IF($B19<=0.25,Entradas!$B$8+(Entradas!$B$9-Entradas!$B$8)*($B19/0.25),IF($B19<=0.5,Entradas!$B$9+(Entradas!$B$10-Entradas!$B$9)*(($B19-0.25)/0.25),IF($B19<=0.75,Entradas!$B$10+(Entradas!$B$11-Entradas!$B$10)*(($B19-0.5)/0.25),Entradas!$B$11+(Entradas!$B$12-Entradas!$B$11)*(($B19-0.75)/0.25))))) | E19: =IF($B19="","",AVERAGE(Entradas!$B$21:$B$22)) | F19: =IF($B19="",0,$D19*$E19)
A20: =IF(16<=Entradas!$B$15,"Rua 16 (N)","") | B20: =IF(16<=Entradas!$B$15,0.5-0.5*((16-0.5)/Entradas!$B$15),"") | C20: =IF($B20="",0,MIN(5,INT($B20*5)+1)) | D20: =IF($B20="","",IF($B20<=0.25,Entradas!$B$8+(Entradas!$B$9-Entradas!$B$8)*($B20/0.25),IF($B20<=0.5,Entradas!$B$9+(Entradas!$B$10-Entradas!$B$9)*(($B20-0.25)/0.25),IF($B20<=0.75,Entradas!$B$10+(Entradas!$B$11-Entradas!$B$10)*(($B20-0.5)/0.25),Entradas!$B$11+(Entradas!$B$12-Entradas!$B$11)*(($B20-0.75)/0.25))))) | E20: =IF($B20="","",AVERAGE(Entradas!$B$21:$B$22)) | F20: =IF($B20="",0,$D20*$E20)
A21: =IF(17<=Entradas!$B$15,"Rua 17 (N)","") | B21: =IF(17<=Entradas!$B$15,0.5-0.5*((17-0.5)/Entradas!$B$15),"") | C21: =IF($B21="",0,MIN(5,INT($B21*5)+1)) | D21: =IF($B21="","",IF($B21<=0.25,Entradas!$B$8+(Entradas!$B$9-Entradas!$B$8)*($B21/0.25),IF($B21<=0.5,Entradas!$B$9+(Entradas!$B$10-Entradas!$B$9)*(($B21-0.25)/0.25),IF($B21<=0.75,Entradas!$B$10+(Entradas!$B$11-Entradas!$B$10)*(($B21-0.5)/0.25),Entradas!$B$11+(Entradas!$B$12-Entradas!$B$11)*(($B21-0.75)/0.25))))) | E21: =IF($B21="","",AVERAGE(Entradas!$B$21:$B$22)) | F21: =IF($B21="",0,$D21*$E21)
A22: =IF(18<=Entradas!$B$15,"Rua 18 (N)","") | B22: =IF(18<=Entradas!$B$15,0.5-0.5*((18-0.5)/Entradas!$B$15),"") | C22: =IF($B22="",0,MIN(5,INT($B22*5)+1)) | D22: =IF($B22="","",IF($B22<=0.25,Entradas!$B$8+(Entradas!$B$9-Entradas!$B$8)*($B22/0.25),IF($B22<=0.5,Entradas!$B$9+(Entradas!$B$10-Entradas!$B$9)*(($B22-0.25)/0.25),IF($B22<=0.75,Entradas!$B$10+(Entradas!$B$11-Entradas!$B$10)*(($B22-0.5)/0.25),Entradas!$B$11+(Entradas!$B$12-Entradas!$B$11)*(($B22-0.75)/0.25))))) | E22: =IF($B22="","",AVERAGE(Entradas!$B$21:$B$22)) | F22: =IF($B22="",0,$D22*$E22)
A23: =IF(19<=Entradas!$B$15,"Rua 19 (N)","") | B23: =IF(19<=Entradas!$B$15,0.5-0.5*((19-0.5)/Entradas!$B$15),"") | C23: =IF($B23="",0,MIN(5,INT($B23*5)+1)) | D23: =IF($B23="","",IF($B23<=0.25,Entradas!$B$8+(Entradas!$B$9-Entradas!$B$8)*($B23/0.25),IF($B23<=0.5,Entradas!$B$9+(Entradas!$B$10-Entradas!$B$9)*(($B23-0.25)/0.25),IF($B23<=0.75,Entradas!$B$10+(Entradas!$B$11-Entradas!$B$10)*(($B23-0.5)/0.25),Entradas!$B$11+(Entradas!$B$12-Entradas!$B$11)*(($B23-0.75)/0.25))))) | E23: =IF($B23="","",AVERAGE(Entradas!$B$21:$B$22)) | F23: =IF($B23="",0,$D23*$E23)
A24: =IF(20<=Entradas!$B$15,"Rua 20 (N)","") | B24: =IF(20<=Entradas!$B$15,0.5-0.5*((20-0.5)/Entradas!$B$15),"") | C24: =IF($B24="",0,MIN(5,INT($B24*5)+1)) | D24: =IF($B24="","",IF($B24<=0.25,Entradas!$B$8+(Entradas!$B$9-Entradas!$B$8)*($B24/0.25),IF($B24<=0.5,Entradas!$B$9+(Entradas!$B$10-Entradas!$B$9)*(($B24-0.25)/0.25),IF($B24<=0.75,Entradas!$B$10+(Entradas!$B$11-Entradas!$B$10)*(($B24-0.5)/0.25),Entradas!$B$11+(Entradas!$B$12-Entradas!$B$11)*(($B24-0.75)/0.25))))) | E24: =IF($B24="","",AVERAGE(Entradas!$B$21:$B$22)) | F24: =IF($B24="",0,$D24*$E24)
A25: =IF(21<=Entradas!$B$15,"Rua 21 (N)","") | B25: =IF(21<=Entradas!$B$15,0.5-0.5*((21-0.5)/Entradas!$B$15),"") | C25: =IF($B25="",0,MIN(5,INT($B25*5)+1)) | D25: =IF($B25="","",IF($B25<=0.25,Entradas!$B$8+(Entradas!$B$9-Entradas!$B$8)*($B25/0.25),IF($B25<=0.5,Entradas!$B$9+(Entradas!$B$10-Entradas!$B$9)*(($B25-0.25)/0.25),IF($B25<=0.75,Entradas!$B$10+(Entradas!$B$11-Entradas!$B$10)*(($B25-0.5)/0.25),Entradas!$B$11+(Entradas!$B$12-Entradas!$B$11)*(($B25-0.75)/0.25))))) | E25: =IF($B25="","",AVERAGE(Entradas!$B$21:$B$22)) | F25: =IF($B25="",0,$D25*$E25)
A26: =IF(22<=Entradas!$B$15,"Rua 22 (N)","") | B26: =IF(22<=Entradas!$B$15,0.5-0.5*((22-0.5)/Entradas!$B$15),"") | C26: =IF($B26="",0,MIN(5,INT($B26*5)+1)) | D26: =IF($B26="","",IF($B26<=0.25,Entradas!$B$8+(Entradas!$B$9-Entradas!$B$8)*($B26/0.25),IF($B26<=0.5,Entradas!$B$9+(Entradas!$B$10-Entradas!$B$9)*(($B26-0.25)/0.25),IF($B26<=0.75,Entradas!$B$10+(Entradas!$B$11-Entradas!$B$10)*(($B26-0.5)/0.25),Entradas!$B$11+(Entradas!$B$12-Entradas!$B$11)*(($B26-0.75)/0.25))))) | E26: =IF($B26="","",AVERAGE(Entradas!$B$21:$B$22)) | F26: =IF($B26="",0,$D26*$E26)
A27: =IF(23<=Entradas!$B$15,"Rua 23 (N)","") | B27: =IF(23<=Entradas!$B$15,0.5-0.5*((23-0.5)/Entradas!$B$15),"") | C27: =IF($B27="",0,MIN(5,INT($B27*5)+1)) | D27: =IF($B27="","",IF($B27<=0.25,Entradas!$B$8+(Entradas!$B$9-Entradas!$B$8)*($B27/0.25),IF($B27<=0.5,Entradas!$B$9+(Entradas!$B$10-Entradas!$B$9)*(($B27-0.25)/0.25),IF($B27<=0.75,Entradas!$B$10+(Entradas!$B$11-Entradas!$B$10)*(($B27-0.5)/0.25),Entradas!$B$11+(Entradas!$B$12-Entradas!$B$11)*(($B27-0.75)/0.25))))) | E27: =IF($B27="","",AVERAGE(Entradas!$B$21:$B$22)) | F27: =IF($B27="",0,$D27*$E27)
A28: =IF(24<=Entradas!$B$15,"Rua 24 (N)","") | B28: =IF(24<=Entradas!$B$15,0.5-0.5*((24-0.5)/Entradas!$B$15),"") | C28: =IF($B28="",0,MIN(5,INT($B28*5)+1)) | D28: =IF($B28="","",IF($B28<=0.25,Entradas!$B$8+(Entradas!$B$9-Entradas!$B$8)*($B28/0.25),IF($B28<=0.5,Entradas!$B$9+(Entradas!$B$10-Entradas!$B$9)*(($B28-0.25)/0.25),IF($B28<=0.75,Entradas!$B$10+(Entradas!$B$11-Entradas!$B$10)*(($B28-0.5)/0.25),Entradas!$B$11+(Entradas!$B$12-Entradas!$B$11)*(($B28-0.75)/0.25))))) | E28: =IF($B28="","",AVERAGE(Entradas!$B$21:$B$22)) | F28: =IF($B28="",0,$D28*$E28)
A29: =IF(25<=Entradas!$B$15,"Rua 25 (N)","") | B29: =IF(25<=Entradas!$B$15,0.5-0.5*((25-0.5)/Entradas!$B$15),"") | C29: =IF($B29="",0,MIN(5,INT($B29*5)+1)) | D29: =IF($B29="","",IF($B29<=0.25,Entradas!$B$8+(Entradas!$B$9-Entradas!$B$8)*($B29/0.25),IF($B29<=0.5,Entradas!$B$9+(Entradas!$B$10-Entradas!$B$9)*(($B29-0.25)/0.25),IF($B29<=0.75,Entradas!$B$10+(Entradas!$B$11-Entradas!$B$10)*(($B29-0.5)/0.25),Entradas!$B$11+(Entradas!$B$12-Entradas!$B$11)*(($B29-0.75)/0.25))))) | E29: =IF($B29="","",AVERAGE(Entradas!$B$21:$B$22)) | F29: =IF($B29="",0,$D29*$E29)
A30: =IF(26<=Entradas!$B$15,"Rua 26 (N)","") | B30: =IF(26<=Entradas!$B$15,0.5-0.5*((26-0.5)/Entradas!$B$15),"") | C30: =IF($B30="",0,MIN(5,INT($B30*5)+1)) | D30: =IF($B30="","",IF($B30<=0.25,Entradas!$B$8+(Entradas!$B$9-Entradas!$B$8)*($B30/0.25),IF($B30<=0.5,Entradas!$B$9+(Entradas!$B$10-Entradas!$B$9)*(($B30-0.25)/0.25),IF($B30<=0.75,Entradas!$B$10+(Entradas!$B$11-Entradas!$B$10)*(($B30-0.5)/0.25),Entradas!$B$11+(Entradas!$B$12-Entradas!$B$11)*(($B30-0.75)/0.25))))) | E30: =IF($B30="","",AVERAGE(Entradas!$B$21:$B$22)) | F30: =IF($B30="",0,$D30*$E30)
A31: =IF(27<=Entradas!$B$15,"Rua 27 (N)","") | B31: =IF(27<=Entradas!$B$15,0.5-0.5*((27-0.5)/Entradas!$B$15),"") | C31: =IF($B31="",0,MIN(5,INT($B31*5)+1)) | D31: =IF($B31="","",IF($B31<=0.25,Entradas!$B$8+(Entradas!$B$9-Entradas!$B$8)*($B31/0.25),IF($B31<=0.5,Entradas!$B$9+(Entradas!$B$10-Entradas!$B$9)*(($B31-0.25)/0.25),IF($B31<=0.75,Entradas!$B$10+(Entradas!$B$11-Entradas!$B$10)*(($B31-0.5)/0.25),Entradas!$B$11+(Entradas!$B$12-Entradas!$B$11)*(($B31-0.75)/0.25))))) | E31: =IF($B31="","",AVERAGE(Entradas!$B$21:$B$22)) | F31: =IF($B31="",0,$D31*$E31)
A32: =IF(28<=Entradas!$B$15,"Rua 28 (N)","") | B32: =IF(28<=Entradas!$B$15,0.5-0.5*((28-0.5)/Entradas!$B$15),"") | C32: =IF($B32="",0,MIN(5,INT($B32*5)+1)) | D32: =IF($B32="","",IF($B32<=0.25,Entradas!$B$8+(Entradas!$B$9-Entradas!$B$8)*($B32/0.25),IF($B32<=0.5,Entradas!$B$9+(Entradas!$B$10-Entradas!$B$9)*(($B32-0.25)/0.25),IF($B32<=0.75,Entradas!$B$10+(Entradas!$B$11-Entradas!$B$10)*(($B32-0.5)/0.25),Entradas!$B$11+(Entradas!$B$12-Entradas!$B$11)*(($B32-0.75)/0.25))))) | E32: =IF($B32="","",AVERAGE(Entradas!$B$21:$B$22)) | F32: =IF($B32="",0,$D32*$E32)
A33: =IF(29<=Entradas!$B$15,"Rua 29 (N)","") | B33: =IF(29<=Entradas!$B$15,0.5-0.5*((29-0.5)/Entradas!$B$15),"") | C33: =IF($B33="",0,MIN(5,INT($B33*5)+1)) | D33: =IF($B33="","",IF($B33<=0.25,Entradas!$B$8+(Entradas!$B$9-Entradas!$B$8)*($B33/0.25),IF($B33<=0.5,Entradas!$B$9+(Entradas!$B$10-Entradas!$B$9)*(($B33-0.25)/0.25),IF($B33<=0.75,Entradas!$B$10+(Entradas!$B$11-Entradas!$B$10)*(($B33-0.5)/0.25),Entradas!$B$11+(Entradas!$B$12-Entradas!$B$11)*(($B33-0.75)/0.25))))) | E33: =IF($B33="","",AVERAGE(Entradas!$B$21:$B$22)) | F33: =IF($B33="",0,$D33*$E33)
A34: =IF(30<=Entradas!$B$15,"Rua 30 (N)","") | B34: =IF(30<=Entradas!$B$15,0.5-0.5*((30-0.5)/Entradas!$B$15),"") | C34: =IF($B34="",0,MIN(5,INT($B34*5)+1)) | D34: =IF($B34="","",IF($B34<=0.25,Entradas!$B$8+(Entradas!$B$9-Entradas!$B$8)*($B34/0.25),IF($B34<=0.5,Entradas!$B$9+(Entradas!$B$10-Entradas!$B$9)*(($B34-0.25)/0.25),IF($B34<=0.75,Entradas!$B$10+(Entradas!$B$11-Entradas!$B$10)*(($B34-0.5)/0.25),Entradas!$B$11+(Entradas!$B$12-Entradas!$B$11)*(($B34-0.75)/0.25))))) | E34: =IF($B34="","",AVERAGE(Entradas!$B$21:$B$22)) | F34: =IF($B34="",0,$D34*$E34)
A35: =IF(31<=Entradas!$B$15,"Rua 31 (N)","") | B35: =IF(31<=Entradas!$B$15,0.5-0.5*((31-0.5)/Entradas!$B$15),"") | C35: =IF($B35="",0,MIN(5,INT($B35*5)+1)) | D35: =IF($B35="","",IF($B35<=0.25,Entradas!$B$8+(Entradas!$B$9-Entradas!$B$8)*($B35/0.25),IF($B35<=0.5,Entradas!$B$9+(Entradas!$B$10-Entradas!$B$9)*(($B35-0.25)/0.25),IF($B35<=0.75,Entradas!$B$10+(Entradas!$B$11-Entradas!$B$10)*(($B35-0.5)/0.25),Entradas!$B$11+(Entradas!$B$12-Entradas!$B$11)*(($B35-0.75)/0.25))))) | E35: =IF($B35="","",AVERAGE(Entradas!$B$21:$B$22)) | F35: =IF($B35="",0,$D35*$E35)
A36: =IF(32<=Entradas!$B$15,"Rua 32 (N)","") | B36: =IF(32<=Entradas!$B$15,0.5-0.5*((32-0.5)/Entradas!$B$15),"") | C36: =IF($B36="",0,MIN(5,INT($B36*5)+1)) | D36: =IF($B36="","",IF($B36<=0.25,Entradas!$B$8+(Entradas!$B$9-Entradas!$B$8)*($B36/0.25),IF($B36<=0.5,Entradas!$B$9+(Entradas!$B$10-Entradas!$B$9)*(($B36-0.25)/0.25),IF($B36<=0.75,Entradas!$B$10+(Entradas!$B$11-Entradas!$B$10)*(($B36-0.5)/0.25),Entradas!$B$11+(Entradas!$B$12-Entradas!$B$11)*(($B36-0.75)/0.25))))) | E36: =IF($B36="","",AVERAGE(Entradas!$B$21:$B$22)) | F36: =IF($B36="",0,$D36*$E36)
A37: =IF(33<=Entradas!$B$15,"Rua 33 (N)","") | B37: =IF(33<=Entradas!$B$15,0.5-0.5*((33-0.5)/Entradas!$B$15),"") | C37: =IF($B37="",0,MIN(5,INT($B37*5)+1)) | D37: =IF($B37="","",IF($B37<=0.25,Entradas!$B$8+(Entradas!$B$9-Entradas!$B$8)*($B37/0.25),IF($B37<=0.5,Entradas!$B$9+(Entradas!$B$10-Entradas!$B$9)*(($B37-0.25)/0.25),IF($B37<=0.75,Entradas!$B$10+(Entradas!$B$11-Entradas!$B$10)*(($B37-0.5)/0.25),Entradas!$B$11+(Entradas!$B$12-Entradas!$B$11)*(($B37-0.75)/0.25))))) | E37: =IF($B37="","",AVERAGE(Entradas!$B$21:$B$22)) | F37: =IF($B37="",0,$D37*$E37)
A38: =IF(34<=Entradas!$B$15,"Rua 34 (N)","") | B38: =IF(34<=Entradas!$B$15,0.5-0.5*((34-0.5)/Entradas!$B$15),"") | C38: =IF($B38="",0,MIN(5,INT($B38*5)+1)) | D38: =IF($B38="","",IF($B38<=0.25,Entradas!$B$8+(Entradas!$B$9-Entradas!$B$8)*($B38/0.25),IF($B38<=0.5,Entradas!$B$9+(Entradas!$B$10-Entradas!$B$9)*(($B38-0.25)/0.25),IF($B38<=0.75,Entradas!$B$10+(Entradas!$B$11-Entradas!$B$10)*(($B38-0.5)/0.25),Entradas!$B$11+(Entradas!$B$12-Entradas!$B$11)*(($B38-0.75)/0.25))))) | E38: =IF($B38="","",AVERAGE(Entradas!$B$21:$B$22)) | F38: =IF($B38="",0,$D38*$E38)
A39: =IF(35<=Entradas!$B$15,"Rua 35 (N)","") | B39: =IF(35<=Entradas!$B$15,0.5-0.5*((35-0.5)/Entradas!$B$15),"") | C39: =IF($B39="",0,MIN(5,INT($B39*5)+1)) | D39: =IF($B39="","",IF($B39<=0.25,Entradas!$B$8+(Entradas!$B$9-Entradas!$B$8)*($B39/0.25),IF($B39<=0.5,Entradas!$B$9+(Entradas!$B$10-Entradas!$B$9)*(($B39-0.25)/0.25),IF($B39<=0.75,Entradas!$B$10+(Entradas!$B$11-Entradas!$B$10)*(($B39-0.5)/0.25),Entradas!$B$11+(Entradas!$B$12-Entradas!$B$11)*(($B39-0.75)/0.25))))) | E39: =IF($B39="","",AVERAGE(Entradas!$B$21:$B$22)) | F39: =IF($B39="",0,$D39*$E39)
A40: =IF(36<=Entradas!$B$15,"Rua 36 (N)","") | B40: =IF(36<=Entradas!$B$15,0.5-0.5*((36-0.5)/Entradas!$B$15),"") | C40: =IF($B40="",0,MIN(5,INT($B40*5)+1)) | D40: =IF($B40="","",IF($B40<=0.25,Entradas!$B$8+(Entradas!$B$9-Entradas!$B$8)*($B40/0.25),IF($B40<=0.5,Entradas!$B$9+(Entradas!$B$10-Entradas!$B$9)*(($B40-0.25)/0.25),IF($B40<=0.75,Entradas!$B$10+(Entradas!$B$11-Entradas!$B$10)*(($B40-0.5)/0.25),Entradas!$B$11+(Entradas!$B$12-Entradas!$B$11)*(($B40-0.75)/0.25))))) | E40: =IF($B40="","",AVERAGE(Entradas!$B$21:$B$22)) | F40: =IF($B40="",0,$D40*$E40)
A41: =IF(37<=Entradas!$B$15,"Rua 37 (N)","") | B41: =IF(37<=Entradas!$B$15,0.5-0.5*((37-0.5)/Entradas!$B$15),"") | C41: =IF($B41="",0,MIN(5,INT($B41*5)+1)) | D41: =IF($B41="","",IF($B41<=0.25,Entradas!$B$8+(Entradas!$B$9-Entradas!$B$8)*($B41/0.25),IF($B41<=0.5,Entradas!$B$9+(Entradas!$B$10-Entradas!$B$9)*(($B41-0.25)/0.25),IF($B41<=0.75,Entradas!$B$10+(Entradas!$B$11-Entradas!$B$10)*(($B41-0.5)/0.25),Entradas!$B$11+(Entradas!$B$12-Entradas!$B$11)*(($B41-0.75)/0.25))))) | E41: =IF($B41="","",AVERAGE(Entradas!$B$21:$B$22)) | F41: =IF($B41="",0,$D41*$E41)
...

Sheet Resultados
A1: RESULTADOS E CHECAGENS
A3: A · TOTAIS DA MALHA
A4: Nº de ruas transversais (norte + sul) | B4: =Entradas!B15+Entradas!B16
A5: Nº de avenidas (máximo entre estações) | B5: =MAX(Entradas!C8:C12)
A6: Extensão total das ruas (km) | B6: =SUM(Malha!$D$5:$D$84)/1000
A7: Extensão total das avenidas (km) | B7: =SUM(Malha!$D$88:$D$102)/1000
A8: EXTENSÃO TOTAL DA MALHA (km) | B8: =B6+B7
A9: ÁREA TOTAL DE VIAS (m²) | B9: =SUM(Malha!$F$5:$F$84)+SUM(Malha!$F$88:$F$102)
A10: Largura média implícita (m²/m) | B10: =IF(B8>0,B9/(B8*1000),"")
A12: B · PAVIMENTO
A13: Área pavimentada — ruas (m²) | B13: =SUMPRODUCT((Malha!$C$5:$C$84=1)*Malha!$F$5:$F$84)*Entradas!E8+SUMPRODUCT((Malha!$C$5:$C$84=2)*Malha!$F$5:$F$84)*Entradas!E9+SUMPRODUCT((Malha!$C$5:$C$84=3)*Malha!$F$5:$F$84)*Entradas!E10+SUMPRODUCT((Malha!$C$5:$C$84=4)*Malha!$F$5:$F$84)*Entradas!E11+SUMPRODUCT((Malha!$C$5:$C$84=5)*Malha!$F$5:$F$84)*Entradas!E12
A14: Área pavimentada — avenidas (m²) | B14: =(Entradas!B5*1000/5)*AVERAGE(Entradas!B19:B20)*(Entradas!C8*Entradas!D8+Entradas!C9*Entradas!D9+Entradas!C10*Entradas!D10+Entradas!C11*Entradas!D11+Entradas!C12*Entradas!D12)
A15: ÁREA JÁ PAVIMENTADA (m²) | B15: =B13+B14
A16: ÁREA A PAVIMENTAR (m²) | B16: =B9-B15
A17: % da malha já pavimentada | B17: =IF(B9>0,B15/B9,"")
A19: C · CONVERSÃO EM DEMANDA (fatores editáveis)
A20: Agregados por m² de urbanização (t/m²) — fator ANEPAC | B20: 1.4
A21: Participação da brita no mix de agregados — ANEPAC | B21: 0.42
A22: AGREGADOS na área a pavimentar (t) | B22: =B16*B20
A23: BRITA na área a pavimentar (t) | B23: =B22*B21
A25: D · CHECAGENS CONTRA AS TRÊS ÂNCORAS INDEPENDENTES
A26: Âncora 1 — Bacia 1 contratada: 125.000 m² ÷ 13,5 km = 9,26 m de largura média | B26: =IF(B10="","",IF(ABS(B10-9.26)/9.26<=0.35,"coerente","DIVERGE — rever caixas do Passo 5"))
A27: Âncora 2 — logradouros oficiais: ~146 (CEP: Guriri Norte ~70 + Guriri Sul ~76) | B27: =IF(B4=0,"",IF(ABS((B4+B5)-146)/146<=0.35,"coerente","verificar — a contagem CEP inclui travessas e vias nomeadas fora da grade"))
A28: Âncora 3 — estimativa do Estudo (grade): 40–48 km e 350.000–400.000 m² | B28: =IF(B8=0,"",IF(AND(B8>=40*0.85,B8<=48*1.15),"dentro da banda","fora da banda — o Estudo será ajustado ao medido"))
A30: Nota: este levantamento substitui a estimativa de grade do Estudo (item 7.2) assim que preenchido. Divergência não é problema — o número MEDIDO prevalece e o pacote é ajustado a ele; as checagens existem para pegar erro de unidade (km × m, régua no zoom errado), não para forçar concordância.
