Workbook

Sheet Resumo Geral
A1: Levantamento de pavimentação — Loteamentos de Guriri (São Mateus/ES) — v2, reconciliada
A2: Pista = leito carroçável; Passeio = calçada de pedestre. Base: auditoria ponto a ponto de 637 pontos (1 a cada ~350 m de trecho contínuo de via, mínimo 1 por trecho), verificados individualmente no Google Street View (517) e, onde não há cobertura, em imagem de satélite (120). TODOS os 637 pontos estão listados um a um na aba "Pontos auditados", com coordenada, data da imagem e classificação. Emissão v2: 19/08/2026.
A3: Nesta versão v2: (a) os 141 pontos que caem na malha física sem nome no mapa passaram a ser reportados em coluna própria, de modo que 496 + 141 = 637 fecham; (b) a largura de pista deixou de ser um escalar único de 8 m e passou a vir da caixa de via das plantas, via a via, com a regra declarada na aba de cada loteamento; (c) o % de passeio dos loteamentos sem base de medição foi marcado como NÃO MEDIDO em vez de estimado.
A5: Nº | B5: Loteamento | C5: Proprietário / empreendedor | D5: Matrícula (registro) | E5: Área oficial (m²) | F5: Nº de vias | G5: Extensão de vias (m) | H5: Pista pavimentada (m) | I5: % pavimentada | J5: Falta pavimentar (m) | K5: Falta pavimentar (m²) — larguras da planta | L5: Falta pavimentar (m²) — premissa 8 m | M5: Passeio faltante (m de via) | N5: Passeio faltante (m²) | O5: % passeio existente | P5: Base do % de passeio | Q5: Pontos em vias nomeadas | R5: Pontos na malha física | S5: Total de pontos | T5: Metragem medida (m) | U5: Metragem só de planta (m) | V5: Falta s/ metragem medida (m) | W5: Falta s/ metragem de planta (m)
A6: 7 | B6: Balneário de Guriri | C6: Município de São Mateus | D6: 7.798/3-J (22/02/1979) | E6: 578500 | F6: 20 | G6: ='07 Balneário de Guriri'!B26 -> 16241.4 | H6: ='07 Balneário de Guriri'!E26 -> 9731.3 | I6: =IF(G6=0,0,H6/G6) -> 0.59916633 | J6: ='07 Balneário de Guriri'!F26 -> 6510.1 | K6: ='07 Balneário de Guriri'!D28 -> 52083 | L6: ='07 Balneário de Guriri'!D29 -> 52080.8 | M6: ='07 Balneário de Guriri'!D32 -> 6496.56 | N6: ='07 Balneário de Guriri'!D33 -> 25986 | O6: 0.6 | P6: 53 ponto(s) do Street View | Q6: 54 | R6: 4 | S6: 58 | T6: 16241 | U6: 0 | V6: 6510 | W6: 0
A7: 9 | B7: Bosque da Praia | C7: TEGIL Territorial Guriri Ltda | D7: 2.315 (14/12/1979) | E7: 1728555 | F7: 40 | G7: ='09 Bosque da Praia'!B46 -> 36392.4 | H7: ='09 Bosque da Praia'!E46 -> 0 | I7: =IF(G7=0,0,H7/G7) -> 0 | J7: ='09 Bosque da Praia'!F46 -> 36392.4 | K7: ='09 Bosque da Praia'!D48 -> 335689 | L7: ='09 Bosque da Praia'!D49 -> 291139.2 | M7: ='09 Bosque da Praia'!D52 -> 32796.28 | N7: ='09 Bosque da Praia'!D53 -> 131185 | O7: 0.05 | P7: 12 ponto(s) do Street View | Q7: 3 | R7: 24 | S7: 27 | T7: 942 | U7: 35450 | V7: 942 | W7: 35450
A8: 10 | B8: Parque dos Albatrozes | C8: BINOTTE Emp. Imobiliários | D8: 2.383 (18/06/1980) | E8: 757170 | F8: 32 | G8: ='10 Parque dos Albatrozes'!B38 -> 17996.4 | H8: ='10 Parque dos Albatrozes'!E38 -> 5685.3 | I8: =IF(G8=0,0,H8/G8) -> 0.31591318 | J8: ='10 Parque dos Albatrozes'!F38 -> 12311.1 | K8: ='10 Parque dos Albatrozes'!D40 -> 104760 | L8: ='10 Parque dos Albatrozes'!D41 -> 98488.8 | M8: ='10 Parque dos Albatrozes'!D44 -> 8458.308 | N8: ='10 Parque dos Albatrozes'!D45 -> 33833 | O8: 0.53 | P8: 54 ponto(s) do Street View | Q8: 54 | R8: 0 | S8: 54 | T8: 17996 | U8: 0 | V8: 12311 | W8: 0
A9: 13 | B9: Praia de Guriri | C9: Dalla Bernardina Imob. | D9: 2.025 (06/07/1983) | E9: 625209.2 | F9: 40 | G9: ='13 Praia de Guriri'!B46 -> 12416.1 | H9: ='13 Praia de Guriri'!E46 -> 2691.3 | I9: =IF(G9=0,0,H9/G9) -> 0.21675889 | J9: ='13 Praia de Guriri'!F46 -> 9724.8 | K9: ='13 Praia de Guriri'!D48 -> 77796 | L9: ='13 Praia de Guriri'!D49 -> 77798.4 | M9: ='13 Praia de Guriri'!D52 -> 9063.753 | N9: ='13 Praia de Guriri'!D53 -> 36255 | O9: 0.27 | P9: 56 ponto(s) do Street View | Q9: 57 | R9: 0 | S9: 57 | T9: 12416 | U9: 0 | V9: 9725 | W9: 0
A10: 14 | B10: Jardim das Caiçaras | C10: Caiçaras Emp. Imobiliários | D10: 4.170 (05/05/1986) | E10: 1141457.9 | F10: 48 | G10: ='14 Jardim das Caiçaras'!B54 -> 21907.8 | H10: ='14 Jardim das Caiçaras'!E54 -> 3731.2 | I10: =IF(G10=0,0,H10/G10) -> 0.17031377 | J10: ='14 Jardim das Caiçaras'!F54 -> 18176.6 | K10: ='14 Jardim das Caiçaras'!D56 -> 145416 | L10: ='14 Jardim das Caiçaras'!D57 -> 145412.8 | M10: ='14 Jardim das Caiçaras'!D60 -> 18402.552 | N10: ='14 Jardim das Caiçaras'!D61 -> 73610 | O10: 0.16 | P10: 73 ponto(s) do Street View | Q10: 78 | R10: 0 | S10: 78 | T10: 21908 | U10: 0 | V10: 18177 | W10: 0
A11: 15 | B11: Morada do Sol | C11: Guriri Beach Turismo | D11: 7.640 (09/10/1986) | E11: 122213.92 | F11: 13 | G11: ='15 Morada do Sol'!B19 -> 3114.8 | H11: ='15 Morada do Sol'!E19 -> 514.4 | I11: =IF(G11=0,0,H11/G11) -> 0.16514704 | J11: ='15 Morada do Sol'!F19 -> 2600.4 | K11: ='15 Morada do Sol'!D21 -> 20801 | L11: ='15 Morada do Sol'!D22 -> 20803.2 | M11: ='15 Morada do Sol'!D25 -> 1993.472 | N11: ='15 Morada do Sol'!D26 -> 7974 | O11: 0.36 | P11: 15 ponto(s) do Street View | Q11: 15 | R11: 0 | S11: 15 | T11: 3115 | U11: 0 | V11: 2600 | W11: 0
A12: 25 | B12: Parque Residencial Oitizeiro | C12: Alba Figueiredo Brasileiro | D12: 14.380 (02/06/2000) | E12: 557784.5 | F12: 31 | G12: ='25 Park Res. Oitizeiro'!B37 -> 13895.5 | H12: ='25 Park Res. Oitizeiro'!E37 -> 752.2 | I12: =IF(G12=0,0,H12/G12) -> 0.054132633 | J12: ='25 Park Res. Oitizeiro'!F37 -> 13143.3 | K12: ='25 Park Res. Oitizeiro'!D39 -> 110278 | L12: ='25 Park Res. Oitizeiro'!D40 -> 105146.4 | M12: ='25 Park Res. Oitizeiro'!D43 -> 7781.48 | N12: ='25 Park Res. Oitizeiro'!D44 -> 31756 | O12: 0.44 | P12: 41 ponto(s) do Street View | Q12: 41 | R12: 0 | S12: 41 | T12: 13896 | U12: 0 | V12: 13143 | W12: 0
A13: 27 | B13: Residencial Mar Aberto | C13: Mirante Emp. Imobiliários | D13: 9.853 (25/08/2000) | E13: 387200 | F13: 35 | G13: ='27 Res. Mar Aberto'!B41 -> 6839 | H13: ='27 Res. Mar Aberto'!E41 -> 626.2 | I13: =IF(G13=0,0,H13/G13) -> 0.091563094 | J13: ='27 Res. Mar Aberto'!F41 -> 6212.8 | K13: ='27 Res. Mar Aberto'!D43 -> 68341 | L13: ='27 Res. Mar Aberto'!D44 -> 49702.4 | M13: ='27 Res. Mar Aberto'!D47 -> 6702.22 | N13: ='27 Res. Mar Aberto'!D48 -> 33511 | O13: 0.02 | P13: 33 ponto(s) do Street View | Q13: 8 | R13: 25 | S13: 33 | T13: 2731 | U13: 4108 | V13: 2220 | W13: 3993
A14: 31 | B14: Melhorini Residencial Parque | C14: Domingos Melhorini | D14: 9.300 (26/11/2001) | E14: 70180 | F14: 10 | G14: ='31 Melhorini Res. Parque'!B16 -> 1520.9 | H14: ='31 Melhorini Res. Parque'!E16 -> 339.3 | I14: =IF(G14=0,0,H14/G14) -> 0.22309159 | J14: ='31 Melhorini Res. Parque'!F16 -> 1181.6 | K14: ='31 Melhorini Res. Parque'!D18 -> 9453 | L14: ='31 Melhorini Res. Parque'!D19 -> 9452.8 | M14: ='31 Melhorini Res. Parque'!D22 -> 1079.839 | N14: ='31 Melhorini Res. Parque'!D23 -> 4319 | O14: 0.29 | P14: 10 ponto(s) do Street View | Q14: 10 | R14: 0 | S14: 10 | T14: 1521 | U14: 0 | V14: 1182 | W14: 0
A15: 35 | B15: Verão Vermelho | C15: Neri Mariani | D15: 16.265 (24/10/2003) | E15: 402084 | F15: 34 | G15: ='35 Verão Vermelho'!B40 -> 10602.1 | H15: ='35 Verão Vermelho'!E40 -> 425.3 | I15: =IF(G15=0,0,H15/G15) -> 0.040114694 | J15: ='35 Verão Vermelho'!F40 -> 10176.8 | K15: ='35 Verão Vermelho'!D42 -> 79492 | L15: ='35 Verão Vermelho'!D43 -> 81414.4 | M15: ='35 Verão Vermelho'!D46 -> 6807.574 | N15: ='35 Verão Vermelho'!D47 -> 27741 | O15: 0.06 | P15: 19 ponto(s) do Street View | Q15: 9 | R15: 28 | S15: 37 | T15: 2772 | U15: 7830 | V15: 2347 | W15: 7830
A16: 36 | B16: Residencial Ilha de Guriri I | C16: Airton Ruberth | D16: 15.191 (12/11/2003) | E16: 77639 | F16: 9 | G16: ='36 Res. Ilha de Guriri I'!B15 -> 1995.2 | H16: ='36 Res. Ilha de Guriri I'!E15 -> 0 | I16: =IF(G16=0,0,H16/G16) -> 0 | J16: ='36 Res. Ilha de Guriri I'!F15 -> 1995.2 | K16: ='36 Res. Ilha de Guriri I'!D17 -> 15962 | L16: ='36 Res. Ilha de Guriri I'!D18 -> 15961.6 | M16: ='36 Res. Ilha de Guriri I'!D21 -> 1556.256 | N16: ='36 Res. Ilha de Guriri I'!D22 -> 6225 | O16: 0.22 | P16: 8 ponto(s) do Street View | Q16: 9 | R16: 0 | S16: 9 | T16: 1995 | U16: 0 | V16: 1995 | W16: 0
A17: 39 | B17: Central | C17: Kajuzal Camping | D17: 16.104 (25/11/2003) | E17: 124388 | F17: 15 | G17: ='39 Central'!B21 -> 3725.3 | H17: ='39 Central'!E21 -> 435.4 | I17: =IF(G17=0,0,H17/G17) -> 0.11687649 | J17: ='39 Central'!F21 -> 3289.9 | K17: ='39 Central'!D23 -> 26319 | L17: ='39 Central'!D24 -> 26319.2 | M17: ='39 Central'!D27 -> 2980.24 | N17: ='39 Central'!D28 -> 11921 | O17: 0.2 | P17: 10 ponto(s) do Street View | Q17: 10 | R17: 0 | S17: 10 | T17: 3725 | U17: 0 | V17: 3290 | W17: 0
A18: 42 | B18: Residencial Bom Jesus | C18: Kajuzal Camping | D18: 15.989 (23/12/2003) | E18: 1089673.4 | F18: 22 | G18: ='42 Res. Bom Jesus'!B28 -> 23700.1 | H18: ='42 Res. Bom Jesus'!E28 -> 20665.5 | I18: =IF(G18=0,0,H18/G18) -> 0.87195835 | J18: ='42 Res. Bom Jesus'!F28 -> 3034.6 | K18: ='42 Res. Bom Jesus'!D30 -> 24277 | L18: ='42 Res. Bom Jesus'!D31 -> 24276.8 | M18: ='42 Res. Bom Jesus'!D34 -> 18249.077 | N18: ='42 Res. Bom Jesus'!D35 -> 74201 | O18: 0.23 | P18: 48 ponto(s) do Street View | Q18: 70 | R18: 0 | S18: 70 | T18: 21624 | U18: 2076 | V18: 2702 | W18: 332
A19: 47 | B19: Praiano | C19: Praiano Guriri Clube | D19: 10.725 | E19: 96800 | F19: 15 | G19: ='47 Praiano'!B21 -> 2612.2 | H19: ='47 Praiano'!E21 -> 257.4 | I19: =IF(G19=0,0,H19/G19) -> 0.098537631 | J19: ='47 Praiano'!F21 -> 2354.8 | K19: ='47 Praiano'!D23 -> 18838 | L19: ='47 Praiano'!D24 -> 18838.4 | M19: ='47 Praiano'!D27 -> 2063.638 | N19: ='47 Praiano'!D28 -> 8393 | O19: 0.21 | P19: 15 ponto(s) do Street View | Q19: 15 | R19: 0 | S19: 15 | T19: 2612 | U19: 0 | V19: 2355 | W19: 0
A20: 49 | B20: Vale do Amazonas | C20: Igor Vescovi Devens | D20: 15.185 | E20: 77639 | F20: 4 | G20: ='49 Vale do Amazonas'!B10 -> 1154.4 | H20: ='49 Vale do Amazonas'!E10 -> 0 | I20: =IF(G20=0,0,H20/G20) -> 0 | J20: ='49 Vale do Amazonas'!F10 -> 1154.4 | K20: ='49 Vale do Amazonas'!D12 -> 10442 | L20: ='49 Vale do Amazonas'!D13 -> 9235.2 | M20: ='49 Vale do Amazonas'!D16 -> 1154.4 | N20: ='49 Vale do Amazonas'!D17 -> 4618 | O20: 0 | P20: 4 ponto(s) do Street View | Q20: 4 | R20: 0 | S20: 4 | T20: 1154 | U20: 0 | V20: 1154 | W20: 0
A21: 50 | B21: Flor Pan | C21: Antonio Costa | D21: 15.189 | E21: 77639 | F21: 7 | G21: ='50 Flor Pan'!B13 -> 1809.1 | H21: ='50 Flor Pan'!E13 -> 0 | I21: =IF(G21=0,0,H21/G21) -> 0 | J21: ='50 Flor Pan'!F13 -> 1809.1 | K21: ='50 Flor Pan'!D15 -> 19900 | L21: ='50 Flor Pan'!D16 -> 14472.8 | M21: ='50 Flor Pan'!D19 -> 1320.643 | N21: ='50 Flor Pan'!D20 -> 5283 | O21: 0.27 | P21: 9 ponto(s) do Street View | Q21: 9 | R21: 0 | S21: 9 | T21: 1809 | U21: 0 | V21: 1809 | W21: 0
A22: 60 | B22: Residencial Evidência | C22: Anildo Moreira Tavares | D22: 9.497 | E22: 138513.92 | F22: 22 | G22: ='60 Res. Evidência'!B28 -> 3885 | H22: ='60 Res. Evidência'!E28 -> 0 | I22: =IF(G22=0,0,H22/G22) -> 0 | J22: ='60 Res. Evidência'!F28 -> 3885 | K22: ='60 Res. Evidência'!D30 -> 31083 | L22: ='60 Res. Evidência'!D31 -> 31080 | M22: ='60 Res. Evidência'!D34 -> 2602.95 | N22: ='60 Res. Evidência'!D35 -> 10412 | O22: 0.33 | P22: 22 ponto(s) do Street View | Q22: 22 | R22: 0 | S22: 22 | T22: 3885 | U22: 0 | V22: 3885 | W22: 0
A23: 70 | B23: Pontal de Guriri | C23: João Bosco Cevolane | D23: 19.747 | E23: 244194.61 | F23: 17 | G23: ='70 Pontal de Guriri'!B23 -> 6052.1 | H23: ='70 Pontal de Guriri'!E23 -> 572 | I23: =IF(G23=0,0,H23/G23) -> 0.094512649 | J23: ='70 Pontal de Guriri'!F23 -> 5480.1 | K23: ='70 Pontal de Guriri'!D25 -> 43842 | L23: ='70 Pontal de Guriri'!D26 -> 43840.8 | M23: ='70 Pontal de Guriri'!D29 -> 5931.058 | N23: ='70 Pontal de Guriri'!D30 -> 23724 | O23: 0.02 | P23: 23 ponto(s) do Street View | Q23: 28 | R23: 0 | S23: 28 | T23: 6052 | U23: 0 | V23: 5480 | W23: 0
A24: 78 | B24: João de Barro (COHAJOBA) | C24: COHAJOBA | D24: 19.792 | E24: 54750 | F24: 10 | G24: ='78 João de Barro'!B16 -> 1490 | H24: ='78 João de Barro'!E16 -> 0 | I24: =IF(G24=0,0,H24/G24) -> 0 | J24: ='78 João de Barro'!F16 -> 1490 | K24: ='78 João de Barro'!D18 -> 11920 | L24: ='78 João de Barro'!D19 -> 11920 | M24: não estimado | N24: não estimado | O24: não medido | P24: NÃO MEDIDO — nenhum ponto com leitura de calçada | Q24: 0 | R24: 14 | S24: 14 | T24: 0 | U24: 1490 | V24: 0 | W24: 1490
A25: 80 | B25: Soma Cevolani (Golden Guriri) | C25: Soma Cevolani SPE | D25: 52.586 | E25: 234671.83 | F25: 8 | G25: ='80 Soma Cevolani'!B14 -> 4952 | H25: ='80 Soma Cevolani'!E14 -> 4952 | I25: =IF(G25=0,0,H25/G25) -> 1 | J25: ='80 Soma Cevolani'!F14 -> 0 | K25: ='80 Soma Cevolani'!D16 -> 0 | L25: ='80 Soma Cevolani'!D17 -> 0 | M25: não estimado | N25: não estimado | O25: não medido | P25: NÃO MEDIDO — as 2 leituras existentes ficam na ES-010 (orla), fora da malha interna | Q25: 0 | R25: 32 | S25: 32 | T25: 0 | U25: 4952 | V25: 0 | W25: 0
A26: 84 | B26: Pontal de Guriri II | C26: João Bosco Cevolane Ltda | D26: 54.633 | E26: 44371.01 | F26: 5 | G26: ='84 Pontal de Guriri II'!B11 -> 1073 | H26: ='84 Pontal de Guriri II'!E11 -> 0 | I26: =IF(G26=0,0,H26/G26) -> 0 | J26: ='84 Pontal de Guriri II'!F11 -> 1073 | K26: ='84 Pontal de Guriri II'!D13 -> 9855 | L26: ='84 Pontal de Guriri II'!D14 -> 8584 | M26: ='84 Pontal de Guriri II'!D17 -> 772.56 | N26: ='84 Pontal de Guriri II'!D18 -> 3256 | O26: 0.28 | P26: 4 ponto(s) do Street View | Q26: 0 | R26: 14 | S26: 14 | T26: 0 | U26: 1073 | V26: 0 | W26: 1073
B27: TOTAL GERAL — GURIRI | F27: =SUM(F6:F26) -> 437 | G27: =SUM(G6:G26) -> 193374.8 | H27: =SUM(H6:H26) -> 51378.8 | I27: =IF(G27=0,0,H27/G27) -> 0.26569543 | J27: =SUM(J6:J26) -> 141996 | K27: =SUM(K6:K26) -> 1216547 | L27: =SUM(L6:L26) -> 1135968 | M27: =SUMIF($O$6:$O$26,"<>não estimado",M6:M26) -> 136212.86 | N27: =SUMIF($O$6:$O$26,"<>não estimado",N6:N26) -> 554203 | P27: soma exclui os NÃO MEDIDOS | Q27: =SUM(Q6:Q26) -> 496 | R27: =SUM(R6:R26) -> 141 | S27: =SUM(S6:S26) -> 637 | T27: =SUM(T6:T26) -> 136394 | U27: =SUM(U6:U26) -> 56979 | V27: =SUM(V6:V26) -> 91827 | W27: =SUM(W6:W26) -> 50168
A29: Notas, premissas e reconciliação:
A30: • CONTAGEM DE PONTOS: 637 = 496 pontos atribuídos a vias nomeadas + 141 pontos na malha física existente no mapa mas sem nome que corresponda a uma via da planta. Os 141 foram efetivamente verificados e alimentam a taxa do loteamento; por não terem nome, não podem ser creditados a uma linha de via. Todos os 637 constam da aba "Pontos auditados".
A31: • LARGURA DE PISTA: a caixa de via vem do quadro/legenda das plantas (185 das 418 vias de planta a trazem; 12,0 m é o valor dominante, em 146 delas). Conversão declarada: caixa até 15 m → pista = caixa − 4,0 m (dois passeios de 2,0 m); caixa de 15 a 20 m → pista = caixa − 5,0 m; caixa acima de 20 m → pista = caixa − 8,0 m (dois passeios de 2,5 m + canteiro central de 3,0 m). Vias sem largura na planta usam a mediana da própria planta (célula em amarelo); plantas sem nenhuma largura usam 12,0 m, a moda da ilha, que devolve os mesmos 8,0 m da premissa anterior.
A32: • A coluna "Falta pavimentar (m²) — premissa 8 m" é mantida apenas como base de comparação com a versão anterior do levantamento.
A33: • PASSEIO: o % é a média ponderada das leituras de calçada dos pontos do loteamento (ambos os lados = 100%, um lado = 50%, nenhum = 0%). Onde não há leitura válida, a célula diz NÃO MEDIDO e o passeio faltante não é estimado — a metragem correspondente fica fora do total, em vez de receber um número sem base.
A34: • "Passeio faltante (m de via)" são metros de VIA sem calçada completa nos dois lados, NÃO metros lineares de calçada. Para orçar calçada em metro linear, multiplique por 2.
A35: • A extensão de vias não abertas está incluída em "Falta pavimentar", pois são obras a executar; ela NÃO entra no cálculo de passeio.
A36: • Metragem medida = via com traçado existente medido sobre imagem. Metragem só de planta = via prevista no projeto sem traçado medido; sua existência física deve ser confirmada em campo antes de orçar.
A37: • Valores aproximados. Recomenda-se conferência em campo e junto à Prefeitura de São Mateus antes de uso oficial.

Sheet 07 Balneário de Guriri
A1: Loteamento Balneário de Guriri — planta nº 7
A2: Proprietário/empreendedor: Município de São Mateus | Matrícula: 7.798/3-J (22/02/1979) | Área oficial: 578.500 m²
A3: Pontos verificados neste loteamento: 58 (54 atribuídos a vias nomeadas + 4 na malha física sem nome no mapa). Metragem com traçado medido: 16.241 m; só de planta: 0 m. Todos os pontos estão listados na aba 'Pontos auditados'.
A5: Rua / via | B5: Extensão da via (m) | C5: Situação da pista | D5: % pista pavimentada | E5: Pavimentado (m) | F5: Falta pavimentar (m) | G5: Caixa de via — planta (m) | H5: Origem da largura | I5: Largura de pista adotada (m) | J5: Falta pavimentar (m²) | K5: Confiança | L5: Passeio (calçada) | M5: % passeio (via) | N5: Pontos próprios | O5: Origem da classificação | P5: Metragem | Q5: Observações
A6: Avenida Oceano Atlântico | B6: 2712 | C6: Pavimentada | D6: 1 | E6: =ROUND(B6*D6,1) -> 2712 | F6: =B6-E6 -> 0 | G6: 12 | H6: moda da ilha (12 m) | I6: 8 | J6: =ROUND(F6*I6,0) -> 0 | K6: alta | L6: Sim (maioria) | M6: 0.93 | N6: 8 | O6: 8 ponto(s): 8 SV + 0 satélite (bloquete) | P6: medida (traçado) | Q6: Primeira Avenida da planta/orla ES-010; asfalto cinza com estacionamento, quiosques e calcadao junto a praca.
A7: Avenida Governador Eurico Vieira de Rezende | B7: 805.1 | C7: Pavimentada | D7: 1 | E7: =ROUND(B7*D7,1) -> 805.1 | F7: =B7-E7 -> 0 | G7: 12 | H7: moda da ilha (12 m) | I7: 8 | J7: =ROUND(F7*I7,0) -> 0 | K7: alta | L7: Sim (maioria) | M7: 1 | N7: 2 | O7: 2 ponto(s): 1 SV + 1 satélite (asfalto, bloquete) | P7: medida (traçado) | Q7: Corresponde ao eixo Av. Guriri/praca do centro comercial; cinza, comercio denso.
A8: Avenida Esbertalina Barbosa Damiani | B8: 379.5 | C8: Pavimentada | D8: 1 | E8: =ROUND(B8*D8,1) -> 379.5 | F8: =B8-E8 -> 0 | G8: 12 | H8: moda da ilha (12 m) | I8: 8 | J8: =ROUND(F8*I8,0) -> 0 | K8: alta | L8: Parcial | M8: 0.5 | N8: 1 | O8: 1 ponto(s): 1 SV + 0 satélite (bloquete) | P8: medida (traçado) | Q8: Segunda Avenida da planta (limite oeste); cinza continua, rota de onibus. | corrigido por SV
A9: Rua Pinheiros | B9: 386.2 | C9: Não pavimentada | D9: 0 | E9: =ROUND(B9*D9,1) -> 0 | F9: =B9-E9 -> 386.2 | G9: 12 | H9: moda da ilha (12 m) | I9: 8 | J9: =ROUND(F9*I9,0) -> 3090 | K9: alta | L9: Parcial | M9: 0.5 | N9: 1 | O9: 1 ponto(s): 1 SV + 0 satélite (saibro) | P9: medida (traçado) | Q9: Areia/bege no satelite (hz_18395/18435/18475).
A10: Rua Linhares | B10: 1390.7 | C10: Não pavimentada | D10: 0 | E10: =ROUND(B10*D10,1) -> 0 | F10: =B10-E10 -> 1390.7 | G10: 12 | H10: moda da ilha (12 m) | I10: 8 | J10: =ROUND(F10*I10,0) -> 11126 | K10: alta | L10: Parcial | M10: 0.5 | N10: 5 | O10: 5 ponto(s): 5 SV + 0 satélite (saibro) | P10: medida (traçado) | Q10: OSM unpaved; satelite mostra ~150 m cinza junto ao centro comercial (Zuliani/Eurico Rezende); restante ate -18.751 em areia.
A11: Avenida Oceano Índico | B11: 805.8 | C11: Pavimentada | D11: 1 | E11: =ROUND(B11*D11,1) -> 805.8 | F11: =B11-E11 -> 0 | G11: 12 | H11: moda da ilha (12 m) | I11: 8 | J11: =ROUND(F11*I11,0) -> 0 | K11: alta | L11: Parcial | M11: 0.5 | N11: 2 | O11: 2 ponto(s): 2 SV + 0 satélite (bloquete) | P11: medida (traçado) | Q11: Terceira Avenida da planta (transversal com canteiro); cinza da Esbertalina ate a orla.
A12: Rua Horácio Barbosa Alves | B12: 1372.6 | C12: Parcial | D12: 0.77 | E12: =ROUND(B12*D12,1) -> 1056.9 | F12: =B12-E12 -> 315.7 | G12: 12 | H12: moda da ilha (12 m) | I12: 8 | J12: =ROUND(F12*I12,0) -> 2526 | K12: alta | L12: Parcial | M12: 0.54 | N12: 5 | O12: 5 ponto(s): 5 SV + 0 satélite (bloquete, saibro) | P12: medida (traçado) | Q12: Areia/bege no satelite (hz_18395/18435/18475).
A13: Rua São Gabriel da Palha | B13: 1414 | C13: Parcial | D13: 0.27 | E13: =ROUND(B13*D13,1) -> 381.8 | F13: =B13-E13 -> 1032.2 | G13: 12 | H13: moda da ilha (12 m) | I13: 8 | J13: =ROUND(F13*I13,0) -> 8258 | K13: alta | L13: Parcial | M13: 0.64 | N13: 5 | O13: 5 ponto(s): 5 SV + 0 satélite (bloquete, saibro) | P13: medida (traçado) | Q13: Areia; possivel toco curto pavimentado junto ao centro (nao conclusivo).
A14: Rua Barra de São Francisco | B14: 383.2 | C14: Não pavimentada | D14: 0 | E14: =ROUND(B14*D14,1) -> 0 | F14: =B14-E14 -> 383.2 | G14: 12 | H14: moda da ilha (12 m) | I14: 8 | J14: =ROUND(F14*I14,0) -> 3066 | K14: alta | L14: Parcial | M14: 0.5 | N14: 1 | O14: 1 ponto(s): 1 SV + 0 satélite (saibro) | P14: medida (traçado) | Q14: Areia/bege no satelite (hz_18395/18435/18475).
A15: (sem nome) | B15: 367.2 | C15: Parcial | D15: 0.66 | E15: =ROUND(B15*D15,1) -> 242.4 | F15: =B15-E15 -> 124.8 | G15: 12 | H15: moda da ilha (12 m) | I15: 8 | J15: =ROUND(F15*I15,0) -> 998 | K15: alta | L15: Sim (maioria) | M15: 0.79 | N15: 5 | O15: 5 ponto(s): 5 SV + 0 satélite (areia, asfalto, bloquete) | P15: medida (traçado) | Q15: 22 ways de ligacao na praca/orla (primary_link/tertiary_link) majoritariamente asfaltados; poucos tocos de areia.
A16: Avenida Esbertalina B. Damiani | B16: 1142.1 | C16: Pavimentada | D16: 1 | E16: =ROUND(B16*D16,1) -> 1142.1 | F16: =B16-E16 -> 0 | G16: 12 | H16: moda da ilha (12 m) | I16: 8 | J16: =ROUND(F16*I16,0) -> 0 | K16: alta | L16: Parcial | M16: 0.5 | N16: 2 | O16: 2 ponto(s): 2 SV + 0 satélite (bloquete) | P16: medida (traçado) | Q16: Continuacao sul do mesmo eixo; cinza com pontos de onibus ate alem da Mantenopolis. | corrigido por SV
A17: Rua Boa Esperança | B17: 389 | C17: Não pavimentada | D17: 0 | E17: =ROUND(B17*D17,1) -> 0 | F17: =B17-E17 -> 389 | G17: 12 | H17: moda da ilha (12 m) | I17: 8 | J17: =ROUND(F17*I17,0) -> 3112 | K17: alta | L17: Não | M17: 0 | N17: 1 | O17: 1 ponto(s): 1 SV + 0 satélite (areia) | P17: medida (traçado) | Q17: Areia/bege no satelite (hz_18395/18435/18475).
... A25: Rua Esbertalina B. Damiani | B25: 9.2 | C25: Pavimentada | D25: 1 | E25: =ROUND(B25*D25,1) -> 9.2 | F25: =B25-E25 -> 0 | G25: 12 | H25: moda da ilha (12 m) | I25: 8 | J25: =ROUND(F25*I25,0) -> 0 | K25: alta | L25: Sim (maioria) | M25: 1 | N25: 1 | O25: 1 ponto(s): 1 SV + 0 satélite (bloquete) | P25: medida (traçado) | Q25: Toco de 9 m sem tag; mesmo eixo pavimentado. | corrigido por SV
A26: TOTAL | B26: =SUM(B6:B25) -> 16241.4 | D26: =IF(B26=0,0,E26/B26) -> 0.59916633 | E26: =SUM(E6:E25) -> 9731.3 | F26: =SUM(F6:F25) -> 6510.1 | J26: =SUM(J6:J25) -> 52083
A28: Falta pavimentar — pista (m²), larguras da planta: | D28: =J26 -> 52083 | F28: soma da coluna J (falta × largura de pista de cada via)
A29: Falta pavimentar — pista (m²), premissa única de 8 m: | D29: =F26*8 -> 52080.8 | F29: base de comparação com a versão anterior do levantamento
A30: Vias não abertas incluídas no total (m): | D30: 0 | F30: constam na planta, sem abertura visível; contam como obra a executar
A31: Passeio (calçada) existente: | D31: 0.6 | F31: 53 ponto(s) do Street View
A32: Passeio faltante (m de via aberta): | D32: =(B26-D30)*(1-D31) -> 6496.56 | F32: metros de VIA sem calçada completa nos dois lados (não é metro linear de calçada)
A33: Passeio faltante (m²): | D33: =ROUND(D32*4,0) -> 25986 | F33: 4.00 m² de calçada por metro de via (dois lados, larguras da planta)
A34: Pontos verificados — em vias nomeadas: | D34: 54
A35: Pontos verificados — na malha física sem nome no mapa: | D35: 4 | F35: verificados e usados na taxa do loteamento; ver aba Pontos auditados
A36: Pavimento sobre metragem medida (m): | D36: 9731
A37: Pavimento sobre metragem só de planta (m): | D37: 0 | F37: sem traçado medido — existência a confirmar em campo

Sheet 09 Bosque da Praia
A1: Loteamento Bosque da Praia — planta nº 9
A2: Proprietário/empreendedor: TEGIL Territorial Guriri Ltda | Matrícula: 2.315 (14/12/1979) | Área oficial: 1.728.555 m²
A3: Pontos verificados neste loteamento: 27 (3 atribuídos a vias nomeadas + 24 na malha física sem nome no mapa). Metragem com traçado medido: 942 m; só de planta: 35.450 m. Todos os pontos estão listados na aba 'Pontos auditados'.
A5: Rua / via | B5: Extensão da via (m) | C5: Situação da pista | D5: % pista pavimentada | E5: Pavimentado (m) | F5: Falta pavimentar (m) | G5: Caixa de via — planta (m) | H5: Origem da largura | I5: Largura de pista adotada (m) | J5: Falta pavimentar (m²) | K5: Confiança | L5: Passeio (calçada) | M5: % passeio (via) | N5: Pontos próprios | O5: Origem da classificação | P5: Metragem | Q5: Observações
A6: Estrada São Mateus-Estiva de Barra Nova | B6: 942.4 | C6: Não pavimentada | D6: 0 | E6: =ROUND(B6*D6,1) -> 0 | F6: =B6-E6 -> 942.4 | G6: 12 | H6: mediana da planta | I6: 8 | J6: =ROUND(F6*I6,0) -> 7539 | K6: alta | L6: Não | M6: 0 | N6: 3 | O6: 3 ponto(s): 3 SV + 0 satélite (saibro) | P6: medida (traçado) | Q6: 'AV.' diagonal de 20 m da divisa oeste da planta de 1979; hoje ES-010 asfaltada (linha escura no satelite), 942 m no poligono
A7: RUA 1 | B7: 920 | C7: Não pavimentada | D7: 0 | E7: =ROUND(B7*D7,1) -> 0 | F7: =B7-E7 -> 920 | G7: 15 | H7: quadro/legenda da planta | I7: 11 | J7: =ROUND(F7*I7,0) -> 10120 | K7: baixa | L7: Não avaliável | M7: — | N7: 0 | O7: sem ponto próprio — taxa agregada da malha física auditada do loteamento | P7: planta (não medida) | Q7: primeira rua junto a orla, atras da duna: aberta em areia, continua de -18.7746 a ~-18.782
A8: RUA 2 | B8: 920 | C8: Não pavimentada | D8: 0 | E8: =ROUND(B8*D8,1) -> 0 | F8: =B8-E8 -> 920 | G8: 15 | H8: quadro/legenda da planta | I8: 11 | J8: =ROUND(F8*I8,0) -> 10120 | K8: baixa | L8: Não avaliável | M8: — | N8: 0 | O8: sem ponto próprio — taxa agregada da malha física auditada do loteamento | P8: planta (não medida) | Q8: 'R. Dois' rotulada no Google: aberta em areia por toda a extensao
A9: RUA 3 | B9: 920 | C9: Não pavimentada | D9: 0 | E9: =ROUND(B9*D9,1) -> 0 | F9: =B9-E9 -> 920 | G9: 15 | H9: quadro/legenda da planta | I9: 11 | J9: =ROUND(F9*I9,0) -> 10120 | K9: baixa | L9: Não avaliável | M9: — | N9: 0 | O9: sem ponto próprio — taxa agregada da malha física auditada do loteamento | P9: planta (não medida) | Q9: aberta em areia (grade visivel hz_18775s/hz_18830s) de -18.7746 ate a mata em ~-18.782; sem edificacao na maior parte
A10: RUA 4 | B10: 920 | C10: Não pavimentada | D10: 0 | E10: =ROUND(B10*D10,1) -> 0 | F10: =B10-E10 -> 920 | G10: 15 | H10: quadro/legenda da planta | I10: 11 | J10: =ROUND(F10*I10,0) -> 10120 | K10: baixa | L10: Não avaliável | M10: — | N10: 0 | O10: sem ponto próprio — taxa agregada da malha física auditada do loteamento | P10: planta (não medida) | Q10: aberta em areia (grade visivel hz_18775s/hz_18830s) de -18.7746 ate a mata em ~-18.782; sem edificacao na maior parte
A11: RUA 5 | B11: 920 | C11: Não pavimentada | D11: 0 | E11: =ROUND(B11*D11,1) -> 0 | F11: =B11-E11 -> 920 | G11: 15 | H11: quadro/legenda da planta | I11: 11 | J11: =ROUND(F11*I11,0) -> 10120 | K11: baixa | L11: Não avaliável | M11: — | N11: 0 | O11: sem ponto próprio — taxa agregada da malha física auditada do loteamento | P11: planta (não medida) | Q11: aberta em areia (grade visivel hz_18775s/hz_18830s) de -18.7746 ate a mata em ~-18.782; sem edificacao na maior parte
A12: RUA 6 | B12: 920 | C12: Não pavimentada | D12: 0 | E12: =ROUND(B12*D12,1) -> 0 | F12: =B12-E12 -> 920 | G12: 12 | H12: quadro/legenda da planta | I12: 8 | J12: =ROUND(F12*I12,0) -> 7360 | K12: baixa | L12: Não avaliável | M12: — | N12: 0 | O12: sem ponto próprio — taxa agregada da malha física auditada do loteamento | P12: planta (não medida) | Q12: aberta em areia (grade visivel hz_18775s/hz_18830s) de -18.7746 ate a mata em ~-18.782; sem edificacao na maior parte
A13: RUA 7 | B13: 920 | C13: Não pavimentada | D13: 0 | E13: =ROUND(B13*D13,1) -> 0 | F13: =B13-E13 -> 920 | G13: 12 | H13: quadro/legenda da planta | I13: 8 | J13: =ROUND(F13*I13,0) -> 7360 | K13: baixa | L13: Não avaliável | M13: — | N13: 0 | O13: sem ponto próprio — taxa agregada da malha física auditada do loteamento | P13: planta (não medida) | Q13: aberta em areia (grade visivel hz_18775s/hz_18830s) de -18.7746 ate a mata em ~-18.782; sem edificacao na maior parte
A14: RUA 8 | B14: 920 | C14: Não pavimentada | D14: 0 | E14: =ROUND(B14*D14,1) -> 0 | F14: =B14-E14 -> 920 | G14: 12 | H14: quadro/legenda da planta | I14: 8 | J14: =ROUND(F14*I14,0) -> 7360 | K14: baixa | L14: Não avaliável | M14: — | N14: 0 | O14: sem ponto próprio — taxa agregada da malha física auditada do loteamento | P14: planta (não medida) | Q14: aberta em areia (grade visivel hz_18775s/hz_18830s) de -18.7746 ate a mata em ~-18.782; sem edificacao na maior parte
A15: RUA 9 | B15: 920 | C15: Não pavimentada | D15: 0 | E15: =ROUND(B15*D15,1) -> 0 | F15: =B15-E15 -> 920 | G15: 12 | H15: quadro/legenda da planta | I15: 8 | J15: =ROUND(F15*I15,0) -> 7360 | K15: baixa | L15: Não avaliável | M15: — | N15: 0 | O15: sem ponto próprio — taxa agregada da malha física auditada do loteamento | P15: planta (não medida) | Q15: aberta em areia (grade visivel hz_18775s/hz_18830s) de -18.7746 ate a mata em ~-18.782; sem edificacao na maior parte
A16: RUA 10 | B16: 920 | C16: Não pavimentada | D16: 0 | E16: =ROUND(B16*D16,1) -> 0 | F16: =B16-E16 -> 920 | G16: 12 | H16: quadro/legenda da planta | I16: 8 | J16: =ROUND(F16*I16,0) -> 7360 | K16: baixa | L16: Não avaliável | M16: — | N16: 0 | O16: sem ponto próprio — taxa agregada da malha física auditada do loteamento | P16: planta (não medida) | Q16: aberta em areia (grade visivel hz_18775s/hz_18830s) de -18.7746 ate a mata em ~-18.782; sem edificacao na maior parte
A17: RUA 11 | B17: 920 | C17: Não pavimentada | D17: 0 | E17: =ROUND(B17*D17,1) -> 0 | F17: =B17-E17 -> 920 | G17: 12 | H17: quadro/legenda da planta | I17: 8 | J17: =ROUND(F17*I17,0) -> 7360 | K17: baixa | L17: Não avaliável | M17: — | N17: 0 | O17: sem ponto próprio — taxa agregada da malha física auditada do loteamento | P17: planta (não medida) | Q17: aberta em areia (grade visivel hz_18775s/hz_18830s) de -18.7746 ate a mata em ~-18.782; sem edificacao na maior parte
A18: RUA 12 | B18: 920 | C18: Não pavimentada | D18: 0 | E18: =ROUND(B18*D18,1) -> 0 | F18: =B18-E18 -> 920 | G18: 12 | H18: quadro/legenda da planta | I18: 8 | J18: =ROUND(F18*I18,0) -> 7360 | K18: baixa | L18: Não avaliável | M18: — | N18: 0 | O18: sem ponto próprio — taxa agregada da malha física auditada do loteamento | P18: planta (não medida) | Q18: aberta em areia (grade visivel hz_18775s/hz_18830s) de -18.7746 ate a mata em ~-18.782; sem edificacao na maior parte
... A45: AV. ATLANTICA | B45: 920 | C45: Não pavimentada | D45: 0 | E45: =ROUND(B45*D45,1) -> 0 | F45: =B45-E45 -> 920 | G45: 12 | H45: mediana da planta | I45: 8 | J45: =ROUND(F45*I45,0) -> 7360 | K45: baixa | L45: Não avaliável | M45: — | N45: 0 | O45: sem ponto próprio — taxa agregada da malha física auditada do loteamento | P45: planta (não medida) | Q45: orla: trilha de areia na crista da duna, continua em trechos; estacionamento e calcadao do projeto nunca implantados
A46: TOTAL | B46: =SUM(B6:B45) -> 36392.4 | D46: =IF(B46=0,0,E46/B46) -> 0 | E46: =SUM(E6:E45) -> 0 | F46: =SUM(F6:F45) -> 36392.4 | J46: =SUM(J6:J45) -> 335689
A48: Falta pavimentar — pista (m²), larguras da planta: | D48: =J46 -> 335689 | F48: soma da coluna J (falta × largura de pista de cada via)
A49: Falta pavimentar — pista (m²), premissa única de 8 m: | D49: =F46*8 -> 291139.2 | F49: base de comparação com a versão anterior do levantamento
A50: Vias não abertas incluídas no total (m): | D50: 1870 | F50: constam na planta, sem abertura visível; contam como obra a executar
A51: Passeio (calçada) existente: | D51: 0.05 | F51: 12 ponto(s) do Street View
A52: Passeio faltante (m de via aberta): | D52: =(B46-D50)*(1-D51) -> 32796.28 | F52: metros de VIA sem calçada completa nos dois lados (não é metro linear de calçada)
A53: Passeio faltante (m²): | D53: =ROUND(D52*4,0) -> 131185 | F53: 4.00 m² de calçada por metro de via (dois lados, larguras da planta)
A54: Pontos verificados — em vias nomeadas: | D54: 3
A55: Pontos verificados — na malha física sem nome no mapa: | D55: 24 | F55: verificados e usados na taxa do loteamento; ver aba Pontos auditados
A56: Pavimento sobre metragem medida (m): | D56: 0
A57: Pavimento sobre metragem só de planta (m): | D57: 0 | F57: sem traçado medido — existência a confirmar em campo

Sheet 10 Parque dos Albatrozes
A1: Loteamento Parque dos Albatrozes — planta nº 10
A2: Proprietário/empreendedor: BINOTTE Emp. Imobiliários | Matrícula: 2.383 (18/06/1980) | Área oficial: 757.170 m²
A3: Pontos verificados neste loteamento: 54 (54 atribuídos a vias nomeadas + 0 na malha física sem nome no mapa). Metragem com traçado medido: 17.996 m; só de planta: 0 m. Todos os pontos estão listados na aba 'Pontos auditados'.
A5: Rua / via | B5: Extensão da via (m) | C5: Situação da pista | D5: % pista pavimentada | E5: Pavimentado (m) | F5: Falta pavimentar (m) | G5: Caixa de via — planta (m) | H5: Origem da largura | I5: Largura de pista adotada (m) | J5: Falta pavimentar (m²) | K5: Confiança | L5: Passeio (calçada) | M5: % passeio (via) | N5: Pontos próprios | O5: Origem da classificação | P5: Metragem | Q5: Observações
A6: Sétima Avenida | B6: 1101.1 | C6: Não pavimentada | D6: 0 | E6: =ROUND(B6*D6,1) -> 0 | F6: =B6-E6 -> 1101.1 | G6: 15 | H6: quadro/legenda da planta | I6: 11 | J6: =ROUND(F6*I6,0) -> 12112 | K6: alta | L6: Parcial | M6: 0.33 | N6: 3 | O6: 3 ponto(s): 3 SV + 0 satélite (areia) | P6: medida (traçado) | Q6: Areia/bege no satelite (hz_18315/18355).
A7: Avenida Homero Zordan | B7: 1377.1 | C7: Parcial | D7: 0.42 | E7: =ROUND(B7*D7,1) -> 578.4 | F7: =B7-E7 -> 798.7 | G7: 12 | H7: mediana da planta | I7: 8 | J7: =ROUND(F7*I7,0) -> 6390 | K7: alta | L7: Parcial | M7: 0.32 | N7: 4 | O7: 4 ponto(s): 4 SV + 0 satélite (areia, bloquete) | P7: medida (traçado) | Q7: OSM dirt+paving_stones; satelite mostra cinza no trecho central (cruzamento com o eixo asfaltado Othovarino e junto a Esbertalina/praca de eventos); extremo oeste e trecho junto a orla em tom areia.
A8: Avenida Espera Feliz | B8: 536.1 | C8: Parcial | D8: 0.52 | E8: =ROUND(B8*D8,1) -> 278.8 | F8: =B8-E8 -> 257.3 | G8: 12 | H8: mediana da planta | I8: 8 | J8: =ROUND(F8*I8,0) -> 2058 | K8: baixa | L8: Não avaliável | M8: — | N8: 0 | O8: trecho curto sem ponto próprio — adotada a situação da mesma via (nome próprio, loteamento contíguo) em 6 ponto(s): p13=0%, p14=100%, p60=0% | P8: medida (traçado) | Q8: Pavimentada (cinza, rotatoria e ponto de onibus) da diagonal Othovarino ate a orla; toco oeste em areia.
A9: Rua Pedro Alves Ribeiro | B9: 624.3 | C9: Não pavimentada | D9: 0 | E9: =ROUND(B9*D9,1) -> 0 | F9: =B9-E9 -> 624.3 | G9: 12 | H9: mediana da planta | I9: 8 | J9: =ROUND(F9*I9,0) -> 4994 | K9: alta | L9: Parcial | M9: 0.25 | N9: 2 | O9: 2 ponto(s): 2 SV + 0 satélite (areia) | P9: medida (traçado) | Q9: Areia/bege no satelite (hz_18315/18355).
A10: Rua Elisa Maria Ditthz de Abreu Costa | B10: 598.3 | C10: Não pavimentada | D10: 0 | E10: =ROUND(B10*D10,1) -> 0 | F10: =B10-E10 -> 598.3 | G10: 12 | H10: mediana da planta | I10: 8 | J10: =ROUND(F10*I10,0) -> 4786 | K10: alta | L10: Não | M10: 0 | N10: 2 | O10: 2 ponto(s): 2 SV + 0 satélite (areia) | P10: medida (traçado) | Q10: Areia/bege no satelite (hz_18315/18355).
A11: (sem nome) | B11: 346.1 | C11: Não pavimentada | D11: 0 | E11: =ROUND(B11*D11,1) -> 0 | F11: =B11-E11 -> 346.1 | G11: 12 | H11: mediana da planta | I11: 8 | J11: =ROUND(F11*I11,0) -> 2769 | K11: alta | L11: Parcial | M11: 0.5 | N11: 1 | O11: 1 ponto(s): 1 SV + 0 satélite (saibro) | P11: medida (traçado) | Q11: 3 ways paving_stones+unpaved; vielas junto ao eixo Esbertalina.
A12: Avenida Esbertalina Barbosa Damiani | B12: 21.6 | C12: Pavimentada | D12: 1 | E12: =ROUND(B12*D12,1) -> 21.6 | F12: =B12-E12 -> 0 | G12: 12 | H12: mediana da planta | I12: 8 | J12: =ROUND(F12*I12,0) -> 0 | K12: alta | L12: Sim (maioria) | M12: 1 | N12: 1 | O12: 1 ponto(s): 1 SV + 0 satélite (asfalto) | P12: medida (traçado) | Q12: Toco de 22 m na rotatoria com a Espera Feliz; cinza no satelite.
A13: Rua Álvaro Leal Calmon | B13: 596 | C13: Não pavimentada | D13: 0 | E13: =ROUND(B13*D13,1) -> 0 | F13: =B13-E13 -> 596 | G13: 12 | H13: mediana da planta | I13: 8 | J13: =ROUND(F13*I13,0) -> 4768 | K13: alta | L13: Parcial | M13: 0.25 | N13: 2 | O13: 2 ponto(s): 2 SV + 0 satélite (saibro) | P13: medida (traçado) | Q13: Areia/bege no satelite (hz_18315/18355).
A14: Rua Raísa Bastos Magnago | B14: 592.3 | C14: Não pavimentada | D14: 0 | E14: =ROUND(B14*D14,1) -> 0 | F14: =B14-E14 -> 592.3 | G14: 12 | H14: mediana da planta | I14: 8 | J14: =ROUND(F14*I14,0) -> 4738 | K14: alta | L14: Parcial | M14: 0.31 | N14: 2 | O14: 2 ponto(s): 2 SV + 0 satélite (saibro) | P14: medida (traçado) | Q14: Areia/bege no satelite (hz_18315/18355).
A15: Rua Octávio Borotto | B15: 361.4 | C15: Não pavimentada | D15: 0 | E15: =ROUND(B15*D15,1) -> 0 | F15: =B15-E15 -> 361.4 | G15: 12 | H15: mediana da planta | I15: 8 | J15: =ROUND(F15*I15,0) -> 2891 | K15: alta | L15: Sim (maioria) | M15: 1 | N15: 1 | O15: 1 ponto(s): 1 SV + 0 satélite (saibro) | P15: medida (traçado) | Q15: Areia/bege no satelite (hz_18315/18355).
A16: Rua Odílio Nico | B16: 558.1 | C16: Não pavimentada | D16: 0 | E16: =ROUND(B16*D16,1) -> 0 | F16: =B16-E16 -> 558.1 | G16: 12 | H16: mediana da planta | I16: 8 | J16: =ROUND(F16*I16,0) -> 4465 | K16: alta | L16: Parcial | M16: 0.5 | N16: 2 | O16: 2 ponto(s): 2 SV + 0 satélite (saibro) | P16: medida (traçado) | Q16: Areia/bege no satelite (hz_18315/18355).
A17: Rua Albino Negris | B17: 595.8 | C17: Parcial | D17: 0.5 | E17: =ROUND(B17*D17,1) -> 297.9 | F17: =B17-E17 -> 297.9 | G17: 12 | H17: mediana da planta | I17: 8 | J17: =ROUND(F17*I17,0) -> 2383 | K17: alta | L17: Sim (maioria) | M17: 0.75 | N17: 2 | O17: 2 ponto(s): 2 SV + 0 satélite (bloquete, saibro) | P17: medida (traçado) | Q17: Areia/bege no satelite (hz_18315/18355).
A18: Rua Adriana Barbosa Caran | B18: 102 | C18: Pavimentada | D18: 1 | E18: =ROUND(B18*D18,1) -> 102 | F18: =B18-E18 -> 0 | G18: 12 | H18: mediana da planta | I18: 8 | J18: =ROUND(F18*I18,0) -> 0 | K18: alta | L18: Parcial | M18: 0.5 | N18: 1 | O18: 1 ponto(s): 1 SV + 0 satélite (bloquete) | P18: medida (traçado) | Q18: Areia/bege no satelite (hz_18315/18355). | SV: pavimentada no trecho sul, areia ao norte
A19: Rua Rogério Campista Correia | B19: 351.2 | C19: Não pavimentada | D19: 0 | E19: =ROUND(B19*D19,1) -> 0 | F19: =B19-E19 -> 351.2 | G19: 12 | H19: mediana da planta | I19: 8 | J19: =ROUND(F19*I19,0) -> 2810 | K19: alta | L19: Parcial | M19: 0.5 | N19: 1 | O19: 1 ponto(s): 1 SV + 0 satélite (saibro) | P19: medida (traçado) | Q19: Areia/bege no satelite (hz_18315/18355).
A20: Jamil Alhakim Ribeiro | B20: 347.5 | C20: Não pavimentada | D20: 0 | E20: =ROUND(B20*D20,1) -> 0 | F20: =B20-E20 -> 347.5 | G20: 12 | H20: mediana da planta | I20: 8 | J20: =ROUND(F20*I20,0) -> 2780 | K20: alta | L20: Parcial | M20: 0.5 | N20: 1 | O20: 1 ponto(s): 1 SV + 0 satélite (saibro) | P20: medida (traçado) | Q20: Areia/bege no satelite (hz_18315/18355).
... A37: Rua Maria Tezolin Carrafa | B37: 171.6 | C37: Não pavimentada | D37: 0 | E37: =ROUND(B37*D37,1) -> 0 | F37: =B37-E37 -> 171.6 | G37: 12 | H37: mediana da planta | I37: 8 | J37: =ROUND(F37*I37,0) -> 1373 | K37: alta | L37: Não | M37: 0 | N37: 1 | O37: 1 ponto(s): 1 SV + 0 satélite (saibro) | P37: medida (traçado) | Q37: Areia/bege no satelite (hz_18315/18355).
A38: TOTAL | B38: =SUM(B6:B37) -> 17996.4 | D38: =IF(B38=0,0,E38/B38) -> 0.31591318 | E38: =SUM(E6:E37) -> 5685.3 | F38: =SUM(F6:F37) -> 12311.1 | J38: =SUM(J6:J37) -> 104760
A40: Falta pavimentar — pista (m²), larguras da planta: | D40: =J38 -> 104760 | F40: soma da coluna J (falta × largura de pista de cada via)
A41: Falta pavimentar — pista (m²), premissa única de 8 m: | D41: =F38*8 -> 98488.8 | F41: base de comparação com a versão anterior do levantamento
A42: Vias não abertas incluídas no total (m): | D42: 0 | F42: constam na planta, sem abertura visível; contam como obra a executar
A43: Passeio (calçada) existente: | D43: 0.53 | F43: 54 ponto(s) do Street View
A44: Passeio faltante (m de via aberta): | D44: =(B38-D42)*(1-D43) -> 8458.308 | F44: metros de VIA sem calçada completa nos dois lados (não é metro linear de calçada)
A45: Passeio faltante (m²): | D45: =ROUND(D44*4,0) -> 33833 | F45: 4.00 m² de calçada por metro de via (dois lados, larguras da planta)
A46: Pontos verificados — em vias nomeadas: | D46: 54
A47: Pontos verificados — na malha física sem nome no mapa: | D47: 0 | F47: verificados e usados na taxa do loteamento; ver aba Pontos auditados
A48: Pavimento sobre metragem medida (m): | D48: 5685
A49: Pavimento sobre metragem só de planta (m): | D49: 0 | F49: sem traçado medido — existência a confirmar em campo

Sheet 13 Praia de Guriri
A1: Loteamento Praia de Guriri — planta nº 13
A2: Proprietário/empreendedor: Dalla Bernardina Imob. | Matrícula: 2.025 (06/07/1983) | Área oficial: 625.209 m²
A3: Pontos verificados neste loteamento: 57 (57 atribuídos a vias nomeadas + 0 na malha física sem nome no mapa). Metragem com traçado medido: 12.416 m; só de planta: 0 m. Todos os pontos estão listados na aba 'Pontos auditados'.
A5: Rua / via | B5: Extensão da via (m) | C5: Situação da pista | D5: % pista pavimentada | E5: Pavimentado (m) | F5: Falta pavimentar (m) | G5: Caixa de via — planta (m) | H5: Origem da largura | I5: Largura de pista adotada (m) | J5: Falta pavimentar (m²) | K5: Confiança | L5: Passeio (calçada) | M5: % passeio (via) | N5: Pontos próprios | O5: Origem da classificação | P5: Metragem | Q5: Observações
A6: Rua XXXII | B6: 143.9 | C6: Pavimentada | D6: 1 | E6: =ROUND(B6*D6,1) -> 143.9 | F6: =B6-E6 -> 0 | G6: 12 | H6: moda da ilha (12 m) | I6: 8 | J6: =ROUND(F6*I6,0) -> 0 | K6: alta | L6: Não | M6: 0 | N6: 1 | O6: 1 ponto(s): 1 SV + 0 satélite (bloquete) | P6: medida (traçado) | Q6: areia clara no satelite (hz_18275_O/hz_18315_O)
A7: Rua Antônio Massucatti | B7: 467.7 | C7: Não pavimentada | D7: 0 | E7: =ROUND(B7*D7,1) -> 0 | F7: =B7-E7 -> 467.7 | G7: 12 | H7: moda da ilha (12 m) | I7: 8 | J7: =ROUND(F7*I7,0) -> 3742 | K7: média | L7: Não | M7: 0 | N7: 1 | O7: 1 ponto(s): 1 SV + 0 satélite (saibro) | P7: medida (traçado) | Q7: areia clara no satelite (hz_18275_O/hz_18315_O)
A8: Rua Antônio Cunha Filho | B8: 189.3 | C8: Não pavimentada | D8: 0 | E8: =ROUND(B8*D8,1) -> 0 | F8: =B8-E8 -> 189.3 | G8: 12 | H8: moda da ilha (12 m) | I8: 8 | J8: =ROUND(F8*I8,0) -> 1514 | K8: alta | L8: Parcial | M8: 0.5 | N8: 1 | O8: 1 ponto(s): 1 SV + 0 satélite (saibro) | P8: medida (traçado) | Q8: areia clara no satelite (hz_18275_O/hz_18315_O)
A9: Rua Trinta e Sete | B9: 522.3 | C9: Não pavimentada | D9: 0 | E9: =ROUND(B9*D9,1) -> 0 | F9: =B9-E9 -> 522.3 | G9: 12 | H9: moda da ilha (12 m) | I9: 8 | J9: =ROUND(F9*I9,0) -> 4178 | K9: alta | L9: Parcial | M9: 0.25 | N9: 2 | O9: 2 ponto(s): 2 SV + 0 satélite (saibro) | P9: medida (traçado) | Q9: areia clara no satelite (hz_18275_O/hz_18315_O)
A10: Rua Trinta e Nove | B10: 187.3 | C10: Não pavimentada | D10: 0 | E10: =ROUND(B10*D10,1) -> 0 | F10: =B10-E10 -> 187.3 | G10: 12 | H10: moda da ilha (12 m) | I10: 8 | J10: =ROUND(F10*I10,0) -> 1498 | K10: alta | L10: Parcial | M10: 0.5 | N10: 1 | O10: 1 ponto(s): 1 SV + 0 satélite (saibro) | P10: medida (traçado) | Q10: areia clara no satelite (hz_18275_O/hz_18315_O)
A11: Rua Trinta e Cinco | B11: 75.3 | C11: Pavimentada | D11: 1 | E11: =ROUND(B11*D11,1) -> 75.3 | F11: =B11-E11 -> 0 | G11: 12 | H11: moda da ilha (12 m) | I11: 8 | J11: =ROUND(F11*I11,0) -> 0 | K11: alta | L11: Parcial | M11: 0.5 | N11: 1 | O11: 1 ponto(s): 1 SV + 0 satélite (bloquete) | P11: medida (traçado) | Q11: areia clara no satelite (hz_18275_O/hz_18315_O) | SV nov/2023: bloquete sextavado (R. XXXV)
A12: Rua Climéria Santos Barcellos | B12: 98.5 | C12: Não pavimentada | D12: 0 | E12: =ROUND(B12*D12,1) -> 0 | F12: =B12-E12 -> 98.5 | G12: 12 | H12: moda da ilha (12 m) | I12: 8 | J12: =ROUND(F12*I12,0) -> 788 | K12: alta | L12: Não | M12: 0 | N12: 1 | O12: 1 ponto(s): 1 SV + 0 satélite (saibro) | P12: medida (traçado) | Q12: areia clara no satelite (hz_18275_O/hz_18315_O)
A13: Rua Felisberto Fereguetti | B13: 405.9 | C13: Não pavimentada | D13: 0 | E13: =ROUND(B13*D13,1) -> 0 | F13: =B13-E13 -> 405.9 | G13: 12 | H13: moda da ilha (12 m) | I13: 8 | J13: =ROUND(F13*I13,0) -> 3247 | K13: alta | L13: Parcial | M13: 0.5 | N13: 1 | O13: 1 ponto(s): 1 SV + 0 satélite (saibro) | P13: medida (traçado) | Q13: areia clara no satelite (hz_18275_O/hz_18315_O)
A14: Rua José Bonomo | B14: 121.8 | C14: Não pavimentada | D14: 0 | E14: =ROUND(B14*D14,1) -> 0 | F14: =B14-E14 -> 121.8 | G14: 12 | H14: moda da ilha (12 m) | I14: 8 | J14: =ROUND(F14*I14,0) -> 974 | K14: alta | L14: Não | M14: 0 | N14: 1 | O14: 1 ponto(s): 1 SV + 0 satélite (saibro) | P14: medida (traçado) | Q14: areia clara no satelite (hz_18275_O/hz_18315_O)
A15: (sem nome) | B15: 639.2 | C15: Parcial | D15: 0.62 | E15: =ROUND(B15*D15,1) -> 396.3 | F15: =B15-E15 -> 242.9 | G15: 12 | H15: moda da ilha (12 m) | I15: 8 | J15: =ROUND(F15*I15,0) -> 1943 | K15: alta | L15: Não | M15: 0.18 | N15: 7 | O15: 7 ponto(s): 7 SV + 0 satélite (bloquete, saibro) | P15: medida (traçado) | Q15: segmentos difusos dirt/unpaved; zona toda em areia no satelite
A16: Rua Adelino Fereguetti | B16: 392 | C16: Não pavimentada | D16: 0 | E16: =ROUND(B16*D16,1) -> 0 | F16: =B16-E16 -> 392 | G16: 12 | H16: moda da ilha (12 m) | I16: 8 | J16: =ROUND(F16*I16,0) -> 3136 | K16: alta | L16: Não | M16: 0 | N16: 1 | O16: 1 ponto(s): 1 SV + 0 satélite (saibro) | P16: medida (traçado) | Q16: areia clara no satelite (hz_18275_O/hz_18315_O)
A17: Rua Domingos Carrafa | B17: 183.9 | C17: Não pavimentada | D17: 0 | E17: =ROUND(B17*D17,1) -> 0 | F17: =B17-E17 -> 183.9 | G17: 12 | H17: moda da ilha (12 m) | I17: 8 | J17: =ROUND(F17*I17,0) -> 1471 | K17: alta | L17: Parcial | M17: 0.5 | N17: 1 | O17: 1 ponto(s): 1 SV + 0 satélite (saibro) | P17: medida (traçado) | Q17: areia clara no satelite (hz_18275_O/hz_18315_O)
... A45: Rodovia Othovarino Duarte Santos | B45: 479.6 | C45: Pavimentada | D45: 1 | E45: =ROUND(B45*D45,1) -> 479.6 | F45: =B45-E45 -> 0 | G45: 12 | H45: moda da ilha (12 m) | I45: 8 | J45: =ROUND(F45*I45,0) -> 0 | K45: média | L45: Sim (maioria) | M45: 1 | N45: 1 | O45: 1 ponto(s): 1 SV + 0 satélite (asfalto) | P45: medida (traçado) | Q45: trecho junto a ponte/limite oeste; cinza no canto do quadro hz_18275_O, parcialmente fora das imagens
A46: TOTAL | B46: =SUM(B6:B45) -> 12416.1 | D46: =IF(B46=0,0,E46/B46) -> 0.21675889 | E46: =SUM(E6:E45) -> 2691.3 | F46: =SUM(F6:F45) -> 9724.8 | J46: =SUM(J6:J45) -> 77796
A48: Falta pavimentar — pista (m²), larguras da planta: | D48: =J46 -> 77796 | F48: soma da coluna J (falta × largura de pista de cada via)
A49: Falta pavimentar — pista (m²), premissa única de 8 m: | D49: =F46*8 -> 77798.4 | F49: base de comparação com a versão anterior do levantamento
A50: Vias não abertas incluídas no total (m): | D50: 0 | F50: constam na planta, sem abertura visível; contam como obra a executar
A51: Passeio (calçada) existente: | D51: 0.27 | F51: 56 ponto(s) do Street View
A52: Passeio faltante (m de via aberta): | D52: =(B46-D50)*(1-D51) -> 9063.753 | F52: metros de VIA sem calçada completa nos dois lados (não é metro linear de calçada)
A53: Passeio faltante (m²): | D53: =ROUND(D52*4,0) -> 36255 | F53: 4.00 m² de calçada por metro de via (dois lados, larguras da planta)
A54: Pontos verificados — em vias nomeadas: | D54: 57
A55: Pontos verificados — na malha física sem nome no mapa: | D55: 0 | F55: verificados e usados na taxa do loteamento; ver aba Pontos auditados
A56: Pavimento sobre metragem medida (m): | D56: 2691
A57: Pavimento sobre metragem só de planta (m): | D57: 0 | F57: sem traçado medido — existência a confirmar em campo

Sheet 14 Jardim das Caiçaras
A1: Loteamento Jardim das Caiçaras — planta nº 14
A2: Proprietário/empreendedor: Caiçaras Emp. Imobiliários | Matrícula: 4.170 (05/05/1986) | Área oficial: 1.141.458 m²
A3: Pontos verificados neste loteamento: 78 (78 atribuídos a vias nomeadas + 0 na malha física sem nome no mapa). Metragem com traçado medido: 21.908 m; só de planta: 0 m. Todos os pontos estão listados na aba 'Pontos auditados'.
A5: Rua / via | B5: Extensão da via (m) | C5: Situação da pista | D5: % pista pavimentada | E5: Pavimentado (m) | F5: Falta pavimentar (m) | G5: Caixa de via — planta (m) | H5: Origem da largura | I5: Largura de pista adotada (m) | J5: Falta pavimentar (m²) | K5: Confiança | L5: Passeio (calçada) | M5: % passeio (via) | N5: Pontos próprios | O5: Origem da classificação | P5: Metragem | Q5: Observações
A6: Rua XXXII | B6: 156.6 | C6: Pavimentada | D6: 1 | E6: =ROUND(B6*D6,1) -> 156.6 | F6: =B6-E6 -> 0 | G6: 12 | H6: moda da ilha (12 m) | I6: 8 | J6: =ROUND(F6*I6,0) -> 0 | K6: alta | L6: Sim (maioria) | M6: 1 | N6: 1 | O6: 1 ponto(s): 1 SV + 0 satélite (bloquete) | P6: medida (traçado) | Q6: Areia/bege no satelite (hz_18275/18315).
A7: Rua Antônio Cunha Filho | B7: 156.6 | C7: Não pavimentada | D7: 0 | E7: =ROUND(B7*D7,1) -> 0 | F7: =B7-E7 -> 156.6 | G7: 12 | H7: moda da ilha (12 m) | I7: 8 | J7: =ROUND(F7*I7,0) -> 1253 | K7: alta | L7: Não | M7: 0 | N7: 1 | O7: 1 ponto(s): 1 SV + 0 satélite (saibro) | P7: medida (traçado) | Q7: Areia/bege no satelite (hz_18275/18315).
A8: Rua Trinta e Cinco | B8: 156.6 | C8: Não pavimentada | D8: 0 | E8: =ROUND(B8*D8,1) -> 0 | F8: =B8-E8 -> 156.6 | G8: 12 | H8: moda da ilha (12 m) | I8: 8 | J8: =ROUND(F8*I8,0) -> 1253 | K8: alta | L8: Não | M8: 0 | N8: 1 | O8: 1 ponto(s): 1 SV + 0 satélite (saibro) | P8: medida (traçado) | Q8: Areia/bege no satelite (hz_18275/18315).
A9: Rua Climéria Santos Barcellos | B9: 154.7 | C9: Não pavimentada | D9: 0 | E9: =ROUND(B9*D9,1) -> 0 | F9: =B9-E9 -> 154.7 | G9: 12 | H9: moda da ilha (12 m) | I9: 8 | J9: =ROUND(F9*I9,0) -> 1238 | K9: alta | L9: Não | M9: 0 | N9: 1 | O9: 1 ponto(s): 1 SV + 0 satélite (saibro) | P9: medida (traçado) | Q9: Areia/bege no satelite (hz_18275/18315).
A10: Rua José Bonomo | B10: 155.7 | C10: Não pavimentada | D10: 0 | E10: =ROUND(B10*D10,1) -> 0 | F10: =B10-E10 -> 155.7 | G10: 12 | H10: moda da ilha (12 m) | I10: 8 | J10: =ROUND(F10*I10,0) -> 1246 | K10: alta | L10: Não | M10: 0 | N10: 1 | O10: 1 ponto(s): 1 SV + 0 satélite (saibro) | P10: medida (traçado) | Q10: Areia/bege no satelite (hz_18275/18315).
A11: Rua Domingos Carrafa | B11: 156.6 | C11: Pavimentada | D11: 1 | E11: =ROUND(B11*D11,1) -> 156.6 | F11: =B11-E11 -> 0 | G11: 12 | H11: moda da ilha (12 m) | I11: 8 | J11: =ROUND(F11*I11,0) -> 0 | K11: alta | L11: Não | M11: 0 | N11: 1 | O11: 1 ponto(s): 1 SV + 0 satélite (bloquete) | P11: medida (traçado) | Q11: Areia/bege no satelite (hz_18275/18315).
A12: Décima Primeira Avenida | B12: 917.1 | C12: Não pavimentada | D12: 0 | E12: =ROUND(B12*D12,1) -> 0 | F12: =B12-E12 -> 917.1 | G12: 12 | H12: moda da ilha (12 m) | I12: 8 | J12: =ROUND(F12*I12,0) -> 7337 | K12: alta | L12: Não | M12: 0 | N12: 3 | O12: 3 ponto(s): 3 SV + 0 satélite (areia) | P12: medida (traçado) | Q12: Areia/bege no satelite (hz_18275/18315).
A13: Rua Conceição da Barra | B13: 783 | C13: Não pavimentada | D13: 0 | E13: =ROUND(B13*D13,1) -> 0 | F13: =B13-E13 -> 783 | G13: 12 | H13: moda da ilha (12 m) | I13: 8 | J13: =ROUND(F13*I13,0) -> 6264 | K13: alta | L13: Parcial | M13: 0.25 | N13: 2 | O13: 2 ponto(s): 2 SV + 0 satélite (areia) | P13: medida (traçado) | Q13: Areia/bege no satelite (hz_18275/18315).
A14: Rua Linhares | B14: 723.3 | C14: Não pavimentada | D14: 0 | E14: =ROUND(B14*D14,1) -> 0 | F14: =B14-E14 -> 723.3 | G14: 12 | H14: moda da ilha (12 m) | I14: 8 | J14: =ROUND(F14*I14,0) -> 5786 | K14: alta | L14: Não | M14: 0 | N14: 2 | O14: 2 ponto(s): 2 SV + 0 satélite (areia, saibro) | P14: medida (traçado) | Q14: Areia/bege no satelite (hz_18275/18315).
A15: (sem nome) | B15: 1935.5 | C15: Parcial | D15: 0.74 | E15: =ROUND(B15*D15,1) -> 1432.3 | F15: =B15-E15 -> 503.2 | G15: 12 | H15: moda da ilha (12 m) | I15: 8 | J15: =ROUND(F15*I15,0) -> 4026 | K15: alta | L15: Parcial | M15: 0.38 | N15: 13 | O15: 13 ponto(s): 8 SV + 5 satélite (areia, asfalto, bloquete, saibro) | P15: medida (traçado) | Q15: 16 ways mistos; inclui trecho tertiary com bloquete junto a orla/ES-010 (cinza no satelite) e vielas de areia.
A16: Avenida Espera Feliz | B16: 555.1 | C16: Pavimentada | D16: 1 | E16: =ROUND(B16*D16,1) -> 555.1 | F16: =B16-E16 -> 0 | G16: 12 | H16: moda da ilha (12 m) | I16: 8 | J16: =ROUND(F16*I16,0) -> 0 | K16: alta | L16: Parcial | M16: 0.5 | N16: 3 | O16: 3 ponto(s): 3 SV + 0 satélite (bloquete) | P16: medida (traçado) | Q16: Cinza no satelite da diagonal Othovarino ate a orla; rotatoria na Esbertalina e ponto de onibus; so o toco oeste (~-39.765..-39.769) em areia.
A17: Avenida Nafice Aihakim Ribeiro | B17: 526.6 | C17: Não pavimentada | D17: 0 | E17: =ROUND(B17*D17,1) -> 0 | F17: =B17-E17 -> 526.6 | G17: 12 | H17: moda da ilha (12 m) | I17: 8 | J17: =ROUND(F17*I17,0) -> 4213 | K17: média | L17: Não avaliável | M17: — | N17: 0 | O17: trecho curto sem ponto próprio — adotada a situação da mesma via (nome próprio, loteamento contíguo) em 3 ponto(s): p13=0% | P17: medida (traçado) | Q17: Areia/bege no satelite (hz_18275/18315).
A18: Rua Odílio Nico | B18: 722 | C18: Não pavimentada | D18: 0 | E18: =ROUND(B18*D18,1) -> 0 | F18: =B18-E18 -> 722 | G18: 12 | H18: moda da ilha (12 m) | I18: 8 | J18: =ROUND(F18*I18,0) -> 5776 | K18: alta | L18: Não | M18: 0 | N18: 2 | O18: 2 ponto(s): 2 SV + 0 satélite (areia) | P18: medida (traçado) | Q18: Areia/bege no satelite (hz_18275/18315).
A19: Rua Edith Laura Moreira D'Almeida | B19: 155.7 | C19: Não pavimentada | D19: 0 | E19: =ROUND(B19*D19,1) -> 0 | F19: =B19-E19 -> 155.7 | G19: 12 | H19: moda da ilha (12 m) | I19: 8 | J19: =ROUND(F19*I19,0) -> 1246 | K19: alta | L19: Parcial | M19: 0.5 | N19: 1 | O19: 1 ponto(s): 1 SV + 0 satélite (saibro) | P19: medida (traçado) | Q19: Areia/bege no satelite (hz_18275/18315).
A20: Rua Professor Amaro Nascimento Mendes | B20: 820.7 | C20: Não pavimentada | D20: 0 | E20: =ROUND(B20*D20,1) -> 0 | F20: =B20-E20 -> 820.7 | G20: 12 | H20: moda da ilha (12 m) | I20: 8 | J20: =ROUND(F20*I20,0) -> 6566 | K20: alta | L20: Não | M20: 0 | N20: 2 | O20: 2 ponto(s): 2 SV + 0 satélite (saibro) | P20: medida (traçado) | Q20: Areia/bege no satelite (hz_18275/18315).
A21: Rua XXV | B21: 157.5 | C21: Não pavimentada | D21: 0 | E21: =ROUND(B21*D21,1) -> 0 | F21: =B21-E21 -> 157.5 | G21: 12 | H21: moda da ilha (12 m) | I21: 8 | J21: =ROUND(F21*I21,0) -> 1260 | K21: alta | L21: Não | M21: 0 | N21: 1 | O21: 1 ponto(s): 1 SV + 0 satélite (saibro) | P21: medida (traçado) | Q21: Areia/bege no satelite (hz_18275/18315).
A22: Rua XVI | B22: 337.3 | C22: Pavimentada | D22: 1 | E22: =ROUND(B22*D22,1) -> 337.3 | F22: =B22-E22 -> 0 | G22: 12 | H22: moda da ilha (12 m) | I22: 8 | J22: =ROUND(F22*I22,0) -> 0 | K22: alta | L22: Não | M22: 0 | N22: 1 | O22: 1 ponto(s): 1 SV + 0 satélite (bloquete) | P22: medida (traçado) | Q22: Areia/bege no satelite (hz_18275/18315).
A23: Rua XIII | B23: 432 | C23: Não pavimentada | D23: 0 | E23: =ROUND(B23*D23,1) -> 0 | F23: =B23-E23 -> 432 | G23: 12 | H23: moda da ilha (12 m) | I23: 8 | J23: =ROUND(F23*I23,0) -> 3456 | K23: alta | L23: Não | M23: 0 | N23: 1 | O23: 1 ponto(s): 1 SV + 0 satélite (saibro) | P23: medida (traçado) | Q23: Areia/bege no satelite (hz_18275/18315).
A24: Rua XVII | B24: 196.1 | C24: Pavimentada | D24: 1 | E24: =ROUND(B24*D24,1) -> 196.1 | F24: =B24-E24 -> 0 | G24: 12 | H24: moda da ilha (12 m) | I24: 8 | J24: =ROUND(F24*I24,0) -> 0 | K24: alta | L24: Não | M24: 0 | N24: 1 | O24: 1 ponto(s): 1 SV + 0 satélite (bloquete) | P24: medida (traçado) | Q24: Areia/bege no satelite (hz_18275/18315).
A25: Rua Elisa Maria Ditthz de Abreu Costa | B25: 375 | C25: Não pavimentada | D25: 0 | E25: =ROUND(B25*D25,1) -> 0 | F25: =B25-E25 -> 375 | G25: 12 | H25: moda da ilha (12 m) | I25: 8 | J25: =ROUND(F25*I25,0) -> 3000 | K25: alta | L25: Parcial | M25: 0.5 | N25: 1 | O25: 1 ponto(s): 1 SV + 0 satélite (saibro) | P25: medida (traçado) | Q25: Areia/bege no satelite (hz_18275/18315).
A26: Rua Adriana Barbosa Caran | B26: 631.3 | C26: Não pavimentada | D26: 0 | E26: =ROUND(B26*D26,1) -> 0 | F26: =B26-E26 -> 631.3 | G26: 12 | H26: moda da ilha (12 m) | I26: 8 | J26: =ROUND(F26*I26,0) -> 5050 | K26: alta | L26: Não | M26: 0 | N26: 2 | O26: 2 ponto(s): 2 SV + 0 satélite (saibro) | P26: medida (traçado) | Q26: Areia/bege no satelite (hz_18275/18315).
A27: Rua XIV | B27: 345.4 | C27: Não pavimentada | D27: 0 | E27: =ROUND(B27*D27,1) -> 0 | F27: =B27-E27 -> 345.4 | G27: 12 | H27: moda da ilha (12 m) | I27: 8 | J27: =ROUND(F27*I27,0) -> 2763 | K27: alta | L27: Não | M27: 0 | N27: 1 | O27: 1 ponto(s): 1 SV + 0 satélite (saibro) | P27: medida (traçado) | Q27: Areia/bege no satelite (hz_18275/18315).
A28: Rua Álvaro Leal Calmon | B28: 798.7 | C28: Não pavimentada | D28: 0 | E28: =ROUND(B28*D28,1) -> 0 | F28: =B28-E28 -> 798.7 | G28: 12 | H28: moda da ilha (12 m) | I28: 8 | J28: =ROUND(F28*I28,0) -> 6390 | K28: alta | L28: Não | M28: 0 | N28: 2 | O28: 2 ponto(s): 2 SV + 0 satélite (saibro) | P28: medida (traçado) | Q28: Areia/bege no satelite (hz_18275/18315).
A29: Rua Rogério Campista Correia | B29: 156.7 | C29: Não pavimentada | D29: 0 | E29: =ROUND(B29*D29,1) -> 0 | F29: =B29-E29 -> 156.7 | G29: 12 | H29: moda da ilha (12 m) | I29: 8 | J29: =ROUND(F29*I29,0) -> 1254 | K29: alta | L29: Não | M29: 0 | N29: 1 | O29: 1 ponto(s): 1 SV + 0 satélite (saibro) | P29: medida (traçado) | Q29: Areia/bege no satelite (hz_18275/18315).
... A53: Rua Esbertalina B. Damiani | B53: 1074.4 | C53: Parcial | D53: 0.5 | E53: =ROUND(B53*D53,1) -> 537.2 | F53: =B53-E53 -> 537.2 | G53: 12 | H53: moda da ilha (12 m) | I53: 8 | J53: =ROUND(F53*I53,0) -> 4298 | K53: alta | L53: Parcial | M53: 0.25 | N53: 2 | O53: 2 ponto(s): 2 SV + 0 satélite (areia, bloquete) | P53: medida (traçado) | Q53: Areia/bege no satelite (hz_18275/18315).
A54: TOTAL | B54: =SUM(B6:B53) -> 21907.8 | D54: =IF(B54=0,0,E54/B54) -> 0.17031377 | E54: =SUM(E6:E53) -> 3731.2 | F54: =SUM(F6:F53) -> 18176.6 | J54: =SUM(J6:J53) -> 145416
A56: Falta pavimentar — pista (m²), larguras da planta: | D56: =J54 -> 145416 | F56: soma da coluna J (falta × largura de pista de cada via)
A57: Falta pavimentar — pista (m²), premissa única de 8 m: | D57: =F54*8 -> 145412.8 | F57: base de comparação com a versão anterior do levantamento
A58: Vias não abertas incluídas no total (m): | D58: 0 | F58: constam na planta, sem abertura visível; contam como obra a executar
A59: Passeio (calçada) existente: | D59: 0.16 | F59: 73 ponto(s) do Street View
A60: Passeio faltante (m de via aberta): | D60: =(B54-D58)*(1-D59) -> 18402.552 | F60: metros de VIA sem calçada completa nos dois lados (não é metro linear de calçada)
A61: Passeio faltante (m²): | D61: =ROUND(D60*4,0) -> 73610 | F61: 4.00 m² de calçada por metro de via (dois lados, larguras da planta)
A62: Pontos verificados — em vias nomeadas: | D62: 78
A63: Pontos verificados — na malha física sem nome no mapa: | D63: 0 | F63: verificados e usados na taxa do loteamento; ver aba Pontos auditados
A64: Pavimento sobre metragem medida (m): | D64: 3731
A65: Pavimento sobre metragem só de planta (m): | D65: 0 | F65: sem traçado medido — existência a confirmar em campo

Sheet 15 Morada do Sol
A1: Loteamento Morada do Sol — planta nº 15
A2: Proprietário/empreendedor: Guriri Beach Turismo | Matrícula: 7.640 (09/10/1986) | Área oficial: 122.214 m²
A3: Pontos verificados neste loteamento: 15 (15 atribuídos a vias nomeadas + 0 na malha física sem nome no mapa). Metragem com traçado medido: 3.115 m; só de planta: 0 m. Todos os pontos estão listados na aba 'Pontos auditados'.
A5: Rua / via | B5: Extensão da via (m) | C5: Situação da pista | D5: % pista pavimentada | E5: Pavimentado (m) | F5: Falta pavimentar (m) | G5: Caixa de via — planta (m) | H5: Origem da largura | I5: Largura de pista adotada (m) | J5: Falta pavimentar (m²) | K5: Confiança | L5: Passeio (calçada) | M5: % passeio (via) | N5: Pontos próprios | O5: Origem da classificação | P5: Metragem | Q5: Observações
