Workbook

Sheet Resumo Geral
A1: Levantamento de pavimentação — Loteamentos de Guriri (São Mateus/ES)
A2: Pista = leito carroçável da rua; Passeio = calçada de pedestre. Elaborado em 19/08/2026 a partir de: plantas dos loteamentos, planilha oficial de loteamentos, OpenStreetMap (medição das vias) e AUDITORIA COMPLETA DE 637 PONTOS — 1 ponto a cada ~350 m de via, verificados um a um no Google Street View (517 pontos, imagens de fev/2012 a mai/2026, predominando nov-dez/2023 e mai/2026) e, onde não há cobertura de Street View, em imagem de satélite (120 pontos).
A3: Valores aproximados. Em cada ponto classificou-se a superfície da pista (asfalto e bloquete = pavimentada; saibro e areia = não pavimentada) e a existência de calçada nas testadas. 69% da metragem teve a situação decidida por ponto próprio; o restante herdou a taxa da mesma via em loteamento contíguo ou a taxa agregada da malha auditada do loteamento (ver coluna "Origem da classificação" em cada aba). Azul = premissa/entrada editável. Recomenda-se conferência em campo e junto à Prefeitura antes de uso oficial.
A5: Nº | B5: Loteamento | C5: Proprietário / empreendedor | D5: Matrícula (registro) | E5: Área oficial (m²) | F5: Nº de vias | G5: Extensão de vias (m) | H5: Pista pavimentada (m) | I5: % pavimentada | J5: Falta pavimentar — pista (m) | K5: Falta pavimentar — pista (m²) | L5: Passeio faltante (m de via) | M5: Passeio faltante (m²) | N5: Pontos auditados | O5: Metragem medida (m) | P5: Metragem só de planta (m) | Q5: Falta s/ metragem medida (m) | R5: Falta s/ metragem de planta (m) | S5: % passeio existente | T5: Confiança do passeio
A6: 7 | B6: Balneário de Guriri | C6: Município de São Mateus | D6: 7.798/3-J (22/02/1979) | E6: 578500 | F6: 20 | G6: ='07 Balneário de Guriri'!B26 -> 16241.4 | H6: ='07 Balneário de Guriri'!E26 -> 9731.3 | I6: =IF(G6=0,0,H6/G6) -> 0.59916633 | J6: ='07 Balneário de Guriri'!F26 -> 6510.1 | K6: ='07 Balneário de Guriri'!D28 -> 52080.8 | L6: ='07 Balneário de Guriri'!D31 -> 6496.56 | M6: ='07 Balneário de Guriri'!D32 -> 25986.24 | N6: 58 | O6: 16241 | P6: 0 | Q6: 6510 | R6: 0 | S6: 0.6 | T6: alta
A7: 9 | B7: Bosque da Praia | C7: TEGIL Territorial Guriri Ltda | D7: 2.315 (14/12/1979) | E7: 1728555 | F7: 40 | G7: ='09 Bosque da Praia'!B46 -> 36392.4 | H7: ='09 Bosque da Praia'!E46 -> 0 | I7: =IF(G7=0,0,H7/G7) -> 0 | J7: ='09 Bosque da Praia'!F46 -> 36392.4 | K7: ='09 Bosque da Praia'!D48 -> 291139.2 | L7: ='09 Bosque da Praia'!D51 -> 32796.28 | M7: ='09 Bosque da Praia'!D52 -> 131185.12 | N7: 27 | O7: 942 | P7: 35450 | Q7: 942 | R7: 35450 | S7: 0.05 | T7: média
A8: 10 | B8: Parque dos Albatrozes | C8: BINOTTE Emp. Imobiliários | D8: 2.383 (18/06/1980) | E8: 757170 | F8: 32 | G8: ='10 Parque dos Albatrozes'!B38 -> 17996.4 | H8: ='10 Parque dos Albatrozes'!E38 -> 5685.3 | I8: =IF(G8=0,0,H8/G8) -> 0.31591318 | J8: ='10 Parque dos Albatrozes'!F38 -> 12311.1 | K8: ='10 Parque dos Albatrozes'!D40 -> 98488.8 | L8: ='10 Parque dos Albatrozes'!D43 -> 8458.308 | M8: ='10 Parque dos Albatrozes'!D44 -> 33833.232 | N8: 54 | O8: 17996 | P8: 0 | Q8: 12311 | R8: 0 | S8: 0.53 | T8: alta
A9: 13 | B9: Praia de Guriri | C9: Dalla Bernardina Imob. | D9: 2.025 (06/07/1983) | E9: 625209.2 | F9: 40 | G9: ='13 Praia de Guriri'!B46 -> 12416.1 | H9: ='13 Praia de Guriri'!E46 -> 2691.3 | I9: =IF(G9=0,0,H9/G9) -> 0.21675889 | J9: ='13 Praia de Guriri'!F46 -> 9724.8 | K9: ='13 Praia de Guriri'!D48 -> 77798.4 | L9: ='13 Praia de Guriri'!D51 -> 9063.753 | M9: ='13 Praia de Guriri'!D52 -> 36255.012 | N9: 57 | O9: 12416 | P9: 0 | Q9: 9725 | R9: 0 | S9: 0.27 | T9: alta
A10: 14 | B10: Jardim das Caiçaras | C10: Caiçaras Emp. Imobiliários | D10: 4.170 (05/05/1986) | E10: 1141457.9 | F10: 48 | G10: ='14 Jardim das Caiçaras'!B54 -> 21907.8 | H10: ='14 Jardim das Caiçaras'!E54 -> 3731.2 | I10: =IF(G10=0,0,H10/G10) -> 0.17031377 | J10: ='14 Jardim das Caiçaras'!F54 -> 18176.6 | K10: ='14 Jardim das Caiçaras'!D56 -> 145412.8 | L10: ='14 Jardim das Caiçaras'!D59 -> 18402.552 | M10: ='14 Jardim das Caiçaras'!D60 -> 73610.208 | N10: 78 | O10: 21908 | P10: 0 | Q10: 18177 | R10: 0 | S10: 0.16 | T10: alta
A11: 15 | B11: Morada do Sol | C11: Guriri Beach Turismo | D11: 7.640 (09/10/1986) | E11: 122213.92 | F11: 13 | G11: ='15 Morada do Sol'!B19 -> 3114.8 | H11: ='15 Morada do Sol'!E19 -> 514.4 | I11: =IF(G11=0,0,H11/G11) -> 0.16514704 | J11: ='15 Morada do Sol'!F19 -> 2600.4 | K11: ='15 Morada do Sol'!D21 -> 20803.2 | L11: ='15 Morada do Sol'!D24 -> 1993.472 | M11: ='15 Morada do Sol'!D25 -> 7973.888 | N11: 15 | O11: 3115 | P11: 0 | Q11: 2600 | R11: 0 | S11: 0.36 | T11: alta
A12: 25 | B12: Parque Residencial Oitizeiro | C12: Alba Figueiredo Brasileiro | D12: 14.380 (02/06/2000) | E12: 557784.5 | F12: 31 | G12: ='25 Park Res. Oitizeiro'!B37 -> 13895.5 | H12: ='25 Park Res. Oitizeiro'!E37 -> 752.2 | I12: =IF(G12=0,0,H12/G12) -> 0.054132633 | J12: ='25 Park Res. Oitizeiro'!F37 -> 13143.3 | K12: ='25 Park Res. Oitizeiro'!D39 -> 105146.4 | L12: ='25 Park Res. Oitizeiro'!D42 -> 7781.48 | M12: ='25 Park Res. Oitizeiro'!D43 -> 31125.92 | N12: 41 | O12: 13896 | P12: 0 | Q12: 13143 | R12: 0 | S12: 0.44 | T12: alta
A13: 27 | B13: Residencial Mar Aberto | C13: Mirante Emp. Imobiliários | D13: 9.853 (25/08/2000) | E13: 387200 | F13: 35 | G13: ='27 Res. Mar Aberto'!B41 -> 6839 | H13: ='27 Res. Mar Aberto'!E41 -> 626.2 | I13: =IF(G13=0,0,H13/G13) -> 0.091563094 | J13: ='27 Res. Mar Aberto'!F41 -> 6212.8 | K13: ='27 Res. Mar Aberto'!D43 -> 49702.4 | L13: ='27 Res. Mar Aberto'!D46 -> 6702.22 | M13: ='27 Res. Mar Aberto'!D47 -> 26808.88 | N13: 33 | O13: 2731 | P13: 4108 | Q13: 2220 | R13: 3993 | S13: 0.02 | T13: alta
A14: 31 | B14: Melhorini Residencial Parque | C14: Domingos Melhorini | D14: 9.300 (26/11/2001) | E14: 70180 | F14: 10 | G14: ='31 Melhorini Res. Parque'!B16 -> 1520.9 | H14: ='31 Melhorini Res. Parque'!E16 -> 339.3 | I14: =IF(G14=0,0,H14/G14) -> 0.22309159 | J14: ='31 Melhorini Res. Parque'!F16 -> 1181.6 | K14: ='31 Melhorini Res. Parque'!D18 -> 9452.8 | L14: ='31 Melhorini Res. Parque'!D21 -> 1079.839 | M14: ='31 Melhorini Res. Parque'!D22 -> 4319.356 | N14: 10 | O14: 1521 | P14: 0 | Q14: 1182 | R14: 0 | S14: 0.29 | T14: média
A15: 35 | B15: Verão Vermelho | C15: Neri Mariani | D15: 16.265 (24/10/2003) | E15: 402084 | F15: 34 | G15: ='35 Verão Vermelho'!B40 -> 10602.1 | H15: ='35 Verão Vermelho'!E40 -> 425.3 | I15: =IF(G15=0,0,H15/G15) -> 0.040114694 | J15: ='35 Verão Vermelho'!F40 -> 10176.8 | K15: ='35 Verão Vermelho'!D42 -> 81414.4 | L15: ='35 Verão Vermelho'!D45 -> 6807.574 | M15: ='35 Verão Vermelho'!D46 -> 27230.296 | N15: 37 | O15: 2772 | P15: 7830 | Q15: 2347 | R15: 7830 | S15: 0.06 | T15: alta
A16: 36 | B16: Residencial Ilha de Guriri I | C16: Airton Ruberth | D16: 15.191 (12/11/2003) | E16: 77639 | F16: 9 | G16: ='36 Res. Ilha de Guriri I'!B15 -> 1995.2 | H16: ='36 Res. Ilha de Guriri I'!E15 -> 0 | I16: =IF(G16=0,0,H16/G16) -> 0 | J16: ='36 Res. Ilha de Guriri I'!F15 -> 1995.2 | K16: ='36 Res. Ilha de Guriri I'!D17 -> 15961.6 | L16: ='36 Res. Ilha de Guriri I'!D20 -> 1556.256 | M16: ='36 Res. Ilha de Guriri I'!D21 -> 6225.024 | N16: 9 | O16: 1995 | P16: 0 | Q16: 1995 | R16: 0 | S16: 0.22 | T16: média
A17: 39 | B17: Central | C17: Kajuzal Camping | D17: 16.104 (25/11/2003) | E17: 124388 | F17: 15 | G17: ='39 Central'!B21 -> 3725.3 | H17: ='39 Central'!E21 -> 435.4 | I17: =IF(G17=0,0,H17/G17) -> 0.11687649 | J17: ='39 Central'!F21 -> 3289.9 | K17: ='39 Central'!D23 -> 26319.2 | L17: ='39 Central'!D26 -> 2980.24 | M17: ='39 Central'!D27 -> 11920.96 | N17: 10 | O17: 3725 | P17: 0 | Q17: 3290 | R17: 0 | S17: 0.2 | T17: média
A18: 42 | B18: Residencial Bom Jesus | C18: Kajuzal Camping | D18: 15.989 (23/12/2003) | E18: 1089673.4 | F18: 22 | G18: ='42 Res. Bom Jesus'!B28 -> 23700.1 | H18: ='42 Res. Bom Jesus'!E28 -> 20665.5 | I18: =IF(G18=0,0,H18/G18) -> 0.87195835 | J18: ='42 Res. Bom Jesus'!F28 -> 3034.6 | K18: ='42 Res. Bom Jesus'!D30 -> 24276.8 | L18: ='42 Res. Bom Jesus'!D33 -> 18249.077 | M18: ='42 Res. Bom Jesus'!D34 -> 72996.308 | N18: 70 | O18: 21624 | P18: 2076 | Q18: 2702 | R18: 332 | S18: 0.23 | T18: alta
A19: 47 | B19: Praiano | C19: Praiano Guriri Clube | D19: 10.725 | E19: 96800 | F19: 15 | G19: ='47 Praiano'!B21 -> 2612.2 | H19: ='47 Praiano'!E21 -> 257.4 | I19: =IF(G19=0,0,H19/G19) -> 0.098537631 | J19: ='47 Praiano'!F21 -> 2354.8 | K19: ='47 Praiano'!D23 -> 18838.4 | L19: ='47 Praiano'!D26 -> 2063.638 | M19: ='47 Praiano'!D27 -> 8254.552 | N19: 15 | O19: 2612 | P19: 0 | Q19: 2355 | R19: 0 | S19: 0.21 | T19: alta
A20: 49 | B20: Vale do Amazonas | C20: Igor Vescovi Devens | D20: 15.185 | E20: 77639 | F20: 4 | G20: ='49 Vale do Amazonas'!B10 -> 1154.4 | H20: ='49 Vale do Amazonas'!E10 -> 0 | I20: =IF(G20=0,0,H20/G20) -> 0 | J20: ='49 Vale do Amazonas'!F10 -> 1154.4 | K20: ='49 Vale do Amazonas'!D12 -> 9235.2 | L20: ='49 Vale do Amazonas'!D15 -> 1154.4 | M20: ='49 Vale do Amazonas'!D16 -> 4617.6 | N20: 4 | O20: 1154 | P20: 0 | Q20: 1154 | R20: 0 | S20: 0 | T20: baixa
A21: 50 | B21: Flor Pan | C21: Antonio Costa | D21: 15.189 | E21: 77639 | F21: 7 | G21: ='50 Flor Pan'!B13 -> 1809.1 | H21: ='50 Flor Pan'!E13 -> 0 | I21: =IF(G21=0,0,H21/G21) -> 0 | J21: ='50 Flor Pan'!F13 -> 1809.1 | K21: ='50 Flor Pan'!D15 -> 14472.8 | L21: ='50 Flor Pan'!D18 -> 1320.643 | M21: ='50 Flor Pan'!D19 -> 5282.572 | N21: 9 | O21: 1809 | P21: 0 | Q21: 1809 | R21: 0 | S21: 0.27 | T21: média
A22: 60 | B22: Residencial Evidência | C22: Anildo Moreira Tavares | D22: 9.497 | E22: 138513.92 | F22: 22 | G22: ='60 Res. Evidência'!B28 -> 3885 | H22: ='60 Res. Evidência'!E28 -> 0 | I22: =IF(G22=0,0,H22/G22) -> 0 | J22: ='60 Res. Evidência'!F28 -> 3885 | K22: ='60 Res. Evidência'!D30 -> 31080 | L22: ='60 Res. Evidência'!D33 -> 2602.95 | M22: ='60 Res. Evidência'!D34 -> 10411.8 | N22: 22 | O22: 3885 | P22: 0 | Q22: 3885 | R22: 0 | S22: 0.33 | T22: alta
A23: 70 | B23: Pontal de Guriri | C23: João Bosco Cevolane | D23: 19.747 | E23: 244194.61 | F23: 17 | G23: ='70 Pontal de Guriri'!B23 -> 6052.1 | H23: ='70 Pontal de Guriri'!E23 -> 572 | I23: =IF(G23=0,0,H23/G23) -> 0.094512649 | J23: ='70 Pontal de Guriri'!F23 -> 5480.1 | K23: ='70 Pontal de Guriri'!D25 -> 43840.8 | L23: ='70 Pontal de Guriri'!D28 -> 5931.058 | M23: ='70 Pontal de Guriri'!D29 -> 23724.232 | N23: 28 | O23: 6052 | P23: 0 | Q23: 5480 | R23: 0 | S23: 0.02 | T23: alta
A24: 78 | B24: João de Barro (COHAJOBA) | C24: COHAJOBA | D24: 19.792 | E24: 54750 | F24: 10 | G24: ='78 João de Barro'!B16 -> 1490 | H24: ='78 João de Barro'!E16 -> 0 | I24: =IF(G24=0,0,H24/G24) -> 0 | J24: ='78 João de Barro'!F16 -> 1490 | K24: ='78 João de Barro'!D18 -> 11920 | L24: ='78 João de Barro'!D21 -> 1102 | M24: ='78 João de Barro'!D22 -> 4408 | N24: 14 | O24: 0 | P24: 1490 | Q24: 0 | R24: 1490 | S24: 0.05 | T24: baixa
A25: 80 | B25: Soma Cevolani (Golden Guriri) | C25: Soma Cevolani SPE | D25: 52.586 | E25: 234671.83 | F25: 8 | G25: ='80 Soma Cevolani'!B14 -> 4952 | H25: ='80 Soma Cevolani'!E14 -> 4952 | I25: =IF(G25=0,0,H25/G25) -> 1 | J25: ='80 Soma Cevolani'!F14 -> 0 | K25: ='80 Soma Cevolani'!D16 -> 0 | L25: ='80 Soma Cevolani'!D19 -> 4308.24 | M25: ='80 Soma Cevolani'!D20 -> 17232.96 | N25: 32 | O25: 0 | P25: 4952 | Q25: 0 | R25: 0 | S25: 0.13 | T25: baixa
A26: 84 | B26: Pontal de Guriri II | C26: João Bosco Cevolane Ltda | D26: 54.633 | E26: 44371.01 | F26: 5 | G26: ='84 Pontal de Guriri II'!B11 -> 1073 | H26: ='84 Pontal de Guriri II'!E11 -> 0 | I26: =IF(G26=0,0,H26/G26) -> 0 | J26: ='84 Pontal de Guriri II'!F11 -> 1073 | K26: ='84 Pontal de Guriri II'!D13 -> 8584 | L26: ='84 Pontal de Guriri II'!D16 -> 772.56 | M26: ='84 Pontal de Guriri II'!D17 -> 3090.24 | N26: 14 | O26: 0 | P26: 1073 | Q26: 0 | R26: 1073 | S26: 0.28 | T26: baixa
B27: TOTAL GERAL — GURIRI | F27: =SUM(F6:F26) -> 437 | G27: =SUM(G6:G26) -> 193374.8 | H27: =SUM(H6:H26) -> 51378.8 | I27: =IF(G27=0,0,H27/G27) -> 0.26569543 | J27: =SUM(J6:J26) -> 141996 | K27: =SUM(K6:K26) -> 1135968 | L27: =SUM(L6:L26) -> 141623.1 | M27: =SUM(M6:M26) -> 566492.4 | N27: =SUM(N6:N26) -> 637 | O27: =SUM(O6:O26) -> 136394 | P27: =SUM(P6:P26) -> 56979 | Q27: =SUM(Q6:Q26) -> 91827 | R27: =SUM(R6:R26) -> 50168
A29: Notas e premissas:
A30: • Falta pavimentar (m²) = metros lineares faltantes × 8 m (largura média de pista adotada como premissa).
A31: • ATENÇÃO — "Passeio faltante (m de via)": são metros de VIA sem calçada completa nos dois lados, NÃO metros lineares de calçada. Para orçar calçada em metro linear, multiplique por 2 (dois lados).
A32: • A extensão de vias não abertas está incluída em "Falta pavimentar", pois são obras a executar; ela NÃO entra no cálculo de passeio.
A33: • Metragem medida = via com traçado existente medido sobre imagem; metragem só de planta = via prevista no projeto, sem traçado medido — sua existência física deve ser confirmada em campo antes de orçar.
A34: • Passeio faltante (m²) = metros de via aberta sem passeio completo × 4 m (2 lados × 2 m de largura de calçada); vias não abertas não entram no cálculo de passeio.
A35: • A extensão total inclui vias previstas em planta ainda não abertas (contam integralmente como “falta pavimentar”).
A36: • Células em azul nas abas = entradas/premissas editáveis (ex.: % de passeio existente por amostragem).
A37: • Áreas oficiais: planilha de loteamentos da Prefeitura de São Mateus e quadros de áreas das plantas.
A38: • Nº 7 (Balneário): a planta disponível cobre apenas um setor (386.000 m²); adotada a área da planilha oficial (578.500 m²).

Sheet 07 Balneário de Guriri
A1: Loteamento Balneário de Guriri — planta nº 7
A2: Proprietário/empreendedor: Município de São Mateus | Matrícula: 7.798/3-J (22/02/1979) | Área oficial: 578.500 m²
A3: Auditoria completa: 58 pontos verificados neste loteamento (1 ponto a cada ~350 m de via) no Google Street View e. onde não há cobertura. em satélite. Metragem com traçado medido: 16.241 m; só de planta: 0 m.
A5: Rua / via | B5: Extensão da pista (m) | C5: Situação da pista | D5: % pista pavimentada | E5: Pavimentado (m) | F5: Falta pavimentar (m) | G5: Confiança | H5: Passeio (calçada) | I5: % passeio | J5: Pontos auditados | K5: Origem da classificação | L5: Metragem | M5: Observações
A6: Avenida Oceano Atlântico | B6: 2712 | C6: Pavimentada | D6: 1 | E6: =ROUND(B6*D6,1) -> 2712 | F6: =B6-E6 -> 0 | G6: alta | H6: Sim (maioria) | I6: 0.93 | J6: 8 | K6: 8 ponto(s): 8 SV + 0 satélite (bloquete) | L6: medida (traçado) | M6: Primeira Avenida da planta/orla ES-010; asfalto cinza com estacionamento, quiosques e calcadao junto a praca.
A7: Avenida Governador Eurico Vieira de Rezende | B7: 805.1 | C7: Pavimentada | D7: 1 | E7: =ROUND(B7*D7,1) -> 805.1 | F7: =B7-E7 -> 0 | G7: alta | H7: Sim (maioria) | I7: 1 | J7: 2 | K7: 2 ponto(s): 1 SV + 1 satélite (asfalto, bloquete) | L7: medida (traçado) | M7: Corresponde ao eixo Av. Guriri/praca do centro comercial; cinza, comercio denso.
A8: Avenida Esbertalina Barbosa Damiani | B8: 379.5 | C8: Pavimentada | D8: 1 | E8: =ROUND(B8*D8,1) -> 379.5 | F8: =B8-E8 -> 0 | G8: alta | H8: Parcial | I8: 0.5 | J8: 1 | K8: 1 ponto(s): 1 SV + 0 satélite (bloquete) | L8: medida (traçado) | M8: Segunda Avenida da planta (limite oeste); cinza continua, rota de onibus. | corrigido por SV
A9: Rua Pinheiros | B9: 386.2 | C9: Não pavimentada | D9: 0 | E9: =ROUND(B9*D9,1) -> 0 | F9: =B9-E9 -> 386.2 | G9: alta | H9: Parcial | I9: 0.5 | J9: 1 | K9: 1 ponto(s): 1 SV + 0 satélite (saibro) | L9: medida (traçado) | M9: Areia/bege no satelite (hz_18395/18435/18475).
A10: Rua Linhares | B10: 1390.7 | C10: Não pavimentada | D10: 0 | E10: =ROUND(B10*D10,1) -> 0 | F10: =B10-E10 -> 1390.7 | G10: alta | H10: Parcial | I10: 0.5 | J10: 5 | K10: 5 ponto(s): 5 SV + 0 satélite (saibro) | L10: medida (traçado) | M10: OSM unpaved; satelite mostra ~150 m cinza junto ao centro comercial (Zuliani/Eurico Rezende); restante ate -18.751 em areia.
A11: Avenida Oceano Índico | B11: 805.8 | C11: Pavimentada | D11: 1 | E11: =ROUND(B11*D11,1) -> 805.8 | F11: =B11-E11 -> 0 | G11: alta | H11: Parcial | I11: 0.5 | J11: 2 | K11: 2 ponto(s): 2 SV + 0 satélite (bloquete) | L11: medida (traçado) | M11: Terceira Avenida da planta (transversal com canteiro); cinza da Esbertalina ate a orla.
A12: Rua Horácio Barbosa Alves | B12: 1372.6 | C12: Parcial | D12: 0.77 | E12: =ROUND(B12*D12,1) -> 1056.9 | F12: =B12-E12 -> 315.7 | G12: alta | H12: Parcial | I12: 0.54 | J12: 5 | K12: 5 ponto(s): 5 SV + 0 satélite (bloquete, saibro) | L12: medida (traçado) | M12: Areia/bege no satelite (hz_18395/18435/18475).
A13: Rua São Gabriel da Palha | B13: 1414 | C13: Parcial | D13: 0.27 | E13: =ROUND(B13*D13,1) -> 381.8 | F13: =B13-E13 -> 1032.2 | G13: alta | H13: Parcial | I13: 0.64 | J13: 5 | K13: 5 ponto(s): 5 SV + 0 satélite (bloquete, saibro) | L13: medida (traçado) | M13: Areia; possivel toco curto pavimentado junto ao centro (nao conclusivo).
A14: Rua Barra de São Francisco | B14: 383.2 | C14: Não pavimentada | D14: 0 | E14: =ROUND(B14*D14,1) -> 0 | F14: =B14-E14 -> 383.2 | G14: alta | H14: Parcial | I14: 0.5 | J14: 1 | K14: 1 ponto(s): 1 SV + 0 satélite (saibro) | L14: medida (traçado) | M14: Areia/bege no satelite (hz_18395/18435/18475).
A15: (sem nome) | B15: 367.2 | C15: Parcial | D15: 0.66 | E15: =ROUND(B15*D15,1) -> 242.4 | F15: =B15-E15 -> 124.8 | G15: alta | H15: Sim (maioria) | I15: 0.79 | J15: 5 | K15: 5 ponto(s): 5 SV + 0 satélite (areia, asfalto, bloquete) | L15: medida (traçado) | M15: 22 ways de ligacao na praca/orla (primary_link/tertiary_link) majoritariamente asfaltados; poucos tocos de areia.
A16: Avenida Esbertalina B. Damiani | B16: 1142.1 | C16: Pavimentada | D16: 1 | E16: =ROUND(B16*D16,1) -> 1142.1 | F16: =B16-E16 -> 0 | G16: alta | H16: Parcial | I16: 0.5 | J16: 2 | K16: 2 ponto(s): 2 SV + 0 satélite (bloquete) | L16: medida (traçado) | M16: Continuacao sul do mesmo eixo; cinza com pontos de onibus ate alem da Mantenopolis. | corrigido por SV
A17: Rua Boa Esperança | B17: 389 | C17: Não pavimentada | D17: 0 | E17: =ROUND(B17*D17,1) -> 0 | F17: =B17-E17 -> 389 | G17: alta | H17: Não | I17: 0 | J17: 1 | K17: 1 ponto(s): 1 SV + 0 satélite (areia) | L17: medida (traçado) | M17: Areia/bege no satelite (hz_18395/18435/18475).
... A25: Rua Esbertalina B. Damiani | B25: 9.2 | C25: Pavimentada | D25: 1 | E25: =ROUND(B25*D25,1) -> 9.2 | F25: =B25-E25 -> 0 | G25: alta | H25: Sim (maioria) | I25: 1 | J25: 1 | K25: 1 ponto(s): 1 SV + 0 satélite (bloquete) | L25: medida (traçado) | M25: Toco de 9 m sem tag; mesmo eixo pavimentado. | corrigido por SV
A26: TOTAL | B26: =SUM(B6:B25) -> 16241.4 | D26: =IF(B26=0,0,E26/B26) -> 0.59916633 | E26: =SUM(E6:E25) -> 9731.3 | F26: =SUM(F6:F25) -> 6510.1
A28: Falta pavimentar — pista (m²): | D28: =F26*8 -> 52080.8 | E28: largura média de pista adotada: 8 m (premissa)
A29: Vias não abertas incluídas no total (m): | D29: 0 | E29: constam na planta, sem abertura visível no satélite
A30: Passeio (calçada de pedestre) existente: | D30: 0.6 | E30: medido em 53 ponto(s) do Street View — confiança alta
A31: Passeio faltante (m de via aberta): | D31: =(B26-D29)*(1-D30) -> 6496.56 | E31: vias não abertas excluídas do cálculo de passeio
A32: Passeio faltante (m²): | D32: =D31*4 -> 25986.24 | E32: premissa: 2 lados × 2 m de largura de calçada
A33: Pavimento sobre metragem medida (m): | D33: 9731
A34: Pavimento sobre metragem só de planta (m): | D34: 0 | E34: sem traçado medido — existência a confirmar em campo
A35: Falta pavimentar sobre metragem medida (m): | D35: 6510
A36: Falta pavimentar sobre metragem só de planta (m): | D36: 0 | E36: parcela do orçamento que depende de vias ainda não confirmadas em campo
A37: Obs. passeio: medido em 53 ponto(s) do Street View — ambos os lados=100%, um lado=50%, nenhum=0%

Sheet 09 Bosque da Praia
A1: Loteamento Bosque da Praia — planta nº 9
A2: Proprietário/empreendedor: TEGIL Territorial Guriri Ltda | Matrícula: 2.315 (14/12/1979) | Área oficial: 1.728.555 m²
A3: Auditoria completa: 27 pontos verificados neste loteamento (1 ponto a cada ~350 m de via) no Google Street View e. onde não há cobertura. em satélite. Metragem com traçado medido: 942 m; só de planta: 35.450 m.
A5: Rua / via | B5: Extensão da pista (m) | C5: Situação da pista | D5: % pista pavimentada | E5: Pavimentado (m) | F5: Falta pavimentar (m) | G5: Confiança | H5: Passeio (calçada) | I5: % passeio | J5: Pontos auditados | K5: Origem da classificação | L5: Metragem | M5: Observações
A6: Estrada São Mateus-Estiva de Barra Nova | B6: 942.4 | C6: Não pavimentada | D6: 0 | E6: =ROUND(B6*D6,1) -> 0 | F6: =B6-E6 -> 942.4 | G6: alta | H6: Não | I6: 0 | J6: 3 | K6: 3 ponto(s): 3 SV + 0 satélite (saibro) | L6: medida (traçado) | M6: 'AV.' diagonal de 20 m da divisa oeste da planta de 1979; hoje ES-010 asfaltada (linha escura no satelite), 942 m no poligono
A7: RUA 1 | B7: 920 | C7: Não pavimentada | D7: 0 | E7: =ROUND(B7*D7,1) -> 0 | F7: =B7-E7 -> 920 | G7: baixa | H7: Não avaliável | I7: — | J7: 0 | K7: sem ponto próprio — taxa agregada da malha física auditada do loteamento | L7: planta (não medida) | M7: primeira rua junto a orla, atras da duna: aberta em areia, continua de -18.7746 a ~-18.782
A8: RUA 2 | B8: 920 | C8: Não pavimentada | D8: 0 | E8: =ROUND(B8*D8,1) -> 0 | F8: =B8-E8 -> 920 | G8: baixa | H8: Não avaliável | I8: — | J8: 0 | K8: sem ponto próprio — taxa agregada da malha física auditada do loteamento | L8: planta (não medida) | M8: 'R. Dois' rotulada no Google: aberta em areia por toda a extensao
A9: RUA 3 | B9: 920 | C9: Não pavimentada | D9: 0 | E9: =ROUND(B9*D9,1) -> 0 | F9: =B9-E9 -> 920 | G9: baixa | H9: Não avaliável | I9: — | J9: 0 | K9: sem ponto próprio — taxa agregada da malha física auditada do loteamento | L9: planta (não medida) | M9: aberta em areia (grade visivel hz_18775s/hz_18830s) de -18.7746 ate a mata em ~-18.782; sem edificacao na maior parte
A10: RUA 4 | B10: 920 | C10: Não pavimentada | D10: 0 | E10: =ROUND(B10*D10,1) -> 0 | F10: =B10-E10 -> 920 | G10: baixa | H10: Não avaliável | I10: — | J10: 0 | K10: sem ponto próprio — taxa agregada da malha física auditada do loteamento | L10: planta (não medida) | M10: aberta em areia (grade visivel hz_18775s/hz_18830s) de -18.7746 ate a mata em ~-18.782; sem edificacao na maior parte
A11: RUA 5 | B11: 920 | C11: Não pavimentada | D11: 0 | E11: =ROUND(B11*D11,1) -> 0 | F11: =B11-E11 -> 920 | G11: baixa | H11: Não avaliável | I11: — | J11: 0 | K11: sem ponto próprio — taxa agregada da malha física auditada do loteamento | L11: planta (não medida) | M11: aberta em areia (grade visivel hz_18775s/hz_18830s) de -18.7746 ate a mata em ~-18.782; sem edificacao na maior parte
A12: RUA 6 | B12: 920 | C12: Não pavimentada | D12: 0 | E12: =ROUND(B12*D12,1) -> 0 | F12: =B12-E12 -> 920 | G12: baixa | H12: Não avaliável | I12: — | J12: 0 | K12: sem ponto próprio — taxa agregada da malha física auditada do loteamento | L12: planta (não medida) | M12: aberta em areia (grade visivel hz_18775s/hz_18830s) de -18.7746 ate a mata em ~-18.782; sem edificacao na maior parte
A13: RUA 7 | B13: 920 | C13: Não pavimentada | D13: 0 | E13: =ROUND(B13*D13,1) -> 0 | F13: =B13-E13 -> 920 | G13: baixa | H13: Não avaliável | I13: — | J13: 0 | K13: sem ponto próprio — taxa agregada da malha física auditada do loteamento | L13: planta (não medida) | M13: aberta em areia (grade visivel hz_18775s/hz_18830s) de -18.7746 ate a mata em ~-18.782; sem edificacao na maior parte
A14: RUA 8 | B14: 920 | C14: Não pavimentada | D14: 0 | E14: =ROUND(B14*D14,1) -> 0 | F14: =B14-E14 -> 920 | G14: baixa | H14: Não avaliável | I14: — | J14: 0 | K14: sem ponto próprio — taxa agregada da malha física auditada do loteamento | L14: planta (não medida) | M14: aberta em areia (grade visivel hz_18775s/hz_18830s) de -18.7746 ate a mata em ~-18.782; sem edificacao na maior parte
A15: RUA 9 | B15: 920 | C15: Não pavimentada | D15: 0 | E15: =ROUND(B15*D15,1) -> 0 | F15: =B15-E15 -> 920 | G15: baixa | H15: Não avaliável | I15: — | J15: 0 | K15: sem ponto próprio — taxa agregada da malha física auditada do loteamento | L15: planta (não medida) | M15: aberta em areia (grade visivel hz_18775s/hz_18830s) de -18.7746 ate a mata em ~-18.782; sem edificacao na maior parte
A16: RUA 10 | B16: 920 | C16: Não pavimentada | D16: 0 | E16: =ROUND(B16*D16,1) -> 0 | F16: =B16-E16 -> 920 | G16: baixa | H16: Não avaliável | I16: — | J16: 0 | K16: sem ponto próprio — taxa agregada da malha física auditada do loteamento | L16: planta (não medida) | M16: aberta em areia (grade visivel hz_18775s/hz_18830s) de -18.7746 ate a mata em ~-18.782; sem edificacao na maior parte
A17: RUA 11 | B17: 920 | C17: Não pavimentada | D17: 0 | E17: =ROUND(B17*D17,1) -> 0 | F17: =B17-E17 -> 920 | G17: baixa | H17: Não avaliável | I17: — | J17: 0 | K17: sem ponto próprio — taxa agregada da malha física auditada do loteamento | L17: planta (não medida) | M17: aberta em areia (grade visivel hz_18775s/hz_18830s) de -18.7746 ate a mata em ~-18.782; sem edificacao na maior parte
A18: RUA 12 | B18: 920 | C18: Não pavimentada | D18: 0 | E18: =ROUND(B18*D18,1) -> 0 | F18: =B18-E18 -> 920 | G18: baixa | H18: Não avaliável | I18: — | J18: 0 | K18: sem ponto próprio — taxa agregada da malha física auditada do loteamento | L18: planta (não medida) | M18: aberta em areia (grade visivel hz_18775s/hz_18830s) de -18.7746 ate a mata em ~-18.782; sem edificacao na maior parte
... A45: AV. ATLANTICA | B45: 920 | C45: Não pavimentada | D45: 0 | E45: =ROUND(B45*D45,1) -> 0 | F45: =B45-E45 -> 920 | G45: baixa | H45: Não avaliável | I45: — | J45: 0 | K45: sem ponto próprio — taxa agregada da malha física auditada do loteamento | L45: planta (não medida) | M45: orla: trilha de areia na crista da duna, continua em trechos; estacionamento e calcadao do projeto nunca implantados
A46: TOTAL | B46: =SUM(B6:B45) -> 36392.4 | D46: =IF(B46=0,0,E46/B46) -> 0 | E46: =SUM(E6:E45) -> 0 | F46: =SUM(F6:F45) -> 36392.4
A48: Falta pavimentar — pista (m²): | D48: =F46*8 -> 291139.2 | E48: largura média de pista adotada: 8 m (premissa)
A49: Vias não abertas incluídas no total (m): | D49: 1870 | E49: constam na planta, sem abertura visível no satélite
A50: Passeio (calçada de pedestre) existente: | D50: 0.05 | E50: medido em 12 ponto(s) do Street View — confiança média
A51: Passeio faltante (m de via aberta): | D51: =(B46-D49)*(1-D50) -> 32796.28 | E51: vias não abertas excluídas do cálculo de passeio
A52: Passeio faltante (m²): | D52: =D51*4 -> 131185.12 | E52: premissa: 2 lados × 2 m de largura de calçada
A53: Pavimento sobre metragem medida (m): | D53: 0
A54: Pavimento sobre metragem só de planta (m): | D54: 0 | E54: sem traçado medido — existência a confirmar em campo
A55: Falta pavimentar sobre metragem medida (m): | D55: 942
A56: Falta pavimentar sobre metragem só de planta (m): | D56: 35450 | E56: parcela do orçamento que depende de vias ainda não confirmadas em campo
A57: Obs. passeio: medido em 12 ponto(s) do Street View — ambos os lados=100%, um lado=50%, nenhum=0%

Sheet 10 Parque dos Albatrozes
A1: Loteamento Parque dos Albatrozes — planta nº 10
A2: Proprietário/empreendedor: BINOTTE Emp. Imobiliários | Matrícula: 2.383 (18/06/1980) | Área oficial: 757.170 m²
A3: Auditoria completa: 54 pontos verificados neste loteamento (1 ponto a cada ~350 m de via) no Google Street View e. onde não há cobertura. em satélite. Metragem com traçado medido: 17.996 m; só de planta: 0 m.
A5: Rua / via | B5: Extensão da pista (m) | C5: Situação da pista | D5: % pista pavimentada | E5: Pavimentado (m) | F5: Falta pavimentar (m) | G5: Confiança | H5: Passeio (calçada) | I5: % passeio | J5: Pontos auditados | K5: Origem da classificação | L5: Metragem | M5: Observações
A6: Sétima Avenida | B6: 1101.1 | C6: Não pavimentada | D6: 0 | E6: =ROUND(B6*D6,1) -> 0 | F6: =B6-E6 -> 1101.1 | G6: alta | H6: Parcial | I6: 0.33 | J6: 3 | K6: 3 ponto(s): 3 SV + 0 satélite (areia) | L6: medida (traçado) | M6: Areia/bege no satelite (hz_18315/18355).
A7: Avenida Homero Zordan | B7: 1377.1 | C7: Parcial | D7: 0.42 | E7: =ROUND(B7*D7,1) -> 578.4 | F7: =B7-E7 -> 798.7 | G7: alta | H7: Parcial | I7: 0.32 | J7: 4 | K7: 4 ponto(s): 4 SV + 0 satélite (areia, bloquete) | L7: medida (traçado) | M7: OSM dirt+paving_stones; satelite mostra cinza no trecho central (cruzamento com o eixo asfaltado Othovarino e junto a Esbertalina/praca de eventos); extremo oeste e trecho junto a orla em tom areia.
A8: Avenida Espera Feliz | B8: 536.1 | C8: Parcial | D8: 0.52 | E8: =ROUND(B8*D8,1) -> 278.8 | F8: =B8-E8 -> 257.3 | G8: baixa | H8: Não avaliável | I8: — | J8: 0 | K8: trecho curto sem ponto próprio — adotada a situação da mesma via (nome próprio, loteamento contíguo) em 6 ponto(s): p13=0%, p14=100%, p60=0% | L8: medida (traçado) | M8: Pavimentada (cinza, rotatoria e ponto de onibus) da diagonal Othovarino ate a orla; toco oeste em areia.
A9: Rua Pedro Alves Ribeiro | B9: 624.3 | C9: Não pavimentada | D9: 0 | E9: =ROUND(B9*D9,1) -> 0 | F9: =B9-E9 -> 624.3 | G9: alta | H9: Parcial | I9: 0.25 | J9: 2 | K9: 2 ponto(s): 2 SV + 0 satélite (areia) | L9: medida (traçado) | M9: Areia/bege no satelite (hz_18315/18355).
A10: Rua Elisa Maria Ditthz de Abreu Costa | B10: 598.3 | C10: Não pavimentada | D10: 0 | E10: =ROUND(B10*D10,1) -> 0 | F10: =B10-E10 -> 598.3 | G10: alta | H10: Não | I10: 0 | J10: 2 | K10: 2 ponto(s): 2 SV + 0 satélite (areia) | L10: medida (traçado) | M10: Areia/bege no satelite (hz_18315/18355).
A11: (sem nome) | B11: 346.1 | C11: Não pavimentada | D11: 0 | E11: =ROUND(B11*D11,1) -> 0 | F11: =B11-E11 -> 346.1 | G11: alta | H11: Parcial | I11: 0.5 | J11: 1 | K11: 1 ponto(s): 1 SV + 0 satélite (saibro) | L11: medida (traçado) | M11: 3 ways paving_stones+unpaved; vielas junto ao eixo Esbertalina.
A12: Avenida Esbertalina Barbosa Damiani | B12: 21.6 | C12: Pavimentada | D12: 1 | E12: =ROUND(B12*D12,1) -> 21.6 | F12: =B12-E12 -> 0 | G12: alta | H12: Sim (maioria) | I12: 1 | J12: 1 | K12: 1 ponto(s): 1 SV + 0 satélite (asfalto) | L12: medida (traçado) | M12: Toco de 22 m na rotatoria com a Espera Feliz; cinza no satelite.
A13: Rua Álvaro Leal Calmon | B13: 596 | C13: Não pavimentada | D13: 0 | E13: =ROUND(B13*D13,1) -> 0 | F13: =B13-E13 -> 596 | G13: alta | H13: Parcial | I13: 0.25 | J13: 2 | K13: 2 ponto(s): 2 SV + 0 satélite (saibro) | L13: medida (traçado) | M13: Areia/bege no satelite (hz_18315/18355).
A14: Rua Raísa Bastos Magnago | B14: 592.3 | C14: Não pavimentada | D14: 0 | E14: =ROUND(B14*D14,1) -> 0 | F14: =B14-E14 -> 592.3 | G14: alta | H14: Parcial | I14: 0.31 | J14: 2 | K14: 2 ponto(s): 2 SV + 0 satélite (saibro) | L14: medida (traçado) | M14: Areia/bege no satelite (hz_18315/18355).
A15: Rua Octávio Borotto | B15: 361.4 | C15: Não pavimentada | D15: 0 | E15: =ROUND(B15*D15,1) -> 0 | F15: =B15-E15 -> 361.4 | G15: alta | H15: Sim (maioria) | I15: 1 | J15: 1 | K15: 1 ponto(s): 1 SV + 0 satélite (saibro) | L15: medida (traçado) | M15: Areia/bege no satelite (hz_18315/18355).
A16: Rua Odílio Nico | B16: 558.1 | C16: Não pavimentada | D16: 0 | E16: =ROUND(B16*D16,1) -> 0 | F16: =B16-E16 -> 558.1 | G16: alta | H16: Parcial | I16: 0.5 | J16: 2 | K16: 2 ponto(s): 2 SV + 0 satélite (saibro) | L16: medida (traçado) | M16: Areia/bege no satelite (hz_18315/18355).
A17: Rua Albino Negris | B17: 595.8 | C17: Parcial | D17: 0.5 | E17: =ROUND(B17*D17,1) -> 297.9 | F17: =B17-E17 -> 297.9 | G17: alta | H17: Sim (maioria) | I17: 0.75 | J17: 2 | K17: 2 ponto(s): 2 SV + 0 satélite (bloquete, saibro) | L17: medida (traçado) | M17: Areia/bege no satelite (hz_18315/18355).
A18: Rua Adriana Barbosa Caran | B18: 102 | C18: Pavimentada | D18: 1 | E18: =ROUND(B18*D18,1) -> 102 | F18: =B18-E18 -> 0 | G18: alta | H18: Parcial | I18: 0.5 | J18: 1 | K18: 1 ponto(s): 1 SV + 0 satélite (bloquete) | L18: medida (traçado) | M18: Areia/bege no satelite (hz_18315/18355). | SV: pavimentada no trecho sul, areia ao norte
A19: Rua Rogério Campista Correia | B19: 351.2 | C19: Não pavimentada | D19: 0 | E19: =ROUND(B19*D19,1) -> 0 | F19: =B19-E19 -> 351.2 | G19: alta | H19: Parcial | I19: 0.5 | J19: 1 | K19: 1 ponto(s): 1 SV + 0 satélite (saibro) | L19: medida (traçado) | M19: Areia/bege no satelite (hz_18315/18355).
A20: Jamil Alhakim Ribeiro | B20: 347.5 | C20: Não pavimentada | D20: 0 | E20: =ROUND(B20*D20,1) -> 0 | F20: =B20-E20 -> 347.5 | G20: alta | H20: Parcial | I20: 0.5 | J20: 1 | K20: 1 ponto(s): 1 SV + 0 satélite (saibro) | L20: medida (traçado) | M20: Areia/bege no satelite (hz_18315/18355).
... A37: Rua Maria Tezolin Carrafa | B37: 171.6 | C37: Não pavimentada | D37: 0 | E37: =ROUND(B37*D37,1) -> 0 | F37: =B37-E37 -> 171.6 | G37: alta | H37: Não | I37: 0 | J37: 1 | K37: 1 ponto(s): 1 SV + 0 satélite (saibro) | L37: medida (traçado) | M37: Areia/bege no satelite (hz_18315/18355).
A38: TOTAL | B38: =SUM(B6:B37) -> 17996.4 | D38: =IF(B38=0,0,E38/B38) -> 0.31591318 | E38: =SUM(E6:E37) -> 5685.3 | F38: =SUM(F6:F37) -> 12311.1
A40: Falta pavimentar — pista (m²): | D40: =F38*8 -> 98488.8 | E40: largura média de pista adotada: 8 m (premissa)
A41: Vias não abertas incluídas no total (m): | D41: 0 | E41: constam na planta, sem abertura visível no satélite
A42: Passeio (calçada de pedestre) existente: | D42: 0.53 | E42: medido em 54 ponto(s) do Street View — confiança alta
A43: Passeio faltante (m de via aberta): | D43: =(B38-D41)*(1-D42) -> 8458.308 | E43: vias não abertas excluídas do cálculo de passeio
A44: Passeio faltante (m²): | D44: =D43*4 -> 33833.232 | E44: premissa: 2 lados × 2 m de largura de calçada
A45: Pavimento sobre metragem medida (m): | D45: 5685
A46: Pavimento sobre metragem só de planta (m): | D46: 0 | E46: sem traçado medido — existência a confirmar em campo
A47: Falta pavimentar sobre metragem medida (m): | D47: 12311
A48: Falta pavimentar sobre metragem só de planta (m): | D48: 0 | E48: parcela do orçamento que depende de vias ainda não confirmadas em campo
A49: Obs. passeio: medido em 54 ponto(s) do Street View — ambos os lados=100%, um lado=50%, nenhum=0%

Sheet 13 Praia de Guriri
A1: Loteamento Praia de Guriri — planta nº 13
A2: Proprietário/empreendedor: Dalla Bernardina Imob. | Matrícula: 2.025 (06/07/1983) | Área oficial: 625.209 m²
A3: Auditoria completa: 57 pontos verificados neste loteamento (1 ponto a cada ~350 m de via) no Google Street View e. onde não há cobertura. em satélite. Metragem com traçado medido: 12.416 m; só de planta: 0 m.
A5: Rua / via | B5: Extensão da pista (m) | C5: Situação da pista | D5: % pista pavimentada | E5: Pavimentado (m) | F5: Falta pavimentar (m) | G5: Confiança | H5: Passeio (calçada) | I5: % passeio | J5: Pontos auditados | K5: Origem da classificação | L5: Metragem | M5: Observações
A6: Rua XXXII | B6: 143.9 | C6: Pavimentada | D6: 1 | E6: =ROUND(B6*D6,1) -> 143.9 | F6: =B6-E6 -> 0 | G6: alta | H6: Não | I6: 0 | J6: 1 | K6: 1 ponto(s): 1 SV + 0 satélite (bloquete) | L6: medida (traçado) | M6: areia clara no satelite (hz_18275_O/hz_18315_O)
A7: Rua Antônio Massucatti | B7: 467.7 | C7: Não pavimentada | D7: 0 | E7: =ROUND(B7*D7,1) -> 0 | F7: =B7-E7 -> 467.7 | G7: média | H7: Não | I7: 0 | J7: 1 | K7: 1 ponto(s): 1 SV + 0 satélite (saibro) | L7: medida (traçado) | M7: areia clara no satelite (hz_18275_O/hz_18315_O)
A8: Rua Antônio Cunha Filho | B8: 189.3 | C8: Não pavimentada | D8: 0 | E8: =ROUND(B8*D8,1) -> 0 | F8: =B8-E8 -> 189.3 | G8: alta | H8: Parcial | I8: 0.5 | J8: 1 | K8: 1 ponto(s): 1 SV + 0 satélite (saibro) | L8: medida (traçado) | M8: areia clara no satelite (hz_18275_O/hz_18315_O)
A9: Rua Trinta e Sete | B9: 522.3 | C9: Não pavimentada | D9: 0 | E9: =ROUND(B9*D9,1) -> 0 | F9: =B9-E9 -> 522.3 | G9: alta | H9: Parcial | I9: 0.25 | J9: 2 | K9: 2 ponto(s): 2 SV + 0 satélite (saibro) | L9: medida (traçado) | M9: areia clara no satelite (hz_18275_O/hz_18315_O)
A10: Rua Trinta e Nove | B10: 187.3 | C10: Não pavimentada | D10: 0 | E10: =ROUND(B10*D10,1) -> 0 | F10: =B10-E10 -> 187.3 | G10: alta | H10: Parcial | I10: 0.5 | J10: 1 | K10: 1 ponto(s): 1 SV + 0 satélite (saibro) | L10: medida (traçado) | M10: areia clara no satelite (hz_18275_O/hz_18315_O)
A11: Rua Trinta e Cinco | B11: 75.3 | C11: Pavimentada | D11: 1 | E11: =ROUND(B11*D11,1) -> 75.3 | F11: =B11-E11 -> 0 | G11: alta | H11: Parcial | I11: 0.5 | J11: 1 | K11: 1 ponto(s): 1 SV + 0 satélite (bloquete) | L11: medida (traçado) | M11: areia clara no satelite (hz_18275_O/hz_18315_O) | SV nov/2023: bloquete sextavado (R. XXXV)
A12: Rua Climéria Santos Barcellos | B12: 98.5 | C12: Não pavimentada | D12: 0 | E12: =ROUND(B12*D12,1) -> 0 | F12: =B12-E12 -> 98.5 | G12: alta | H12: Não | I12: 0 | J12: 1 | K12: 1 ponto(s): 1 SV + 0 satélite (saibro) | L12: medida (traçado) | M12: areia clara no satelite (hz_18275_O/hz_18315_O)
A13: Rua Felisberto Fereguetti | B13: 405.9 | C13: Não pavimentada | D13: 0 | E13: =ROUND(B13*D13,1) -> 0 | F13: =B13-E13 -> 405.9 | G13: alta | H13: Parcial | I13: 0.5 | J13: 1 | K13: 1 ponto(s): 1 SV + 0 satélite (saibro) | L13: medida (traçado) | M13: areia clara no satelite (hz_18275_O/hz_18315_O)
A14: Rua José Bonomo | B14: 121.8 | C14: Não pavimentada | D14: 0 | E14: =ROUND(B14*D14,1) -> 0 | F14: =B14-E14 -> 121.8 | G14: alta | H14: Não | I14: 0 | J14: 1 | K14: 1 ponto(s): 1 SV + 0 satélite (saibro) | L14: medida (traçado) | M14: areia clara no satelite (hz_18275_O/hz_18315_O)
A15: (sem nome) | B15: 639.2 | C15: Parcial | D15: 0.62 | E15: =ROUND(B15*D15,1) -> 396.3 | F15: =B15-E15 -> 242.9 | G15: alta | H15: Não | I15: 0.18 | J15: 7 | K15: 7 ponto(s): 7 SV + 0 satélite (bloquete, saibro) | L15: medida (traçado) | M15: segmentos difusos dirt/unpaved; zona toda em areia no satelite
A16: Rua Adelino Fereguetti | B16: 392 | C16: Não pavimentada | D16: 0 | E16: =ROUND(B16*D16,1) -> 0 | F16: =B16-E16 -> 392 | G16: alta | H16: Não | I16: 0 | J16: 1 | K16: 1 ponto(s): 1 SV + 0 satélite (saibro) | L16: medida (traçado) | M16: areia clara no satelite (hz_18275_O/hz_18315_O)
A17: Rua Domingos Carrafa | B17: 183.9 | C17: Não pavimentada | D17: 0 | E17: =ROUND(B17*D17,1) -> 0 | F17: =B17-E17 -> 183.9 | G17: alta | H17: Parcial | I17: 0.5 | J17: 1 | K17: 1 ponto(s): 1 SV + 0 satélite (saibro) | L17: medida (traçado) | M17: areia clara no satelite (hz_18275_O/hz_18315_O)
... A45: Rodovia Othovarino Duarte Santos | B45: 479.6 | C45: Pavimentada | D45: 1 | E45: =ROUND(B45*D45,1) -> 479.6 | F45: =B45-E45 -> 0 | G45: média | H45: Sim (maioria) | I45: 1 | J45: 1 | K45: 1 ponto(s): 1 SV + 0 satélite (asfalto) | L45: medida (traçado) | M45: trecho junto a ponte/limite oeste; cinza no canto do quadro hz_18275_O, parcialmente fora das imagens
A46: TOTAL | B46: =SUM(B6:B45) -> 12416.1 | D46: =IF(B46=0,0,E46/B46) -> 0.21675889 | E46: =SUM(E6:E45) -> 2691.3 | F46: =SUM(F6:F45) -> 9724.8
A48: Falta pavimentar — pista (m²): | D48: =F46*8 -> 77798.4 | E48: largura média de pista adotada: 8 m (premissa)
A49: Vias não abertas incluídas no total (m): | D49: 0 | E49: constam na planta, sem abertura visível no satélite
A50: Passeio (calçada de pedestre) existente: | D50: 0.27 | E50: medido em 56 ponto(s) do Street View — confiança alta
A51: Passeio faltante (m de via aberta): | D51: =(B46-D49)*(1-D50) -> 9063.753 | E51: vias não abertas excluídas do cálculo de passeio
A52: Passeio faltante (m²): | D52: =D51*4 -> 36255.012 | E52: premissa: 2 lados × 2 m de largura de calçada
A53: Pavimento sobre metragem medida (m): | D53: 2691
A54: Pavimento sobre metragem só de planta (m): | D54: 0 | E54: sem traçado medido — existência a confirmar em campo
A55: Falta pavimentar sobre metragem medida (m): | D55: 9725
A56: Falta pavimentar sobre metragem só de planta (m): | D56: 0 | E56: parcela do orçamento que depende de vias ainda não confirmadas em campo
A57: Obs. passeio: medido em 56 ponto(s) do Street View — ambos os lados=100%, um lado=50%, nenhum=0%

Sheet 14 Jardim das Caiçaras
A1: Loteamento Jardim das Caiçaras — planta nº 14
A2: Proprietário/empreendedor: Caiçaras Emp. Imobiliários | Matrícula: 4.170 (05/05/1986) | Área oficial: 1.141.458 m²
A3: Auditoria completa: 78 pontos verificados neste loteamento (1 ponto a cada ~350 m de via) no Google Street View e. onde não há cobertura. em satélite. Metragem com traçado medido: 21.908 m; só de planta: 0 m.
A5: Rua / via | B5: Extensão da pista (m) | C5: Situação da pista | D5: % pista pavimentada | E5: Pavimentado (m) | F5: Falta pavimentar (m) | G5: Confiança | H5: Passeio (calçada) | I5: % passeio | J5: Pontos auditados | K5: Origem da classificação | L5: Metragem | M5: Observações
A6: Rua XXXII | B6: 156.6 | C6: Pavimentada | D6: 1 | E6: =ROUND(B6*D6,1) -> 156.6 | F6: =B6-E6 -> 0 | G6: alta | H6: Sim (maioria) | I6: 1 | J6: 1 | K6: 1 ponto(s): 1 SV + 0 satélite (bloquete) | L6: medida (traçado) | M6: Areia/bege no satelite (hz_18275/18315).
A7: Rua Antônio Cunha Filho | B7: 156.6 | C7: Não pavimentada | D7: 0 | E7: =ROUND(B7*D7,1) -> 0 | F7: =B7-E7 -> 156.6 | G7: alta | H7: Não | I7: 0 | J7: 1 | K7: 1 ponto(s): 1 SV + 0 satélite (saibro) | L7: medida (traçado) | M7: Areia/bege no satelite (hz_18275/18315).
A8: Rua Trinta e Cinco | B8: 156.6 | C8: Não pavimentada | D8: 0 | E8: =ROUND(B8*D8,1) -> 0 | F8: =B8-E8 -> 156.6 | G8: alta | H8: Não | I8: 0 | J8: 1 | K8: 1 ponto(s): 1 SV + 0 satélite (saibro) | L8: medida (traçado) | M8: Areia/bege no satelite (hz_18275/18315).
A9: Rua Climéria Santos Barcellos | B9: 154.7 | C9: Não pavimentada | D9: 0 | E9: =ROUND(B9*D9,1) -> 0 | F9: =B9-E9 -> 154.7 | G9: alta | H9: Não | I9: 0 | J9: 1 | K9: 1 ponto(s): 1 SV + 0 satélite (saibro) | L9: medida (traçado) | M9: Areia/bege no satelite (hz_18275/18315).
A10: Rua José Bonomo | B10: 155.7 | C10: Não pavimentada | D10: 0 | E10: =ROUND(B10*D10,1) -> 0 | F10: =B10-E10 -> 155.7 | G10: alta | H10: Não | I10: 0 | J10: 1 | K10: 1 ponto(s): 1 SV + 0 satélite (saibro) | L10: medida (traçado) | M10: Areia/bege no satelite (hz_18275/18315).
A11: Rua Domingos Carrafa | B11: 156.6 | C11: Pavimentada | D11: 1 | E11: =ROUND(B11*D11,1) -> 156.6 | F11: =B11-E11 -> 0 | G11: alta | H11: Não | I11: 0 | J11: 1 | K11: 1 ponto(s): 1 SV + 0 satélite (bloquete) | L11: medida (traçado) | M11: Areia/bege no satelite (hz_18275/18315).
A12: Décima Primeira Avenida | B12: 917.1 | C12: Não pavimentada | D12: 0 | E12: =ROUND(B12*D12,1) -> 0 | F12: =B12-E12 -> 917.1 | G12: alta | H12: Não | I12: 0 | J12: 3 | K12: 3 ponto(s): 3 SV + 0 satélite (areia) | L12: medida (traçado) | M12: Areia/bege no satelite (hz_18275/18315).
A13: Rua Conceição da Barra | B13: 783 | C13: Não pavimentada | D13: 0 | E13: =ROUND(B13*D13,1) -> 0 | F13: =B13-E13 -> 783 | G13: alta | H13: Parcial | I13: 0.25 | J13: 2 | K13: 2 ponto(s): 2 SV + 0 satélite (areia) | L13: medida (traçado) | M13: Areia/bege no satelite (hz_18275/18315).
A14: Rua Linhares | B14: 723.3 | C14: Não pavimentada | D14: 0 | E14: =ROUND(B14*D14,1) -> 0 | F14: =B14-E14 -> 723.3 | G14: alta | H14: Não | I14: 0 | J14: 2 | K14: 2 ponto(s): 2 SV + 0 satélite (areia, saibro) | L14: medida (traçado) | M14: Areia/bege no satelite (hz_18275/18315).
A15: (sem nome) | B15: 1935.5 | C15: Parcial | D15: 0.74 | E15: =ROUND(B15*D15,1) -> 1432.3 | F15: =B15-E15 -> 503.2 | G15: alta | H15: Parcial | I15: 0.38 | J15: 13 | K15: 13 ponto(s): 8 SV + 5 satélite (areia, asfalto, bloquete, saibro) | L15: medida (traçado) | M15: 16 ways mistos; inclui trecho tertiary com bloquete junto a orla/ES-010 (cinza no satelite) e vielas de areia.
A16: Avenida Espera Feliz | B16: 555.1 | C16: Pavimentada | D16: 1 | E16: =ROUND(B16*D16,1) -> 555.1 | F16: =B16-E16 -> 0 | G16: alta | H16: Parcial | I16: 0.5 | J16: 3 | K16: 3 ponto(s): 3 SV + 0 satélite (bloquete) | L16: medida (traçado) | M16: Cinza no satelite da diagonal Othovarino ate a orla; rotatoria na Esbertalina e ponto de onibus; so o toco oeste (~-39.765..-39.769) em areia.
A17: Avenida Nafice Aihakim Ribeiro | B17: 526.6 | C17: Não pavimentada | D17: 0 | E17: =ROUND(B17*D17,1) -> 0 | F17: =B17-E17 -> 526.6 | G17: média | H17: Não avaliável | I17: — | J17: 0 | K17: trecho curto sem ponto próprio — adotada a situação da mesma via (nome próprio, loteamento contíguo) em 3 ponto(s): p13=0% | L17: medida (traçado) | M17: Areia/bege no satelite (hz_18275/18315).
A18: Rua Odílio Nico | B18: 722 | C18: Não pavimentada | D18: 0 | E18: =ROUND(B18*D18,1) -> 0 | F18: =B18-E18 -> 722 | G18: alta | H18: Não | I18: 0 | J18: 2 | K18: 2 ponto(s): 2 SV + 0 satélite (areia) | L18: medida (traçado) | M18: Areia/bege no satelite (hz_18275/18315).
A19: Rua Edith Laura Moreira D'Almeida | B19: 155.7 | C19: Não pavimentada | D19: 0 | E19: =ROUND(B19*D19,1) -> 0 | F19: =B19-E19 -> 155.7 | G19: alta | H19: Parcial | I19: 0.5 | J19: 1 | K19: 1 ponto(s): 1 SV + 0 satélite (saibro) | L19: medida (traçado) | M19: Areia/bege no satelite (hz_18275/18315).
A20: Rua Professor Amaro Nascimento Mendes | B20: 820.7 | C20: Não pavimentada | D20: 0 | E20: =ROUND(B20*D20,1) -> 0 | F20: =B20-E20 -> 820.7 | G20: alta | H20: Não | I20: 0 | J20: 2 | K20: 2 ponto(s): 2 SV + 0 satélite (saibro) | L20: medida (traçado) | M20: Areia/bege no satelite (hz_18275/18315).
A21: Rua XXV | B21: 157.5 | C21: Não pavimentada | D21: 0 | E21: =ROUND(B21*D21,1) -> 0 | F21: =B21-E21 -> 157.5 | G21: alta | H21: Não | I21: 0 | J21: 1 | K21: 1 ponto(s): 1 SV + 0 satélite (saibro) | L21: medida (traçado) | M21: Areia/bege no satelite (hz_18275/18315).
A22: Rua XVI | B22: 337.3 | C22: Pavimentada | D22: 1 | E22: =ROUND(B22*D22,1) -> 337.3 | F22: =B22-E22 -> 0 | G22: alta | H22: Não | I22: 0 | J22: 1 | K22: 1 ponto(s): 1 SV + 0 satélite (bloquete) | L22: medida (traçado) | M22: Areia/bege no satelite (hz_18275/18315).
A23: Rua XIII | B23: 432 | C23: Não pavimentada | D23: 0 | E23: =ROUND(B23*D23,1) -> 0 | F23: =B23-E23 -> 432 | G23: alta | H23: Não | I23: 0 | J23: 1 | K23: 1 ponto(s): 1 SV + 0 satélite (saibro) | L23: medida (traçado) | M23: Areia/bege no satelite (hz_18275/18315).
A24: Rua XVII | B24: 196.1 | C24: Pavimentada | D24: 1 | E24: =ROUND(B24*D24,1) -> 196.1 | F24: =B24-E24 -> 0 | G24: alta | H24: Não | I24: 0 | J24: 1 | K24: 1 ponto(s): 1 SV + 0 satélite (bloquete) | L24: medida (traçado) | M24: Areia/bege no satelite (hz_18275/18315).
A25: Rua Elisa Maria Ditthz de Abreu Costa | B25: 375 | C25: Não pavimentada | D25: 0 | E25: =ROUND(B25*D25,1) -> 0 | F25: =B25-E25 -> 375 | G25: alta | H25: Parcial | I25: 0.5 | J25: 1 | K25: 1 ponto(s): 1 SV + 0 satélite (saibro) | L25: medida (traçado) | M25: Areia/bege no satelite (hz_18275/18315).
A26: Rua Adriana Barbosa Caran | B26: 631.3 | C26: Não pavimentada | D26: 0 | E26: =ROUND(B26*D26,1) -> 0 | F26: =B26-E26 -> 631.3 | G26: alta | H26: Não | I26: 0 | J26: 2 | K26: 2 ponto(s): 2 SV + 0 satélite (saibro) | L26: medida (traçado) | M26: Areia/bege no satelite (hz_18275/18315).
A27: Rua XIV | B27: 345.4 | C27: Não pavimentada | D27: 0 | E27: =ROUND(B27*D27,1) -> 0 | F27: =B27-E27 -> 345.4 | G27: alta | H27: Não | I27: 0 | J27: 1 | K27: 1 ponto(s): 1 SV + 0 satélite (saibro) | L27: medida (traçado) | M27: Areia/bege no satelite (hz_18275/18315).
A28: Rua Álvaro Leal Calmon | B28: 798.7 | C28: Não pavimentada | D28: 0 | E28: =ROUND(B28*D28,1) -> 0 | F28: =B28-E28 -> 798.7 | G28: alta | H28: Não | I28: 0 | J28: 2 | K28: 2 ponto(s): 2 SV + 0 satélite (saibro) | L28: medida (traçado) | M28: Areia/bege no satelite (hz_18275/18315).
A29: Rua Rogério Campista Correia | B29: 156.7 | C29: Não pavimentada | D29: 0 | E29: =ROUND(B29*D29,1) -> 0 | F29: =B29-E29 -> 156.7 | G29: alta | H29: Não | I29: 0 | J29: 1 | K29: 1 ponto(s): 1 SV + 0 satélite (saibro) | L29: medida (traçado) | M29: Areia/bege no satelite (hz_18275/18315).
... A53: Rua Esbertalina B. Damiani | B53: 1074.4 | C53: Parcial | D53: 0.5 | E53: =ROUND(B53*D53,1) -> 537.2 | F53: =B53-E53 -> 537.2 | G53: alta | H53: Parcial | I53: 0.25 | J53: 2 | K53: 2 ponto(s): 2 SV + 0 satélite (areia, bloquete) | L53: medida (traçado) | M53: Areia/bege no satelite (hz_18275/18315).
A54: TOTAL | B54: =SUM(B6:B53) -> 21907.8 | D54: =IF(B54=0,0,E54/B54) -> 0.17031377 | E54: =SUM(E6:E53) -> 3731.2 | F54: =SUM(F6:F53) -> 18176.6
A56: Falta pavimentar — pista (m²): | D56: =F54*8 -> 145412.8 | E56: largura média de pista adotada: 8 m (premissa)
A57: Vias não abertas incluídas no total (m): | D57: 0 | E57: constam na planta, sem abertura visível no satélite
A58: Passeio (calçada de pedestre) existente: | D58: 0.16 | E58: medido em 73 ponto(s) do Street View — confiança alta
A59: Passeio faltante (m de via aberta): | D59: =(B54-D57)*(1-D58) -> 18402.552 | E59: vias não abertas excluídas do cálculo de passeio
A60: Passeio faltante (m²): | D60: =D59*4 -> 73610.208 | E60: premissa: 2 lados × 2 m de largura de calçada
A61: Pavimento sobre metragem medida (m): | D61: 3731
A62: Pavimento sobre metragem só de planta (m): | D62: 0 | E62: sem traçado medido — existência a confirmar em campo
A63: Falta pavimentar sobre metragem medida (m): | D63: 18177
A64: Falta pavimentar sobre metragem só de planta (m): | D64: 0 | E64: parcela do orçamento que depende de vias ainda não confirmadas em campo
A65: Obs. passeio: medido em 73 ponto(s) do Street View — ambos os lados=100%, um lado=50%, nenhum=0%

Sheet 15 Morada do Sol
A1: Loteamento Morada do Sol — planta nº 15
A2: Proprietário/empreendedor: Guriri Beach Turismo | Matrícula: 7.640 (09/10/1986) | Área oficial: 122.214 m²
A3: Auditoria completa: 15 pontos verificados neste loteamento (1 ponto a cada ~350 m de via) no Google Street View e. onde não há cobertura. em satélite. Metragem com traçado medido: 3.115 m; só de planta: 0 m.
A5: Rua / via | B5: Extensão da pista (m) | C5: Situação da pista | D5: % pista pavimentada | E5: Pavimentado (m) | F5: Falta pavimentar (m) | G5: Confiança | H5: Passeio (calçada) | I5: % passeio | J5: Pontos auditados | K5: Origem da classificação | L5: Metragem | M5: Observações
A6: Avenida Esbertalina Barbosa Damiani | B6: 145.1 | C6: Pavimentada | D6: 1 | E6: =ROUND(B6*D6,1) -> 145.1 | F6: =B6-E6 -> 0 | G6: alta | H6: Parcial | I6: 0.5 | J6: 1 | K6: 1 ponto(s): 1 SV + 0 satélite (bloquete) | L6: medida (traçado) | M6: cinza em hz_18515_L
A7: Avenida Esbertalina B. Damiani | B7: 595.6 | C7: Parcial | D7: 0.62 | E7: =ROUND(B7*D7,1) -> 369.3 | F7: =B7-E7 -> 226.3 | G7: alta | H7: Não | I7: 0.19 | J7: 2 | K7: 2 ponto(s): 2 SV + 0 satélite (areia, bloquete) | L7: medida (traçado) | M7: tag paving_stones (bloquete) coerente com tom cinza-amarronzado do corredor
A8: Avenida Mar Negro | B8: 337.8 | C8: Não pavimentada | D8: 0 | E8: =ROUND(B8*D8,1) -> 0 | F8: =B8-E8 -> 337.8 | G8: alta | H8: Não | I8: 0 | J8: 2 | K8: 2 ponto(s): 2 SV + 0 satélite (areia) | L8: medida (traçado) | M8: bege/areia em todo o trecho a oeste da Esbertalina (hz_18515_L); tag 'asphalt' do OSM refere-se a trecho junto a orla, fora do poligono
A9: Rua Jaguaré | B9: 320.9 | C9: Não pavimentada | D9: 0 | E9: =ROUND(B9*D9,1) -> 0 | F9: =B9-E9 -> 320.9 | G9: alta | H9: Parcial | I9: 0.5 | J9: 1 | K9: 1 ponto(s): 1 SV + 0 satélite (areia) | L9: medida (traçado) | M9: limite sul do bloco oeste; bege/areia (hz_18515_L)
A10: Rua Albino Negris | B10: 383.9 | C10: Não pavimentada | D10: 0 | E10: =ROUND(B10*D10,1) -> 0 | F10: =B10-E10 -> 383.9 | G10: alta | H10: Parcial | I10: 0.5 | J10: 1 | K10: 1 ponto(s): 1 SV + 0 satélite (areia) | L10: medida (traçado) | M10: via N-S bege/areia entre Mantenopolis e Jaguare (hz_18515_L)
A11: Rua VII | B11: 387.4 | C11: Não pavimentada | D11: 0 | E11: =ROUND(B11*D11,1) -> 0 | F11: =B11-E11 -> 387.4 | G11: alta | H11: Parcial | I11: 0.5 | J11: 1 | K11: 1 ponto(s): 1 SV + 0 satélite (areia) | L11: medida (traçado) | M11: via N-S bege/areia entre Mantenopolis e Jaguare (hz_18515_L)
A12: Rua Adriana Barbosa Caran | B12: 387.5 | C12: Não pavimentada | D12: 0 | E12: =ROUND(B12*D12,1) -> 0 | F12: =B12-E12 -> 387.5 | G12: alta | H12: Parcial | I12: 0.5 | J12: 1 | K12: 1 ponto(s): 1 SV + 0 satélite (saibro) | L12: medida (traçado) | M12: via N-S bege/areia entre Mantenopolis e Jaguare (hz_18515_L)
A13: Rua Mantenópolis | B13: 128.3 | C13: Não pavimentada | D13: 0 | E13: =ROUND(B13*D13,1) -> 0 | F13: =B13-E13 -> 128.3 | G13: alta | H13: Não | I13: 0 | J13: 1 | K13: 1 ponto(s): 1 SV + 0 satélite (areia) | L13: medida (traçado) | M13: limite norte (grafia Mantenopoles na planta); bege/areia
A14: Rua Nova Venécia | B14: 109 | C14: Não pavimentada | D14: 0 | E14: =ROUND(B14*D14,1) -> 0 | F14: =B14-E14 -> 109 | G14: alta | H14: Parcial | I14: 0.5 | J14: 1 | K14: 1 ponto(s): 1 SV + 0 satélite (areia) | L14: medida (traçado) | M14: trecho de ~109 m ao sul da R. Jaguare; trilha de areia visivel que se perde em vegetacao (hz_18515_L c4)
A15: Rua Conceição da Barra | B15: 84.8 | C15: Não pavimentada | D15: 0 | E15: =ROUND(B15*D15,1) -> 0 | F15: =B15-E15 -> 84.8 | G15: alta | H15: Sim (maioria) | I15: 1 | J15: 1 | K15: 1 ponto(s): 1 SV + 0 satélite (areia) | L15: medida (traçado) | M15: trecho curto no lobo leste ao sul da Jaguare; faixa pouco definida em meio a vegetacao, quadras 01-06 pouco ocupadas
A16: Rua Horácio Barbosa Alves | B16: 75.1 | C16: Não pavimentada | D16: 0 | E16: =ROUND(B16*D16,1) -> 0 | F16: =B16-E16 -> 75.1 | G16: alta | H16: Não | I16: 0 | J16: 1 | K16: 1 ponto(s): 1 SV + 0 satélite (areia) | L16: medida (traçado) | M16: trecho curto no lobo leste; areia/vegetacao, abertura apenas parcial visivel
A17: Rua Linhares | B17: 55.4 | C17: Não pavimentada | D17: 0 | E17: =ROUND(B17*D17,1) -> 0 | F17: =B17-E17 -> 55.4 | G17: alta | H17: Parcial | I17: 0.5 | J17: 1 | K17: 1 ponto(s): 1 SV + 0 satélite (areia) | L17: medida (traçado) | M17: trecho de 55 m no lobo leste; faixa pouco definida, quase nao aberta
A18: Rua São Gabriel da Palha | B18: 104 | C18: Não pavimentada | D18: 0 | E18: =ROUND(B18*D18,1) -> 0 | F18: =B18-E18 -> 104 | G18: alta | H18: Parcial | I18: 0.5 | J18: 1 | K18: 1 ponto(s): 1 SV + 0 satélite (areia) | L18: medida (traçado) | M18: trecho no lobo leste; areia/vegetacao, abertura parcial
A19: TOTAL | B19: =SUM(B6:B18) -> 3114.8 | D19: =IF(B19=0,0,E19/B19) -> 0.16514704 | E19: =SUM(E6:E18) -> 514.4 | F19: =SUM(F6:F18) -> 2600.4
A21: Falta pavimentar — pista (m²): | D21: =F19*8 -> 20803.2 | E21: largura média de pista adotada: 8 m (premissa)
A22: Vias não abertas incluídas no total (m): | D22: 0 | E22: constam na planta, sem abertura visível no satélite
A23: Passeio (calçada de pedestre) existente: | D23: 0.36 | E23: medido em 15 ponto(s) do Street View — confiança alta
A24: Passeio faltante (m de via aberta): | D24: =(B19-D22)*(1-D23) -> 1993.472 | E24: vias não abertas excluídas do cálculo de passeio
A25: Passeio faltante (m²): | D25: =D24*4 -> 7973.888 | E25: premissa: 2 lados × 2 m de largura de calçada
A26: Pavimento sobre metragem medida (m): | D26: 514
A27: Pavimento sobre metragem só de planta (m): | D27: 0 | E27: sem traçado medido — existência a confirmar em campo
A28: Falta pavimentar sobre metragem medida (m): | D28: 2600
A29: Falta pavimentar sobre metragem só de planta (m): | D29: 0 | E29: parcela do orçamento que depende de vias ainda não confirmadas em campo
A30: Obs. passeio: medido em 15 ponto(s) do Street View — ambos os lados=100%, um lado=50%, nenhum=0%

Sheet 25 Park Res. Oitizeiro
A1: Loteamento Parque Residencial Oitizeiro — planta nº 25
A2: Proprietário/empreendedor: Alba Figueiredo Brasileiro | Matrícula: 14.380 (02/06/2000) | Área oficial: 557.784 m²
A3: Auditoria completa: 41 pontos verificados neste loteamento (1 ponto a cada ~350 m de via) no Google Street View e. onde não há cobertura. em satélite. Metragem com traçado medido: 13.896 m; só de planta: 0 m.
A5: Rua / via | B5: Extensão da pista (m) | C5: Situação da pista | D5: % pista pavimentada | E5: Pavimentado (m) | F5: Falta pavimentar (m) | G5: Confiança | H5: Passeio (calçada) | I5: % passeio | J5: Pontos auditados | K5: Origem da classificação | L5: Metragem | M5: Observações
A6: Avenida Esbertalina Barbosa Damiani | B6: 344.9 | C6: Pavimentada | D6: 1 | E6: =ROUND(B6*D6,1) -> 344.9 | F6: =B6-E6 -> 0 | G6: alta | H6: Sim (maioria) | I6: 0.75 | J6: 2 | K6: 2 ponto(s): 2 SV + 0 satélite (bloquete) | L6: medida (traçado) | M6: limite leste do loteamento; cinza nos 3 recortes hz_18395/18435/18475; onibus e comercio ao longo | corrigido por SV
A7: Avenida Esbertalina B. Damiani | B7: 85.3 | C7: Pavimentada | D7: 1 | E7: =ROUND(B7*D7,1) -> 85.3 | F7: =B7-E7 -> 0 | G7: alta | H7: Sim (maioria) | I7: 1 | J7: 1 | K7: 1 ponto(s): 1 SV + 0 satélite (asfalto) | L7: medida (traçado) | M7: segmento sul do mesmo eixo pavimentado
A8: Avenida Oceano Índico | B8: 1120.1 | C8: Não pavimentada | D8: 0 | E8: =ROUND(B8*D8,1) -> 0 | F8: =B8-E8 -> 1120.1 | G8: alta | H8: Não | I8: 0.21 | J8: 2 | K8: 2 ponto(s): 2 SV + 0 satélite (saibro) | L8: medida (traçado) | M8: todo o trecho a oeste da Esbertalina e bege/areia (hz_18435_L/O); a parte 'paved' das tags OSM corresponde ao trecho junto a orla, fora do poligono
A9: Rua Montanha | B9: 810 | C9: Não pavimentada | D9: 0 | E9: =ROUND(B9*D9,1) -> 0 | F9: =B9-E9 -> 810 | G9: alta | H9: Parcial | I9: 0.5 | J9: 2 | K9: 2 ponto(s): 2 SV + 0 satélite (areia, saibro) | L9: medida (traçado) | M9: hz_18395_L: faixa bege em toda extensao
A10: Rua Boa Esperança | B10: 812 | C10: Não pavimentada | D10: 0 | E10: =ROUND(B10*D10,1) -> 0 | F10: =B10-E10 -> 812 | G10: alta | H10: Parcial | I10: 0.5 | J10: 2 | K10: 2 ponto(s): 2 SV + 0 satélite (areia, saibro) | L10: medida (traçado) | M10: hz_18395/18435: bege/areia
A11: Rua Pinheiros | B11: 751.2 | C11: Não pavimentada | D11: 0 | E11: =ROUND(B11*D11,1) -> 0 | F11: =B11-E11 -> 751.2 | G11: alta | H11: Parcial | I11: 0.5 | J11: 2 | K11: 2 ponto(s): 2 SV + 0 satélite (saibro) | L11: medida (traçado) | M11: hz_18395/18435: bege/areia
A12: Rua Mururici | B12: 283.4 | C12: Não pavimentada | D12: 0 | E12: =ROUND(B12*D12,1) -> 0 | F12: =B12-E12 -> 283.4 | G12: alta | H12: Parcial | I12: 0.5 | J12: 1 | K12: 1 ponto(s): 1 SV + 0 satélite (saibro) | L12: medida (traçado) | M12: hz_18435_L: bege/areia
A13: Rua São Daniel Comboni | B13: 249 | C13: Não pavimentada | D13: 0 | E13: =ROUND(B13*D13,1) -> 0 | F13: =B13-E13 -> 249 | G13: alta | H13: Parcial | I13: 0.5 | J13: 1 | K13: 1 ponto(s): 1 SV + 0 satélite (saibro) | L13: medida (traçado) | M13: hz_18435/18475: bege/areia
A14: Rua Barra de São Francisco | B14: 284.4 | C14: Não pavimentada | D14: 0 | E14: =ROUND(B14*D14,1) -> 0 | F14: =B14-E14 -> 284.4 | G14: alta | H14: Parcial | I14: 0.5 | J14: 1 | K14: 1 ponto(s): 1 SV + 0 satélite (saibro) | L14: medida (traçado) | M14: hz_18475_L: bege/areia (trecho oeste)
A15: Avenida Praiana | B15: 188.9 | C15: Não pavimentada | D15: 0 | E15: =ROUND(B15*D15,1) -> 0 | F15: =B15-E15 -> 188.9 | G15: alta | H15: Parcial | I15: 0.5 | J15: 1 | K15: 1 ponto(s): 1 SV + 0 satélite (saibro) | L15: medida (traçado) | M15: hz_18475/18515: bege/areia, canteiro nao perceptivel
A16: Rua Mantenópolis | B16: 185.7 | C16: Não pavimentada | D16: 0 | E16: =ROUND(B16*D16,1) -> 0 | F16: =B16-E16 -> 185.7 | G16: alta | H16: Sim (maioria) | I16: 1 | J16: 1 | K16: 1 ponto(s): 1 SV + 0 satélite (saibro) | L16: medida (traçado) | M16: hz_18515_L: bege/areia (trecho oeste)
A17: Rua Octávio Borotto | B17: 439.8 | C17: Não pavimentada | D17: 0 | E17: =ROUND(B17*D17,1) -> 0 | F17: =B17-E17 -> 439.8 | G17: alta | H17: Parcial | I17: 0.5 | J17: 1 | K17: 1 ponto(s): 1 SV + 0 satélite (saibro) | L17: medida (traçado) | M17: transversal N-S bege/areia em todos os recortes (hz_18395/18435/18475)
... A35: Rua Colatina | B35: 32.7 | C35: Não pavimentada | D35: 0 | E35: =ROUND(B35*D35,1) -> 0 | F35: =B35-E35 -> 32.7 | G35: alta | H35: Parcial | I35: 0.5 | J35: 1 | K35: 1 ponto(s): 1 SV + 0 satélite (saibro) | L35: medida (traçado) | M35: toco de 33 m na divisa oeste; mesmo corredor de areia do eixo Colatina/Sao Daniel Comboni
A36: (sem nome) | B36: 24.2 | C36: Parcial | D36: 0.08 | E36: =ROUND(B36*D36,1) -> 1.9 | F36: =B36-E36 -> 22.3 | G36: baixa | H36: Não avaliável | I36: — | J36: 0 | K36: sem ponto próprio — taxa agregada da malha física auditada do loteamento | L36: medida (traçado) | M36: links tertiary_link junto a Esbertalina/Oceano Indico, tag dirt; area do cruzamento em areia no satelite
