Workbook

Sheet LEIA-ME
A1: VIABILIDADE ECONÔMICO-FINANCEIRA — PEDREIRA CIPREM (São Mateus/ES)
A2: Modelo construído sobre o benchmark real da Pedreira Vale Verde (PVV) 2025 · Agosto/2026
A3: USO INTERNO — ferramenta de trabalho da consultoria (contém dados de benchmark de outra empresa do grupo). NÃO anexar ao processo BNB: os documentos entregues ao banco não citam esta base de comparação.
A5: COMO USAR: edite SOMENTE as células AZUIS da aba "Premissas" (as amarelas são as premissas-chave a validar).
A6: Todas as demais abas recalculam automaticamente. Não edite células pretas (fórmulas) nem verdes (links entre abas).
A8: ABAS: Premissas → entradas | DRE_PVV_2025 → benchmark real | Mix_Produtos → de onde vem o preço/t | Frete → de onde vem o R$/t de frete | Producao_Receita / Custos / DRE_Projetada → projeção 12 anos
A9: FNE_SAC → financiamento | Fluxo_Indicadores → TIR, VPL, payback, DSCR | Capacidade_BNB → janela 30-50% (motor oficial)
A10: Sensibilidade → resumo dos cenários prontos (inclui 95% da licença) + produção necessária por ano (DSCR 1,0/1,2/1,3).
A12: QUATRO AVISOS IMPORTANTES:
A13: 1) CUSTO PADRÃO BNB: calculado da DRE real da PVV = 68,62% (tabela indústria BNB: 67,77%). VALIDAR com o analista antes do protocolo.
A14: 2) CAPACIDADE: prazo de 14 anos (condição FNE Mulher) em 2 carência + 12 amortização,
A15: com platô de 237.516 t/ano (90% da licença) alcançado no ANO 3: comprometimento 44,6%
... A26: Pedir ao fabricante a curva granulométrica garantida do circuito antes do protocolo.

Sheet Premissas
A1: PREMISSAS — edite as células azuis (amarelas = validar antes do protocolo)
A3: MIX DE PRODUTOS E PREÇOS FOB (ES)
A4: Produto | B4: % do mix | C4: Preço R$/t
A5: Pó de pedra | B5: 0.27 | C5: 35
A6: Pedrisco/gravilha | B6: 0.14 | C6: 90
A7: Brita 1 | B7: 0.33 | C7: 85
A8: Brita 2 | B8: 0.18 | C8: 78
A9: Bica corrida/rachão | B9: 0.08 | C9: 55
A10: Preço FOB médio ponderado (R$/t) | B10: =ROUND(SUMPRODUCT(B5:B9,C5:C9),1)
A12: COMERCIAL / LOGÍSTICA
A13: % das vendas entregues (CIF) | B13: 0.35
A14: Capacidade da frota própria (t/ano) | B14: 64800 | C14: 2 conjuntos Actros+Rossetti ~30,7 t
A15: Frete médio CIF (R$/t) | B15: 41 | C15: 45 km × R$ 0,91/t/km (tabela PVV)
A16: Custo do frete próprio (% da receita de frete) | B16: 0.72
A17: Deduções s/ receita bruta (ICMS efetivo+PIS+COFINS+devol.) | B17: 0.12 | C17: PVV real: 9,45% — validar ICMS-ES com contador
A18: CFEM (% receita bruta) | B18: 0.01
A20: CUSTOS (benchmark PVV ajustado)
A21: Custo variável de produção (R$/t vendida) | B21: por ano → | C21: 20 | D21: 20 | E21: 19.5 | F21: 19 | G21: 19 | H21: 19 | I21: 19 | J21: 19 | K21: 19 | L21: 19 | M21: 19 | N21: 19 | O21: 19 | P21: 19
A22: Custos fixos de produção (R$/ano) | C22: 700000 | D22: 850000 | E22: 1000000 | F22: 1100000 | G22: 1100000 | H22: 1100000 | I22: 1100000 | J22: 1100000 | K22: 1100000 | L22: 1100000 | M22: 1100000 | N22: 1100000 | O22: 1100000 | P22: 1100000
A23: Despesas adm/comercial/tributárias (R$/ano) | C23: 900000 | D23: 1100000 | E23: 1300000 | F23: 1500000 | G23: 1500000 | H23: 1500000 | I23: 1500000 | J23: 1500000 | K23: 1500000 | L23: 1500000 | M23: 1500000 | N23: 1500000 | O23: 1500000 | P23: 1500000
A24: Custeio de despesas do grupo (R$/ano) | B24: 100000
A25: Depreciação (R$/ano) | B25: 2150000 | C25: equip. R$19,4mi×10% + obras ~R$5,2mi×4%
A26: Capital de giro incremental (% ΔReceita) | B26: 0.08
A28: INVESTIMENTO E FINANCIAMENTO (FNE)
A29: Investimento total (CAPEX, R$) | B29: 25568924
A30: Financiamento FNE (R$) | B30: 24290478
A31: Prazo total (anos) | B31: 14 | C31: 14 anos — condição FNE Mulher (adm. majoritariamente feminina); comprovar no contrato social
A32: Carência (anos) | B32: 2 | C32: 2+12 — montagem que passa na janela já na receita-base
A33: Juros (% a.a.) | B33: 0.103493 | C33: taxa FNE informada ago/2026; bônus de adimplência não contado (colchão)
A34: TMA / taxa de desconto (% a.a.) | B34: 0.12
A36: VENDAS (t/ano) — ramp do plano de produção
C37: Ano 1 | D37: Ano 2 | E37: Ano 3 | F37: Ano 4 | G37: Ano 5 | H37: Ano 6 | I37: Ano 7 | J37: Ano 8 | K37: Ano 9 | L37: Ano 10 | M37: Ano 11 | N37: Ano 12 | O37: Ano 13 | P37: Ano 14
A38: Vendas (t) | C38: 63000 | D38: 126000 | E38: 237516 | F38: 237516 | G38: 237516 | H38: 237516 | I38: 237516 | J38: 237516 | K38: 237516 | L38: 237516 | M38: 237516 | N38: 237516 | O38: 237516 | P38: 237516
A39: Nota: platô 237.516 t/ano = 7.200 m³ in situ/mês = 90% da licença (LI IEMA 000478/2025-D, 8.000 m³/mês) e ≈ o realizado 2025 da PVV (236.280 t desmontadas). Ano 1 começa em 5.250 t/mês; platô a partir do ano 3.

Sheet DRE_PVV_2025
A1: BENCHMARK — DRE REAL PVV 2025 (BI do grupo, conciliada)
A2: Vendas grupo 147.565 t (PVV 75.189 + Porto 44.783 + Trancoso 27.593) · produção 216.385 t · preços×volumes fecham com a receita líquida em 99,6%
A4: Linha | B4: R$ 2025 | C4: % RB | D4: Composição
A5: Receita Bruta Operacional | B5: 17137603 | C5: =B5/$B$5 | D5: vendas 16.408.947 + serviços 728.655
A6: (–) Deduções da receita | B6: -1620318 | C6: =B6/$B$5 | D6: 9,45% da bruta
A7: (=) Receita Líquida | B7: 15517285 | C7: =B7/$B$5
A8: (–) Custos dos produtos | B8: -6515941 | C8: =B8/$B$5 | D8: direto pedra 4.274k · indireto 1.236k · depósitos 474k · CMV 530k
A9: (=) Resultado Bruto | B9: 9001344 | C9: =B9/$B$5 | D9: 58,0% da RL
A10: (–) Despesas operacionais | B10: -3451609 | C10: =B10/$B$5 | D10: adm 1.698k · comercial 749k · logística entrega 815k · tributárias 141k
A11: (=) EBITDA | B11: 5549735 | C11: =B11/$B$5 | D11: 35,8% da RL
A12: (–) Custeio de despesas do grupo | B12: -172646 | C12: =B12/$B$5
A13: (+/-) Resultado não operacional | B13: -106861 | C13: =B13/$B$5
A14: (–) Depreciação e amortização | B14: -2214601 | C14: =B14/$B$5 | D14: 14,3% da RL
A15: (+/-) Resultado financeiro | B15: -478392 | C15: =B15/$B$5
A16: (–) IR e CSLL | B16: -541447 | C16: =B16/$B$5
A17: (=) Lucro Líquido | B17: 2035788 | C17: =B17/$B$5 | D17: 13,1% da RL · 11,9% da bruta
A19: CUSTO PADRÃO BNB (real PVV) = (Deduções+Custos+Despesas+Custeio)/Receita Bruta | B19: =(-B6-B8-B10-B12)/B5
A21: UNIT ECONOMICS
A22: Preço médio realizado (R$ bruto/t vendida) | B22: =B5/147565
A23: Custo produção (R$/t produzida) | B23: =-B8/216385
A24: EBITDA por t vendida (R$/t) | B24: =B11/147565
A25: Conciliação: produção 216.385 t − vendas 147.565 t − Δestoque −15.799 t ⇒ diferença de ~84 kt (transferências/graduada/uso interno) a confirmar com o cliente.

Sheet Mix_Produtos
A1: MIX DE PRODUTOS — DE ONDE VEM O PREÇO MÉDIO POR TONELADA
A2: A britagem gera vários produtos com preços muito diferentes; o modelo NÃO usa preço de um produto único: usa a média ponderada do mix real vendido pela pedreira-modelo (PVV) em 2025, reconciliada abaixo. Azul = dado de documento · preto = fórmula · verde = link entre abas.
A4: A · O QUE A PEDREIRA-MODELO (PVV) VENDEU EM 2025 — na pedreira, FOB (sem frete)
A5: Produto | B5: t vendidas | C5: % do mix | D5: Preço tabela (R$/t) | E5: Desconto médio | F5: Preço líquido (R$/t) | G5: Receita FOB (R$) | H5: Observação
A6: BRITA 1 | B6: 24949.64 | C6: =B6/$B$14 | D6: 98 | E6: 0.05 | F6: =D6*(1-E6) | G6: =B6*F6 | H6: na carta CIPREM: brita 1
A7: PÓ DE PEDRA | B7: 16312.55 | C7: =B7/$B$14 | D7: 25 | E7: 0.15 | F7: =D7*(1-E7) | G7: =B7*F7 | H7: na carta: pó de pedra — 22% do mix na pedreira; sobe a 29% no consolidado
A8: BRITA 0 | B8: 13608.91 | C8: =B8/$B$14 | D8: 120 | E8: 0.06 | F8: =D8*(1-E8) | G8: =B8*F8 | H8: na carta: brita 0
A9: PULMÃO (rachão) | B9: 6640.27 | C9: =B9/$B$14 | D9: 85 | E9: 0.1 | F9: =D9*(1-E9) | G9: =B9*F9 | H9: não listado na carta; PAE prevê "sob demanda"
A10: BRITA GRADUADA (BGS) | B10: 4562.89 | C10: =B10/$B$14 | D10: 85 | E10: 0.17 | F10: =D10*(1-E10) | G10: =B10*F10 | H10: na carta: BGS/solo-brita — mistura de pó + britas
A11: PEDRISCO | B11: 4279.26 | C11: =B11/$B$14 | D11: 80 | E11: 0.11 | F11: =D11*(1-E11) | G11: =B11*F11 | H11: na carta: gravilinha (nome regional)
A12: BRITA 2 | B12: 4253.52 | C12: =B12/$B$14 | D12: 98 | E12: 0.07 | F12: =D12*(1-E12) | G12: =B12*F12 | H12: na carta: brita 2
A13: MARROADA | B13: 582.2 | C13: =B13/$B$14 | D13: 87 | E13: 0.06 | F13: =D13*(1-E13) | G13: =B13*F13 | H13: não listada na carta; venda eventual
A14: TOTAL / PREÇO MÉDIO PONDERADO FOB PEDREIRA | B14: =SUM(B6:B13) | C14: =SUM(C6:C13) | F14: =G14/B14 | G14: =SUM(G6:G13) | H14: ≈ R$ 76,80/t — nenhum produto isolado: é a tonelada média do mix inteiro
A16: B · DA OPERAÇÃO REAL AO PREÇO DO MODELO — RECONCILIAÇÃO
A17: Preço médio FOB pedreira (mix real, seção A) | F17: =F14
A18: Preço médio realizado consolidado 2025 (pedreira + filiais Porto Seguro e Trancoso) | F18: 116.13549 | H18: ver aba DRE_PVV_2025 — inclui preços de varejo das filiais e a logística até elas
A19: Logística/estrutura de filiais embutida no consolidado | F19: 0.36212647
A20: FOB-EQUIVALENTE (consolidado × (1 − logística)) — o número-âncora | F20: =F18*(1-F19) | H20: ≈ R$ 74,08/t — o que a tonelada média rende tirando o custo de levá-la às filiais
A21: PREÇO DO CASO-BASE DO MODELO (aba Premissas) | F21: 68.5
A22: Margem de prudência adotada sobre o FOB-equivalente | F22: =1-F21/F20
A23: Sensibilidade (aba Sensibilidade): a R$ 74/t o comprometimento cai a 46,5%; a R$ 82/t, a 41,3%.
A24: Nas filiais o pó de pedra NÃO sai a R$ 25: tabela Porto Seguro R$ 56,71/t · Trancoso R$ 64,47/t.
A26: C · MIX DE PROJETO DA CIPREM — tabela de produtos do PAE (planta a 20.000 t/mês)
A27: Produto (nome no PAE) | B27: Equivalente comercial | C27: Faixa | D27: % da produção | E27: t/mês | H27: Observação
A28: Brita 19 mm (¾") | B28: brita 1 | C28: 19–12,5 mm | D28: 0.35 | E28: =D28*20000 | H28: produto de maior giro
A29: Brita 12,5 mm (½") — "Gravilhão" | B29: brita 0 / gravilinha | C29: 12,5–4,8 mm | D29: 0.25 | E29: =D29*20000
A30: Brita 4,8 mm (pó de pedra) | B30: pó de pedra | C30: < 4,8 mm | D30: 0.4 | E30: =D30*20000 | H30: fração crítica — ver seção D
A31: Brita 76/38 mm (3"/2") e rachão | B31: brita 2 / rachão | D31: sob demanda
A32: Brita graduada (BGS) | B32: BGS/solo-brita | D32: recombinação de pó + britas (não é massa nova)
A33: Fonte: PAE CIPREM, parte 2 — "Produtos do processo de britagem": 7.000 + 5.000 + 8.000 = 20.000 t/mês (35% + 25% + 40%).
A35: D · TESTE DE ESTRESSE DO MIX — e se o pó só valer o preço mínimo?
A36: Piso: mix de projeto (35/25/40), fração ½" valendo como PEDRISCO e pó a tabela mínima da pedreira | F36: =0.35*F6+0.25*F11+0.40*F7
A37: Mesmo piso, com a fração ½" valendo como BRITA 0 | F37: =0.35*F6+0.25*F8+0.40*F7
A38: Leitura: o caso-base (R$ 68,50) está dentro da banda do piso estressado (F36–F37) e ABAIXO do realizado da operação gêmea (R$ 74–77).
A39: Mitigações que elevam a média de volta: pó misturado em BGS (vende a R$ 85/t) · câmara F-Sand do HP350e (converte fina em areia de brita) · mercado local de intertravado: pó no assentamento e na fabricação de blocos (artefatos próprios: opção futura, fora do escopo) · nas filiais o pó já realiza R$ 57–64/t.
A41: E · PRODUTOS DA CARTA CONSULTA × O QUE A PVV REALMENTE VENDE
A42: Produto na carta consulta (CIPREM) | B42: PVV vende? | D42: SKU na PVV | H42: Observação
A43: brita 0 | B43: Sim | D43: BRITA 0 | H43: mesmo produto
A44: brita 1 | B44: Sim | D44: BRITA 1 | H44: mesmo produto — maior giro da PVV (31% do vendido)
A45: brita 2 | B45: Sim | D45: BRITA 2 | H45: PAE produz "sob demanda" (4% do vendido na PVV)
...

Sheet Frete
A1: FRETE — DE ONDE VEM O R$/t, E AS DUAS CONTAS EM QUE ELE ENTRA
A2: O frete aparece em duas contas distintas do pacote, com a mesma taxa e sentidos diferentes: na régua de vantagem competitiva do Estudo de Mercado (uma diferença entre distâncias, que mede posição frente ao concorrente) e na receita de frete deste modelo (um valor absoluto, que mede o que se cobra para entregar). Esta aba reúne as duas, a origem da taxa e as conferências. Não há número novo aqui: as células puxam Premissas e Mix_Produtos por referência.
A4: A · A TAXA E SUA ORIGEM
A5: Modalidade | B5: R$/t·km | C5: Natureza | H5: Fonte
A6: Carreta — ADOTADA em todo o pacote | B6: 0.91 | C6: preço praticado | H6: Tabela de preços da unidade do grupo em operação (PVV/BA), linha literal "Carreta 0,91 X volume (T) x KM", sob o cabeçalho "VER FRETE MÉDIO SAINDO DA PEDREIRA". É a regra comercial que o grupo já cobra — não é estimativa nem tabela pública.
A7: Truck | B7: 0.99 | C7: preço praticado | H7: Mesma tabela, linha "Truck: 0,99 X Volume (T) x KM". Adotou-se a carreta por ser a menor das duas, e por ser o equipamento orçado no investimento.
A8: SICRO/DNIT — referência externa | B8: 0.78 | C8: CUSTO, não preço | H8: Referência oficial de custo rodoviário em pista pavimentada. A diferença para 0,91 é a margem do transportador. Ver sensibilidade na seção F.
A10: B · USO 1 — RÉGUA DE VANTAGEM COMPETITIVA (Estudo de Mercado, item 4)
A11: vantagem (R$/t) = coeficiente × (km do concorrente − km da CIPREM). É uma DIFERENÇA entre distâncias: mede quanto a pedra da CIPREM chega mais barata que a do concorrente na mesma praça. Não é custo de ninguém, e não entra na projeção financeira — serve para delimitar o mercado-base e os pesos de captura.
A12: Praça | B12: km CIPREM | C12: Concorrente | D12: km conc. | E12: Vantagem | H12: Observação
A13: São Mateus sede + Guriri | B13: 40.7 | C13: MCL (Nova Venécia) | D13: 75.5 | E13: =ROUND($B$6*(D13-B13),1) | H13: ambas medidas
A14: São Mateus sede + Guriri | B14: 40.7 | C14: Mattar (Pinheiros) | D14: 66.8 | E14: =ROUND($B$6*(D14-B14),1) | H14: concorrente de VOLUME mais próximo — referência adotada no pacote
A15: São Mateus sede + Guriri | B15: 40.7 | C15: Usibrita (Jaguaré) | D15: 57.1 | E15: =ROUND($B$6*(D15-B15),1) | H15: produtor mais próximo de qualquer porte; ~5 mil t/ano, sem escala para volume
A16: Boa Esperança | B16: 27.9 | C16: Mattar (Pinheiros) | D16: 22.3 | E16: =ROUND($B$6*(D16-B16),1) | H16: praça-base, paridade
A17: Conceição da Barra | B17: 73.2 | C17: Mattar (Pinheiros) | D17: 67.5 | E17: =ROUND($B$6*(D17-B17),1) | H17: praça-base, paridade
A18: Franja norte (Montanha) | B18: 90.3 | C18: Mattar | D18: 60 | E18: =ROUND($B$6*(D18-B18),1) | H18: fora do raio econômico
A19: Jaguaré sede | B19: 39.6 | C19: Usibrita local | D19: 8 | E19: =ROUND($B$6*(D19-B19),1) | H19: praça disputada — produtor instalado
A20: Nova Venécia sede | B20: 37.3 | C20: MCL local | D20: 5 | E20: =ROUND($B$6*(D20-B20),1) | H20: praça-sede de concorrente
A21: Pedro Canário | B21: 88.3 | C21: Mattar | D21: 50 | E21: =ROUND($B$6*(D21-B21),1) | H21: fora do raio econômico
A22: Pinheiros sede | B22: 45.9 | C22: Mattar local | D22: 5 | E22: =ROUND($B$6*(D22-B22),1) | H22: praça-sede de concorrente
A23: Distâncias medidas em roteirizador (ago/2026) a partir da coordenada do empreendimento registrada no PAE (GPS -18,67144 / -40,17303). Estimadas apenas as distâncias internas dos concorrentes às próprias sedes (linhas com 'local').
A25: C · USO 2 — RECEITA DE FRETE CIF NESTE MODELO (aba Premissas)
A26: Aqui o frete é RECEITA, não vantagem: a CIPREM vende FOB (cliente busca) e CIF (a CIPREM entrega). Nas vendas CIF ela cobra o frete e o executa com frota própria.
A27: Raio médio de entrega adotado (km) | B27: 45 | H27: premissa — validada na seção D
A28: Coeficiente aplicado (R$/t·km) | B28: =B6
A29: Frete médio CIF derivado (R$/t) | B29: =ROUND(B27*B28,0)
A30: Frete médio CIF em uso no modelo (Premissas!B15) | B30: =Premissas!B15 | C30: =IF(ROUND(B29,0)=ROUND(B30,0),"confere","DIVERGE — verificar")
A31: % das vendas entregues (CIF) | B31: =Premissas!B13
A32: Capacidade da frota própria (t/ano) | B32: =Premissas!B14 | H32: 2 conjuntos Actros+Rossetti, ~30,7 t líquidas por viagem — teto do programa CIF
A33: Custo do frete próprio (% da receita de frete) | B33: =Premissas!B16
A34: Margem logística resultante (R$/t) | B34: =ROUND(B30*(1-B33),2)
A36: CADEIA DE CÁLCULO, como roda no modelo:
A37: Vendas CIF (t) = MIN( vendas totais × % CIF ; capacidade da frota ) | H37: aba Producao_Receita, linha 5
A38: Receita de frete (R$) = vendas CIF (t) × frete médio CIF | H38: aba Producao_Receita, linha 7
A39: Custo do frete próprio (R$) = receita de frete × 72% | H39: aba Custos, linha 5
A41: D · VALIDAÇÃO DO RAIO DE 45 km — média das distâncias medidas, ponderada pela captura
A42: A captura por praça vem do item 8 do Estudo (pesos de penetração × demanda do item 6). As obras públicas ficam em São Mateus. A coluna de km é medida, salvo a de São Mateus, que é mistura de sede (40,7), Guriri (além da sede) e corredor (12,3) — editável em azul.
A43: Praça de entrega | B43: km | C43: Captura t/ano | D43: Participação | E43: km × part. | H43: Origem da captura
A44: São Mateus (sede, Guriri, corredor) + obras | B44: 45 | C44: 205835 | D44: =C44/$C$49 | E44: =B44*D44 | H44: 134.423 hab × 1,669 × 65% + 100 mil t de obras × 60%
A45: Conceição da Barra | B45: 73.2 | C45: 12068 | D45: =C45/$C$49 | E45: =B45*D45 | H45: 28.923 hab × 1,669 × 25%
...

Sheet Producao_Receita
A1: PRODUÇÃO E RECEITA — 12 ANOS
C3: Ano 1 | D3: Ano 2 | E3: Ano 3 | F3: Ano 4 | G3: Ano 5 | H3: Ano 6 | I3: Ano 7 | J3: Ano 8 | K3: Ano 9 | L3: Ano 10 | M3: Ano 11 | N3: Ano 12 | O3: Ano 13 | P3: Ano 14
A4: Vendas (t) | C4: =Premissas!C$38 | D4: =Premissas!D$38 | E4: =Premissas!E$38 | F4: =Premissas!F$38 | G4: =Premissas!G$38 | H4: =Premissas!H$38 | I4: =Premissas!I$38 | J4: =Premissas!J$38 | ... P4: =Premissas!P$38
A5: Vendas CIF (t) | C5: =MIN(C4*Premissas!$B$13,Premissas!$B$14) | D5: =MIN(D4*Premissas!$B$13,Premissas!$B$14) | E5: =MIN(E4*Premissas!$B$13,Premissas!$B$14) | F5: =MIN(F4*Premissas!$B$13,Premissas!$B$14) | G5: =MIN(G4*Premissas!$B$13,Premissas!$B$14) | H5: =MIN(H4*Premissas!$B$13,Premissas!$B$14) | I5: =MIN(I4*Premissas!$B$13,Premissas!$B$14) | J5: =MIN(J4*Premissas!$B$13,Premissas!$B$14) | ... P5: =MIN(P4*Premissas!$B$13,Premissas!$B$14)
A6: Receita FOB (R$) | C6: =C4*Premissas!$B$10 | D6: =D4*Premissas!$B$10 | E6: =E4*Premissas!$B$10 | F6: =F4*Premissas!$B$10 | G6: =G4*Premissas!$B$10 | H6: =H4*Premissas!$B$10 | I6: =I4*Premissas!$B$10 | J6: =J4*Premissas!$B$10 | ... P6: =P4*Premissas!$B$10
A7: Receita de frete CIF (R$) | C7: =C5*Premissas!$B$15 | D7: =D5*Premissas!$B$15 | E7: =E5*Premissas!$B$15 | F7: =F5*Premissas!$B$15 | G7: =G5*Premissas!$B$15 | H7: =H5*Premissas!$B$15 | I7: =I5*Premissas!$B$15 | J7: =J5*Premissas!$B$15 | ... P7: =P5*Premissas!$B$15
A8: RECEITA BRUTA (R$) | C8: =C6+C7 | D8: =D6+D7 | E8: =E6+E7 | F8: =F6+F7 | G8: =G6+G7 | H8: =H6+H7 | I8: =I6+I7 | J8: =J6+J7 | ... P8: =P6+P7
A9: (–) Deduções (R$) | C9: =-C8*Premissas!$B$17 | D9: =-D8*Premissas!$B$17 | E9: =-E8*Premissas!$B$17 | F9: =-F8*Premissas!$B$17 | G9: =-G8*Premissas!$B$17 | H9: =-H8*Premissas!$B$17 | I9: =-I8*Premissas!$B$17 | J9: =-J8*Premissas!$B$17 | ... P9: =-P8*Premissas!$B$17
A10: RECEITA LÍQUIDA (R$) | C10: =C8+C9 | D10: =D8+D9 | E10: =E8+E9 | F10: =F8+F9 | G10: =G8+G9 | H10: =H8+H9 | I10: =I8+I9 | J10: =J8+J9 | ... P10: =P8+P9

Sheet Custos
A1: CUSTOS E DESPESAS — 12 ANOS
C3: Ano 1 | D3: Ano 2 | E3: Ano 3 | F3: Ano 4 | G3: Ano 5 | H3: Ano 6 | I3: Ano 7 | J3: Ano 8 | K3: Ano 9 | L3: Ano 10 | M3: Ano 11 | N3: Ano 12 | O3: Ano 13 | P3: Ano 14
A4: Custo variável de produção (R$) | C4: =Producao_Receita!C4*Premissas!C$21 | D4: =Producao_Receita!D4*Premissas!D$21 | E4: =Producao_Receita!E4*Premissas!E$21 | F4: =Producao_Receita!F4*Premissas!F$21 | G4: =Producao_Receita!G4*Premissas!G$21 | H4: =Producao_Receita!H4*Premissas!H$21 | I4: =Producao_Receita!I4*Premissas!I$21 | J4: =Producao_Receita!J4*Premissas!J$21 | ... P4: =Producao_Receita!P4*Premissas!P$21
A5: Custo do frete próprio (R$) | C5: =Producao_Receita!C7*Premissas!$B$16 | D5: =Producao_Receita!D7*Premissas!$B$16 | E5: =Producao_Receita!E7*Premissas!$B$16 | F5: =Producao_Receita!F7*Premissas!$B$16 | G5: =Producao_Receita!G7*Premissas!$B$16 | H5: =Producao_Receita!H7*Premissas!$B$16 | I5: =Producao_Receita!I7*Premissas!$B$16 | J5: =Producao_Receita!J7*Premissas!$B$16 | ... P5: =Producao_Receita!P7*Premissas!$B$16
A6: CFEM (R$) | C6: =Producao_Receita!C8*Premissas!$B$18 | D6: =Producao_Receita!D8*Premissas!$B$18 | E6: =Producao_Receita!E8*Premissas!$B$18 | F6: =Producao_Receita!F8*Premissas!$B$18 | G6: =Producao_Receita!G8*Premissas!$B$18 | H6: =Producao_Receita!H8*Premissas!$B$18 | I6: =Producao_Receita!I8*Premissas!$B$18 | J6: =Producao_Receita!J8*Premissas!$B$18 | ... P6: =Producao_Receita!P8*Premissas!$B$18
A7: Custos fixos de produção (R$) | C7: =Premissas!C$22 | D7: =Premissas!D$22 | E7: =Premissas!E$22 | F7: =Premissas!F$22 | G7: =Premissas!G$22 | H7: =Premissas!H$22 | I7: =Premissas!I$22 | J7: =Premissas!J$22 | ... P7: =Premissas!P$22
A8: Despesas adm/com/trib (R$) | C8: =Premissas!C$23 | D8: =Premissas!D$23 | E8: =Premissas!E$23 | F8: =Premissas!F$23 | G8: =Premissas!G$23 | H8: =Premissas!H$23 | I8: =Premissas!I$23 | J8: =Premissas!J$23 | ... P8: =Premissas!P$23
A9: Custeio grupo (R$) | C9: =Premissas!$B$24 | D9: =Premissas!$B$24 | E9: =Premissas!$B$24 | F9: =Premissas!$B$24 | G9: =Premissas!$B$24 | H9: =Premissas!$B$24 | I9: =Premissas!$B$24 | J9: =Premissas!$B$24 | ... P9: =Premissas!$B$24
A10: TOTAL CUSTOS E DESPESAS (R$) | C10: =SUM(C4:C9) | D10: =SUM(D4:D9) | E10: =SUM(E4:E9) | F10: =SUM(F4:F9) | G10: =SUM(G4:G9) | H10: =SUM(H4:H9) | I10: =SUM(I4:I9) | J10: =SUM(J4:J9) | ... P10: =SUM(P4:P9)

Sheet FNE_SAC
A1: FINANCIAMENTO FNE — SAC ANUAL (juros na carência)
C3: Ano 1 | D3: Ano 2 | E3: Ano 3 | F3: Ano 4 | G3: Ano 5 | H3: Ano 6 | I3: Ano 7 | J3: Ano 8 | K3: Ano 9 | L3: Ano 10 | M3: Ano 11 | N3: Ano 12 | O3: Ano 13 | P3: Ano 14
A4: Saldo inicial (R$) | C4: =Premissas!$B$30 | D4: =C7 | E4: =D7 | F4: =E7 | G4: =F7 | H4: =G7 | I4: =H7 | J4: =I7 | K4: =J7 | ... P4: =O7
A5: Juros (R$) | C5: =C4*Premissas!$B$33 | D5: =D4*Premissas!$B$33 | E5: =E4*Premissas!$B$33 | F5: =F4*Premissas!$B$33 | G5: =G4*Premissas!$B$33 | H5: =H4*Premissas!$B$33 | I5: =I4*Premissas!$B$33 | J5: =J4*Premissas!$B$33 | ... P5: =P4*Premissas!$B$33
A6: Amortização (R$) | C6: =IF(1>Premissas!$B$32,Premissas!$B$30/(Premissas!$B$31-Premissas!$B$32),0) | D6: =IF(2>Premissas!$B$32,Premissas!$B$30/(Premissas!$B$31-Premissas!$B$32),0) | E6: =IF(3>Premissas!$B$32,Premissas!$B$30/(Premissas!$B$31-Premissas!$B$32),0) | F6: =IF(4>Premissas!$B$32,Premissas!$B$30/(Premissas!$B$31-Premissas!$B$32),0) | G6: =IF(5>Premissas!$B$32,Premissas!$B$30/(Premissas!$B$31-Premissas!$B$32),0) | H6: =IF(6>Premissas!$B$32,Premissas!$B$30/(Premissas!$B$31-Premissas!$B$32),0) | I6: =IF(7>Premissas!$B$32,Premissas!$B$30/(Premissas!$B$31-Premissas!$B$32),0) | J6: =IF(8>Premissas!$B$32,Premissas!$B$30/(Premissas!$B$31-Premissas!$B$32),0) | K6: =IF(9>Premissas!$B$32,Premissas!$B$30/(Premissas!$B$31-Premissas!$B$32),0) | L6: =IF(10>Premissas!$B$32,Premissas!$B$30/(Premissas!$B$31-Premissas!$B$32),0) | M6: =IF(11>Premissas!$B$32,Premissas!$B$30/(Premissas!$B$31-Premissas!$B$32),0) | N6: =IF(12>Premissas!$B$32,Premissas!$B$30/(Premissas!$B$31-Premissas!$B$32),0) | O6: =IF(13>Premissas!$B$32,Premissas!$B$30/(Premissas!$B$31-Premissas!$B$32),0) | P6: =IF(14>Premissas!$B$32,Premissas!$B$30/(Premissas!$B$31-Premissas!$B$32),0)
A7: Saldo final (R$) | C7: =C4-C6 | D7: =D4-D6 | E7: =E4-E6 | F7: =F4-F6 | G7: =G4-G6 | H7: =H4-H6 | I7: =I4-I6 | J7: =J4-J6 | ... P7: =P4-P6
A8: Serviço da dívida (R$) | C8: =C5+C6 | D8: =D5+D6 | E8: =E5+E6 | F8: =F5+F6 | G8: =G5+G6 | H8: =H5+H6 | I8: =I5+I6 | J8: =J5+J6 | ... P8: =P5+P6

Sheet DRE_Projetada
A1: DRE PROJETADA — 12 ANOS (Lucro Presumido)
C3: Ano 1 | D3: Ano 2 | E3: Ano 3 | F3: Ano 4 | G3: Ano 5 | H3: Ano 6 | I3: Ano 7 | J3: Ano 8 | K3: Ano 9 | L3: Ano 10 | M3: Ano 11 | N3: Ano 12 | O3: Ano 13 | P3: Ano 14
A4: Receita Bruta (R$) | C4: =Producao_Receita!C8 | D4: =Producao_Receita!D8 | E4: =Producao_Receita!E8 | F4: =Producao_Receita!F8 | G4: =Producao_Receita!G8 | H4: =Producao_Receita!H8 | I4: =Producao_Receita!I8 | J4: =Producao_Receita!J8 | ... P4: =Producao_Receita!P8
A5: (–) Deduções (R$) | C5: =Producao_Receita!C9 | D5: =Producao_Receita!D9 | E5: =Producao_Receita!E9 | F5: =Producao_Receita!F9 | G5: =Producao_Receita!G9 | H5: =Producao_Receita!H9 | I5: =Producao_Receita!I9 | J5: =Producao_Receita!J9 | ... P5: =Producao_Receita!P9
A6: (=) Receita Líquida (R$) | C6: =Producao_Receita!C10 | D6: =Producao_Receita!D10 | E6: =Producao_Receita!E10 | F6: =Producao_Receita!F10 | G6: =Producao_Receita!G10 | H6: =Producao_Receita!H10 | I6: =Producao_Receita!I10 | J6: =Producao_Receita!J10 | ... P6: =Producao_Receita!P10
A7: (–) Custos e despesas (R$) | C7: =-Custos!C10 | D7: =-Custos!D10 | E7: =-Custos!E10 | F7: =-Custos!F10 | G7: =-Custos!G10 | H7: =-Custos!H10 | I7: =-Custos!I10 | J7: =-Custos!J10 | ... P7: =-Custos!P10
A8: (=) EBITDA (R$) | C8: =C6+C7 | D8: =D6+D7 | E8: =E6+E7 | F8: =F6+F7 | G8: =G6+G7 | H8: =H6+H7 | I8: =I6+I7 | J8: =J6+J7 | ... P8: =P6+P7
A9: Margem EBITDA (% RL) | C9: =IFERROR(C8/C6,0) | D9: =IFERROR(D8/D6,0) | E9: =IFERROR(E8/E6,0) | F9: =IFERROR(F8/F6,0) | G9: =IFERROR(G8/G6,0) | H9: =IFERROR(H8/H6,0) | I9: =IFERROR(I8/I6,0) | J9: =IFERROR(J8/J6,0) | ... P9: =IFERROR(P8/P6,0)
A10: (–) Depreciação (R$) | C10: =-Premissas!$B$25 | D10: =-Premissas!$B$25 | E10: =-Premissas!$B$25 | F10: =-Premissas!$B$25 | G10: =-Premissas!$B$25 | H10: =-Premissas!$B$25 | I10: =-Premissas!$B$25 | J10: =-Premissas!$B$25 | ... P10: =-Premissas!$B$25
A11: (–) Juros FNE (R$) | C11: =-FNE_SAC!C5 | D11: =-FNE_SAC!D5 | E11: =-FNE_SAC!E5 | F11: =-FNE_SAC!F5 | G11: =-FNE_SAC!G5 | H11: =-FNE_SAC!H5 | I11: =-FNE_SAC!I5 | J11: =-FNE_SAC!J5 | ... P11: =-FNE_SAC!P5
A12: (=) LAIR (R$) | C12: =C8+C10+C11 | D12: =D8+D10+D11 | E12: =E8+E10+E11 | F12: =F8+F10+F11 | G12: =G8+G10+G11 | H12: =H8+H10+H11 | I12: =I8+I10+I11 | J12: =J8+J10+J11 | ... P12: =P8+P10+P11
A13: (–) IRPJ+CSLL presumido (R$) | C13: =-(0.15*(0.08*C4)+0.1*MAX(0,0.08*C4-240000)+0.09*(0.12*C4)) | D13: =-(0.15*(0.08*D4)+0.1*MAX(0,0.08*D4-240000)+0.09*(0.12*D4)) | E13: =-(0.15*(0.08*E4)+0.1*MAX(0,0.08*E4-240000)+0.09*(0.12*E4)) | F13: =-(0.15*(0.08*F4)+0.1*MAX(0,0.08*F4-240000)+0.09*(0.12*F4)) | G13: =-(0.15*(0.08*G4)+0.1*MAX(0,0.08*G4-240000)+0.09*(0.12*G4)) | H13: =-(0.15*(0.08*H4)+0.1*MAX(0,0.08*H4-240000)+0.09*(0.12*H4)) | I13: =-(0.15*(0.08*I4)+0.1*MAX(0,0.08*I4-240000)+0.09*(0.12*I4)) | J13: =-(0.15*(0.08*J4)+0.1*MAX(0,0.08*J4-240000)+0.09*(0.12*J4)) | ... P13: =-(0.15*(0.08*P4)+0.1*MAX(0,0.08*P4-240000)+0.09*(0.12*P4))
A14: (=) LUCRO LÍQUIDO (R$) | C14: =C12+C13 | D14: =D12+D13 | E14: =E12+E13 | F14: =F12+F13 | G14: =G12+G13 | H14: =H12+H13 | I14: =I12+I13 | J14: =J12+J13 | ... P14: =P12+P13

Sheet Fluxo_Indicadores
A1: FLUXO DE CAIXA E INDICADORES
B3: Ano 0 | C3: Ano 1 | D3: Ano 2 | E3: Ano 3 | F3: Ano 4 | G3: Ano 5 | H3: Ano 6 | I3: Ano 7 | J3: Ano 8 | K3: Ano 9 | L3: Ano 10 | M3: Ano 11 | N3: Ano 12 | O3: Ano 13 | P3: Ano 14
A4: Δ Capital de giro (R$) | C4: =MAX(0,(Producao_Receita!C8-0)*Premissas!$B$26) | D4: =MAX(0,(Producao_Receita!D8-Producao_Receita!C8)*Premissas!$B$26) | E4: =MAX(0,(Producao_Receita!E8-Producao_Receita!D8)*Premissas!$B$26) | F4: =MAX(0,(Producao_Receita!F8-Producao_Receita!E8)*Premissas!$B$26) | G4: =MAX(0,(Producao_Receita!G8-Producao_Receita!F8)*Premissas!$B$26) | H4: =MAX(0,(Producao_Receita!H8-Producao_Receita!G8)*Premissas!$B$26) | I4: =MAX(0,(Producao_Receita!I8-Producao_Receita!H8)*Premissas!$B$26) | J4: =MAX(0,(Producao_Receita!J8-Producao_Receita!I8)*Premissas!$B$26) | K4: =MAX(0,(Producao_Receita!K8-Producao_Receita!J8)*Premissas!$B$26) | ... P4: =MAX(0,(Producao_Receita!P8-Producao_Receita!O8)*Premissas!$B$26)
A5: FC do PROJETO (R$) | B5: =-Premissas!$B$29 | C5: =DRE_Projetada!C8+DRE_Projetada!C13-C4 | D5: =DRE_Projetada!D8+DRE_Projetada!D13-D4 | E5: =DRE_Projetada!E8+DRE_Projetada!E13-E4 | F5: =DRE_Projetada!F8+DRE_Projetada!F13-F4 | G5: =DRE_Projetada!G8+DRE_Projetada!G13-G4 | H5: =DRE_Projetada!H8+DRE_Projetada!H13-H4 | I5: =DRE_Projetada!I8+DRE_Projetada!I13-I4 | J5: =DRE_Projetada!J8+DRE_Projetada!J13-J4 | ... P5: =DRE_Projetada!P8+DRE_Projetada!P13-P4
A6: FC do ACIONISTA (R$) | B6: =-(Premissas!$B$29-Premissas!$B$30) | C6: =C5-FNE_SAC!C8 | D6: =D5-FNE_SAC!D8 | E6: =E5-FNE_SAC!E8 | F6: =F5-FNE_SAC!F8 | G6: =G5-FNE_SAC!G8 | H6: =H5-FNE_SAC!H8 | I6: =I5-FNE_SAC!I8 | J6: =J5-FNE_SAC!J8 | ... P6: =P5-FNE_SAC!P8
A7: FC projeto acumulado (R$) | B7: =B5 | C7: =B7+C5 | D7: =C7+D5 | E7: =D7+E5 | F7: =E7+F5 | G7: =F7+G5 | H7: =G7+H5 | I7: =H7+I5 | J7: =I7+J5 | ... P7: =O7+P5
A8: DSCR — (EBITDA−IR)/serviço | C8: =IFERROR((DRE_Projetada!C8+DRE_Projetada!C13)/FNE_SAC!C8,"—") | D8: =IFERROR((DRE_Projetada!D8+DRE_Projetada!D13)/FNE_SAC!D8,"—") | E8: =IFERROR((DRE_Projetada!E8+DRE_Projetada!E13)/FNE_SAC!E8,"—") | F8: =IFERROR((DRE_Projetada!F8+DRE_Projetada!F13)/FNE_SAC!F8,"—") | G8: =IFERROR((DRE_Projetada!G8+DRE_Projetada!G13)/FNE_SAC!G8,"—") | H8: =IFERROR((DRE_Projetada!H8+DRE_Projetada!H13)/FNE_SAC!H8,"—") | I8: =IFERROR((DRE_Projetada!I8+DRE_Projetada!I13)/FNE_SAC!I8,"—") | J8: =IFERROR((DRE_Projetada!J8+DRE_Projetada!J13)/FNE_SAC!J8,"—") | ... P8: =IFERROR((DRE_Projetada!P8+DRE_Projetada!P13)/FNE_SAC!P8,"—")
A10: INDICADORES
A11: TIR do projeto (% a.a.) | B11: =IRR(B5:P5)
A12: TIR do acionista (% a.a.) | B12: =IRR(B6:P6)
A13: VPL do projeto @ TMA (R$) | B13: =NPV(Premissas!$B$34,C5:P5)+B5
A14: Payback (anos) | B14: =COUNTIF(B7:P7,"<0")
A15: DSCR mínimo (anos de amortização) | B15: =MIN(E8:P8)

Sheet Capacidade_BNB
A1: CAPACIDADE DE PAGAMENTO — MOTOR OFICIAL BNB (janela 30–50%)
A2: Rédito = Receita BRUTA × (1 − custo padrão). Valores calculados no algoritmo VBA real do banco (script da consultoria, validado ao centésimo). Custo padrão proposto: 68,62% (DRE real PVV); tabela indústria: 67,77% — VALIDAR com o analista.
A4: Configuração | B4: Comprometimento máx. | C4: Veredito | D4: Observação
A5: Pleito R$ 24,29 mi · 14a · 2c+12a · platô 237.516 t/ano no ano 3 (BASE) | B5: 0.44635196 | C5: PASSA | D5: 44,6%
A6: Pleito R$ 24,29 mi · 14a · 2c+12a · estresse de rendimento a 91,6% (217.517 t/ano) | B6: 0.49439709 | C6: PASSA | D6: 49,4%
A7: Pleito R$ 24,29 mi · 14a · 2c+12a · platô 216.000 t no ano 3 | B7: 0.49847881 | C7: PASSA | D7: 49,8%
A8: Pleito R$ 24,29 mi · 14a · 2c+12a · platô 216.000 t no ano 4 (versão anterior) | B8: 0.50955827 | C8: NÃO PASSA | D8: 51,0%
A9: Pleito R$ 24,29 mi · 14a · 2c+12a · preço R$ 82/t (ref. PVV) | B9: 0.36407662 | C9: PASSA | D9: 36,4%
A10: Pleito R$ 24,29 mi · 14a · 2c+12a · produção 95% da licença | B10: 0.41955552 | C10: PASSA | D10: 42,0%
A11: Pleito R$ 24,29 mi · 14a · 3c+11a · platô 237.516 t no ano 3 | B11: 0.48789393 | C11: PASSA | D11: 48,8%
A12: Pleito R$ 24,29 mi · 14a · 4c+10a · platô 237.516 t no ano 3 | B12: 0.53796064 | C12: NÃO PASSA | D12: 53,8%
A14: FINANCIAMENTO MÁXIMO QUE PASSA (≤50%)
A15: 14a · 2c+12a · platô 237.516 t/ano no ano 3 (BASE) | B15: 26399655
A16: 14a · 2c+12a · estresse de rendimento a 91,6% (217.517 t/ano) | B16: 24488819
A17: 14a · 2c+12a · platô 216.000 t no ano 3 | B17: 24343874
A18: 14a · 2c+12a · platô 216.000 t no ano 4 (versão anterior) | B18: 23964142
A19: 14a · 2c+12a · preço R$ 82/t (ref. PVV) | B19: 30872164
A20: 14a · 2c+12a · produção 95% da licença | B20: 27660201
A21: 14a · 3c+11a · platô 237.516 t no ano 3 | B21: 24736530
A22: 14a · 4c+10a · platô 237.516 t no ano 3 | B22: 22990827
A24: Fórmulas sem cache: o Excel recalcula ao abrir. Rédito = Receita BRUTA × (1 − custo padrão 68,62%). Motor: capacidade_pagamento.py (réplica do VBA oficial do BNB), validado contra a âncora de 50,96% do platô anterior.

Sheet Sensibilidade
A1: CENÁRIOS PRONTOS (valores calculados — referência rápida)
A3: Cenário | B3: RB platô (R$) | C3: EBITDA platô (R$) | D3: LL platô (R$) | E3: DSCR mín | F3: TIR proj. | G3: VPL @12% | H3: Comprom. BNB
A4: BASE (platô 237.516 t no ano 3 · preço 68,50 · 2c+12a · 10,3493%) | B4: 18926646 | C4: 7340482 | D4: 2327138.1 | E4: 1.5342945 | F4: 0.17692849 | G4: 4927889.8 | H4: 51,0% ✗ (1 p.p.)
A5: ESTRESSE DE RENDIMENTO — hipótese de 91,6% (platô 217.517 t no ano 3) | B5: 17556714 | C5: 6528622.6 | D5: 1557472.6 | E5: 1.3668972 | F5: 0.15706795 | G5: -6303892.3 | H5: —
A6: UPSIDE (preço 82 — ref. PVV) | B6: 22133112 | C6: 10130107 | D6: 5018004.4 | E6: 2.1272444 | F6: 0.24983906 | G6: -7129164.5 | H6: —
A7: 95% DA LICENÇA (250.709 t/ano do ano 3) | B7: 19830366 | C7: 7876051.9 | D7: 2834873.3 | E7: 1.6447237 | F7: 0.18924321 | G7: -14776094 | H7: —
A8: CONSERVADOR (preço −15% · platô adiado ao ano 4) | B8: 16486169 | C8: 5217267.1 | D8: 279089.88 | E8: 0.70891531 | F8: 0.10360079 | G8: 18315726 | H8: 41,3% ✓
A9: ESTRESSE (conservador + juros 11,35%) | B9: 16486169 | C9: 5217267.1 | D9: 56271.31 | E9: 0.67287408 | F9: 0.10360079 | G9: 12340507 | H9: 42,0% ✓
A10: REFERÊNCIA — platô anterior 216.000 t no ano 4 | B10: 17452800 | C10: 6467040 | D10: 1499090.5 | E10: 1.0509307 | F10: 0.14943223
A11: RESERVA ATUAL (platô 9.200 t/mês — cubagem 2019) | B11: 9146640 | C11: 2019324 | D11: -2692795.7 | E11: 0.40696843 | F11: -0.0093724483
A13: Recomendação: 14 anos = 2 carência + 12 amortização, platô de 237.516 t/ano (90% da licença) alcançado no ano 3 — o gargalo do DSCR é o ano 3, não o nível do platô. A linha ESTRESSE DE RENDIMENTO é teste de sensibilidade, não hipótese de trabalho: a verificação do processo produtivo afastou a perda de britagem (circuito fechado, escalpe convertido em bica corrida, sem lavagem, finos comercializados). O modelo não aplica fator de rendimento.
A15: PRODUÇÃO NECESSÁRIA POR ANO (solver sobre o motor · preço R$ 68,50/t · valores em t/mês; % = fração da licença de 8.000 m³ in situ)
A16: Ano | B16: Serviço da dívida (R$) | C16: Mínimo (DSCR 1,0) | D16: Conforto (DSCR 1,2) | E16: Recomendado (DSCR 1,3) | F16: % licença (recom.) | G16: Plano atual (t/mês)
A17: 1 | B17: 2513894.4 | C17: 8908 | D17: 9977 | E17: 10511 | F17: 0.478 | G17: 5250
A18: 2 | B18: 2513894.4 | C18: 9652 | D18: 10721 | E18: 11256 | F18: 0.512 | G18: 10500
A19: 3 | B19: 4538100.9 | C19: 14515 | D19: 16465 | E19: 17460 | F19: 0.794 | G19: 15000
A20: 4 | B20: 4328609.7 | C20: 14522 | D20: 16356 | E20: 17293 | F20: 0.786 | G20: 18000
A21: 5 | B21: 4119118.5 | C21: 14088 | D21: 15812 | E21: 16704 | F21: 0.76 | G21: 18000
A22: 6 | B22: 3909627.3 | C22: 13653 | D22: 15274 | E22: 16114 | F22: 0.733 | G22: 18000
A23: 7 | B23: 3700136.1 | C23: 13219 | D23: 14753 | E23: 15524 | F23: 0.706 | G23: 18000
A24: 8 | B24: 3490644.9 | C24: 12785 | D24: 14232 | E24: 14956 | F24: 0.68 | G24: 18000
A25: 9 | B25: 3281153.7 | C25: 12350 | D25: 13711 | E25: 14391 | F25: 0.654 | G25: 18000
A26: 10 | B26: 3071662.5 | C26: 11916 | D26: 13190 | E26: 13826 | F26: 0.629 | G26: 18000
A27: 11 | B27: 2862171.3 | C27: 11482 | D27: 12668 | E27: 13262 | F27: 0.603 | G27: 18000
A28: 12 | B28: 2652680.1 | C28: 11047 | D28: 12147 | E28: 12697 | F28: 0.577 | G28: 18000
... A30: 14 | B30: 2233697.7 | C30: 10179 | D30: 11105 | E30: 11568 | F30: 0.526 | G30: 18000
A31: Leitura (taxa 10,3493%): ano 3 é o pico (recomendado 17.460 t/mês = 79% da licença); anos 1–2 (carência) o mínimo cobre só juros — gap de ~R$ 1,7 mi no usos e fontes. Cenário 95% da licença: comprometimento 42,0%, DSCR mín 1,64 (1,17 a preço −15%), máx financiável R$ 27,7 mi; contrapartida: reserva medida esgota no ano 7 — sondagem/RFP antes.
